Workbook
Name FN_5: '4'!#REF!
Name FN_5: #REF!
Name FN_5: #REF!
Name FN_5.10: '4'!#REF!
Name FN_5.10: #REF!
Name FN_5.10: #REF!
Name FN_5.11: '4'!#REF!
Name FN_5.11: #REF!
Name FN_5.11: #REF!
Name FN_5.12: '4'!#REF!
Name FN_5.12: #REF!
Name FN_5.12: #REF!
Name FN_5.13: '4'!#REF!
Name FN_5.13: #REF!
Name FN_5.13: #REF!
Name FN_5.2: '4'!#REF!
Name FN_5.2: #REF!
Name FN_5.2: #REF!
Name FN_5.3: '4'!#REF!
Name FN_5.3: #REF!
Name FN_5.3: #REF!
Name FN_5.4: '4'!#REF!
Name FN_5.4: #REF!
Name FN_5.4: #REF!
Name FN_5.5: '4'!#REF!
Name FN_5.5: #REF!
Name FN_5.5: #REF!
Name FN_5.6: '4'!#REF!
Name FN_5.6: #REF!
Name FN_5.6: #REF!
Name FN_5.7: '4'!#REF!
Name FN_5.7: #REF!
Name FN_5.7: #REF!
Name FN_5.8: '4'!#REF!
Name FN_5.8: #REF!
Name FN_5.8: #REF!
Name FN_5.9: '4'!#REF!
Name FN_5.9: #REF!
Name FN_5.9: #REF!
Name RF: #REF!
Name 기초가격: #REF!
Name 만기: #REF!
Name 주가상승계수: #REF!
Name 주가하락계수: #REF!
Name 행사가격: #REF!
Name 행사시작일: #REF!
Name 행사종료일: #REF!
Name 헷지확률: #REF!

Sheet A0
D5: 회사명 | E5: 주식회사 울트라브이와 그 종속기업
D6: 당기개시사업년도 | E6: 46023
D7: 당기종료사업년도 | E7: 46203
D8: 전기개시사업년도 | E8: 45658
D9: 전기종료사업년도 | E9: 46022
D10: 전분기종료사업년도 | E10: 45838
D11: 당기기수 | E11: 15
D12: 전기기수 | E12: 14

Sheet 계정코드
B2: 유동자산 | C2: 10100 | D2: 현금
C3: 10300 | D3: 보통예금
C4: 10400 | D4: 외화보통예금
C5: 10600 | D5: 기타단기금융상품
C6: 10800 | D6: 외상매출금
C7: 10900 | D7: 외상매출금_대손충당금
C8: 11600 | D8: 미수수익
C9: 11700 | D9: 미수수익_대손충당금
C10: 12000 | D10: 미수금
C11: 12100 | D11: 미수금_대손충당금
C12: 12400 | D12: 임차보증금(유동)
C13: 12500 | D13: 임차보증금(유동)_현재가치할인차금
C14: 13100 | D14: 선급금
... C30: 15800 | D30: 재공품재고자산평가충당금
B31: 비유동자산 | C31: 19500 | D31: 당기손익-공정가치금융자산
C32: 17600 | D32: 종속기업투자
C33: 17700 | D33: 관계기업투자
C34: 20100 | D34: 토지
C35: 20200 | D35: 건물
C36: 20300 | D36: 감가상각누계액건물
C37: 20600 | D37: 기계장치
C38: 20700 | D38: 감가상각누계액기계장치
C39: 20800 | D39: 차량운반구
C40: 20900 | D40: 감가상각누계액차량운반구
C41: 21000 | D41: 공구와기구
C42: 21100 | D42: 감가상각누계액공구와기구
C43: 21200 | D43: 비품
... C65: 19600 | D65: 이연법인세자산
B66: 유동부채 | C66: 25100 | D66: 외상매입금
C67: 25300 | D67: 미지급금
C68: 25400 | D68: 예수금
C69: 25500 | D69: 부가세예수금
C70: 25900 | D70: 선수금
C71: 26000 | D71: 단기차입금
C72: 26200 | D72: 미지급비용
C73: 27500 | D73: 미지급법인세
C74: 28100 | D74: 반품충당부채
C75: 28200 | D75: 유동성장기차입금
C76: 28300 | D76: 유동성리스부채
B77: 비유동부채 | C77: 29300 | D77: 장기차입금
...

Sheet 환율
B3: 기준일 | C3: 46203
B5: 통화 | C5: HKD
B6: 평균환율 | C6: 189.66
B7: 기말환율 | C7: 196.6
B16: 통화 | C16: RMB(CNH)
B17: 평균환율 | C17: 216.23
B18: 기말환율 | C18: 226.97
Q20: =ROUND(SUM(E116:E118,E130:E132)*환율!C7,) -> 0
B23: 통화 | C23: SGD
B24: 평균환율 | C24: 1160.66
B25: 기말환율 | C25: 1192.74

Sheet >>BSPL

Sheet 연결PL
B1: 계정과목 | C1: 주석 | D1: =연결BS!D1 -> 46203 | E1: =A0!E10 -> 45838
B2: 매출액 | D2: =SUM(D3:D6) -> 8812244469 | E2: 9441165967
B3: 상품매출 | D3: =SUMIF(PL!$AC:$AC,연결PL!B3,PL!$Y:$Y) -> 1181126900 | E3: 1049196780
B4: 제품매출 | D4: =SUMIF(PL!$AC:$AC,연결PL!B4,PL!$Y:$Y) -> 7595910549 | E4: 8347940342
B5: 서비스매출 | D5: =SUMIF(PL!$AC:$AC,연결PL!B5,PL!$Y:$Y) -> 0 | E5: 0
B6: 식음료매출 | D6: =SUMIF(PL!$AC:$AC,연결PL!B6,PL!$Y:$Y) -> 35207020 | E6: 44028845
B7: 매출원가 | D7: =SUM(D8,D15,D22,D28) -> 3634217621 | E7: 3581100990
B8: (1)제품매출원가 | D8: =SUM(D11:D13)-D14 -> 3389356072 | E8: 3467738461
B9: 기초제품재고액 | D9: =SUMIF(PL!$AC:$AC,연결PL!B9,PL!$Y:$Y) -> 2349819825 | E9: 2459042471
B10: 당기제품제조원가 | D10: =SUMIF(PL!$AC:$AC,연결PL!B10,PL!$Y:$Y) -> 3476800819 | E10: 3344382182
B11: 계(제품) | D11: =SUM(D9:D10) -> 5826620644 | E11: 5803424653
B12: 타계정대체(제품) | D12: =SUMIF(PL!$AC:$AC,연결PL!B12,PL!$Y:$Y) -> -5296679 | E12: -6471662
B13: 재고자산평가(제품) | D13: =SUMIF(PL!$AC:$AC,연결PL!B13,PL!$Y:$Y) -> 102749779 | E13: 8624839
B14: 기말제품재고액 | D14: =SUMIF(PL!$AC:$AC,연결PL!B14,PL!$Y:$Y) -> 2534717672 | E14: 2337839369
B15: (2)상품매출원가 | D15: =SUM(D18:D20)-D21 -> 234624705 | E15: 99559984
B16: 기초상품재고액(상품) | D16: =SUMIF(PL!$AC:$AC,연결PL!B16,PL!$Y:$Y) -> 137397633 | E16: 132365368
B17: 당기상품제조원가(상품) | D17: =SUMIF(PL!$AC:$AC,연결PL!B17,PL!$Y:$Y) -> 287806604 | E17: 182932057
B18: 계(상품) | D18: =SUM(D16:D17) -> 425204237 | E18: 315297425
B19: 타계정대체(상품) | D19: =SUMIF(PL!$AC:$AC,연결PL!B19,PL!$Y:$Y) -> -894006 | E19: 0
B20: 재고자산평가(상품) | D20: =SUMIF(PL!$AC:$AC,연결PL!B20,PL!$Y:$Y) -> -14089 | E20: 0
B21: 기말상품재고액(상품) | D21: =SUMIF(PL!$AC:$AC,연결PL!B21,PL!$Y:$Y) -> 189671437 | E21: 215737441
B22: (3)서비스매출원가 | D22: =D25-D26-D27 -> 0 | E22: 0
B23: 기초상품재고액(서비스) | D23: =SUMIF(PL!$AC:$AC,연결PL!B23,PL!$Y:$Y) -> 0 | E23: 0
B24: 당기상품제조원가(서비스) | D24: =SUMIF(PL!$AC:$AC,연결PL!B24,PL!$Y:$Y) -> 0 | E24: 0
B25: 계(서비스) | D25: =SUM(D23:D24) -> 0 | E25: 0
B26: 타계정대체(서비스) | D26: =SUMIF(PL!$AC:$AC,연결PL!B26,PL!$Y:$Y) -> 0 | E26: 0
B27: 기말상품재고액(서비스) | D27: =SUMIF(PL!$AC:$AC,연결PL!B27,PL!$Y:$Y) -> 0 | E27: 0
B28: (4)식음료매출원가 | D28: =D31-D32-D33 -> 10236844 | E28: 13802545
B29: 기초상품재고액(식음료) | D29: =SUMIF(PL!$AC:$AC,연결PL!B29,PL!$Y:$Y) -> 0 | E29: 0
B30: 당기상품제조원가(식음료) | D30: =SUMIF(PL!$AC:$AC,연결PL!B30,PL!$Y:$Y) -> 10236844 | E30: 13802545
B31: 계(식음료) | D31: =SUM(D29:D30) -> 10236844 | E31: 13802545
B32: 타계정대체(식음료) | D32: =SUMIF(PL!$AC:$AC,연결PL!B32,PL!$Y:$Y) -> 0 | E32: 0
B33: 기말상품재고액(식음료) | D33: =SUMIF(PL!$AC:$AC,연결PL!B33,PL!$Y:$Y) -> 0 | E33: 0
B34: 매출총이익 | D34: =D2-D7 -> 5178026848 | E34: 5860064977
B35: 판매비와관리비 | D35: =SUM(D36:D67) -> 5969068326 | E35: 4763859751
B36: 급여 | D36: =SUMIF(PL!$AC:$AC,연결PL!B36,PL!$Y:$Y) -> 1503402249 | E36: 1770176545
B37: 퇴직급여 | D37: =SUMIF(PL!$AC:$AC,연결PL!B37,PL!$Y:$Y) -> 110359296 | E37: 104651910
B38: 해고급여 | D38: =SUMIF(PL!$AC:$AC,연결PL!B38,PL!$Y:$Y) -> 45930430
B39: 주식보상비 | D39: =SUMIF(PL!$AC:$AC,연결PL!B39,PL!$Y:$Y) -> 0 | E39: 0
B40: 복리후생비 | D40: =SUMIF(PL!$AC:$AC,연결PL!B40,PL!$Y:$Y) -> 197164634 | E40: 203301261
...

Sheet 연결PL_IFRS18
B1: 연결 손익계산서 정산표 (IFRS 18 기준)
B2: ※ [연결PL]·[PL] 시트의 금액을 그대로 연동하여 IFRS 18 범주(영업·투자·재무·법인세)로 재분류한 연결 손익 정산표입니다. 재분류는 하단 [부록 1] R열(노란색·파란글씨)에서 변경하면 자동 반영됩니다.
D3: =연결PL!D1 -> 46203 | E3: =연결PL!E1 -> 45838
B4: 계정과목 | D4: 당기 연결 | E4: 전기 연결 | G4: =PL!I2 -> 울트라브이 | H4: =PL!J2 -> 울트라브이팜 | I4: =PL!K2 -> ULTRA V HONG KONG LIMITED | J4: =PL!L2 -> DERMASTER HONG KONG LIMITED | K4: =PL!M2 -> ULTRA V SHANGHAI LIMITED | L4: =PL!N2 -> ULTRA V (SG) PTE.LTD (24년 설립) | M4: =PL!O2 -> ATGC | N4: 단순합산 | O4: 연결조정(상계·지분법 등)
B5: Ⅰ. 영업 범주
B6: 매출액 | D6: =SUMIFS(D$69:D$133,$R$69:$R$133,$B6) -> 8812244469 | E6: =SUMIFS(E$69:E$133,$R$69:$R$133,$B6) -> 9441165967 | G6: =SUMIFS(G$69:G$133,$R$69:$R$133,$B6) -> 8288170687 | H6: =SUMIFS(H$69:H$133,$R$69:$R$133,$B6) -> 0 | I6: =SUMIFS(I$69:I$133,$R$69:$R$133,$B6) -> 807627666 | J6: =SUMIFS(J$69:J$133,$R$69:$R$133,$B6) -> 110521930 | K6: =SUMIFS(K$69:K$133,$R$69:$R$133,$B6) -> 0 | L6: =SUMIFS(L$69:L$133,$R$69:$R$133,$B6) -> 0 | M6: =SUMIFS(M$69:M$133,$R$69:$R$133,$B6) -> 0 | N6: =SUMIFS(N$69:N$133,$R$69:$R$133,$B6) -> 9206320283 | O6: =SUMIFS(O$69:O$133,$R$69:$R$133,$B6) -> -394075814
B7: 매출원가 | D7: =SUMIFS(D$69:D$133,$R$69:$R$133,$B7) -> 3634217621 | E7: =SUMIFS(E$69:E$133,$R$69:$R$133,$B7) -> 3581100990 | G7: =SUMIFS(G$69:G$133,$R$69:$R$133,$B7) -> 3596633522 | H7: =SUMIFS(H$69:H$133,$R$69:$R$133,$B7) -> 0 | I7: =SUMIFS(I$69:I$133,$R$69:$R$133,$B7) -> 378103308 | J7: =SUMIFS(J$69:J$133,$R$69:$R$133,$B7) -> 24568846 | K7: =SUMIFS(K$69:K$133,$R$69:$R$133,$B7) -> 0 | L7: =SUMIFS(L$69:L$133,$R$69:$R$133,$B7) -> 0 | M7: =SUMIFS(M$69:M$133,$R$69:$R$133,$B7) -> 0 | N7: =SUMIFS(N$69:N$133,$R$69:$R$133,$B7) -> 3999305676 | O7: =SUMIFS(O$69:O$133,$R$69:$R$133,$B7) -> -365088055
B8: 매출총이익 | D8: =D6-D7 -> 5178026848 | E8: =E6-E7 -> 5860064977 | G8: =G6-G7 -> 4691537165 | H8: =H6-H7 -> 0 | I8: =I6-I7 -> 429524358 | J8: =J6-J7 -> 85953084 | K8: =K6-K7 -> 0 | L8: =L6-L7 -> 0 | M8: =M6-M7 -> 0 | N8: =N6-N7 -> 5207014607 | O8: =O6-O7 -> -28987759
B9: 판매비와관리비 | D9: =SUMIFS(D$69:D$133,$R$69:$R$133,$B9) -> 5969068326 | E9: =SUMIFS(E$69:E$133,$R$69:$R$133,$B9) -> 4763859751 | G9: =SUMIFS(G$69:G$133,$R$69:$R$133,$B9) -> 5378351282 | H9: =SUMIFS(H$69:H$133,$R$69:$R$133,$B9) -> 0 | I9: =SUMIFS(I$69:I$133,$R$69:$R$133,$B9) -> 382954300 | J9: =SUMIFS(J$69:J$133,$R$69:$R$133,$B9) -> 182867798 | K9: =SUMIFS(K$69:K$133,$R$69:$R$133,$B9) -> 15619049 | L9: =SUMIFS(L$69:L$133,$R$69:$R$133,$B9) -> 8656005 | M9: =SUMIFS(M$69:M$133,$R$69:$R$133,$B9) -> 0 | N9: =SUMIFS(N$69:N$133,$R$69:$R$133,$B9) -> 5968448434 | O9: =SUMIFS(O$69:O$133,$R$69:$R$133,$B9) -> 619892
B10: 기타영업수익 | D10: =SUMIFS(D$69:D$133,$R$69:$R$133,$B10) -> 189101679 | E10: =SUMIFS(E$69:E$133,$R$69:$R$133,$B10) -> 28740950 | G10: =SUMIFS(G$69:G$133,$R$69:$R$133,$B10) -> 151841271 | H10: =SUMIFS(H$69:H$133,$R$69:$R$133,$B10) -> 0 | I10: =SUMIFS(I$69:I$133,$R$69:$R$133,$B10) -> 8686 | J10: =SUMIFS(J$69:J$133,$R$69:$R$133,$B10) -> 1183 | K10: =SUMIFS(K$69:K$133,$R$69:$R$133,$B10) -> 37250539 | L10: =SUMIFS(L$69:L$133,$R$69:$R$133,$B10) -> 0 | M10: =SUMIFS(M$69:M$133,$R$69:$R$133,$B10) -> 0 | N10: =SUMIFS(N$69:N$133,$R$69:$R$133,$B10) -> 189101679 | O10: =SUMIFS(O$69:O$133,$R$69:$R$133,$B10) -> 0
B11: 기타영업비용 | D11: =SUMIFS(D$69:D$133,$R$69:$R$133,$B11) -> 183777316 | E11: =SUMIFS(E$69:E$133,$R$69:$R$133,$B11) -> 106582748 | G11: =SUMIFS(G$69:G$133,$R$69:$R$133,$B11) -> 177020574 | H11: =SUMIFS(H$69:H$133,$R$69:$R$133,$B11) -> 0 | I11: =SUMIFS(I$69:I$133,$R$69:$R$133,$B11) -> 2371511 | J11: =SUMIFS(J$69:J$133,$R$69:$R$133,$B11) -> 12851 | K11: =SUMIFS(K$69:K$133,$R$69:$R$133,$B11) -> 4342354 | L11: =SUMIFS(L$69:L$133,$R$69:$R$133,$B11) -> 30026 | M11: =SUMIFS(M$69:M$133,$R$69:$R$133,$B11) -> 0 | N11: =SUMIFS(N$69:N$133,$R$69:$R$133,$B11) -> 183777316 | O11: =SUMIFS(O$69:O$133,$R$69:$R$133,$B11) -> 0
B12: 영업손익 | D12: =D8-D9+D10-D11 -> -785717115 | E12: =E8-E9+E10-E11 -> 1018363428 | G12: =G8-G9+G10-G11 -> -711993420 | H12: =H8-H9+H10-H11 -> 0 | I12: =I8-I9+I10-I11 -> 44207233 | J12: =J8-J9+J10-J11 -> -96926382 | K12: =K8-K9+K10-K11 -> 17289136 | L12: =L8-L9+L10-L11 -> -8686031 | M12: =M8-M9+M10-M11 -> 0 | N12: =N8-N9+N10-N11 -> -756109464 | O12: =O8-O9+O10-O11 -> -29607651
B14: Ⅱ. 투자 범주
B15: 투자수익 | D15: =SUMIFS(D$69:D$133,$R$69:$R$133,$B15) -> 2090047231 | E15: =SUMIFS(E$69:E$133,$R$69:$R$133,$B15) -> 28253274 | G15: =SUMIFS(G$69:G$133,$R$69:$R$133,$B15) -> 22098561 | H15: =SUMIFS(H$69:H$133,$R$69:$R$133,$B15) -> 0 | I15: =SUMIFS(I$69:I$133,$R$69:$R$133,$B15) -> 658 | J15: =SUMIFS(J$69:J$133,$R$69:$R$133,$B15) -> 53 | K15: =SUMIFS(K$69:K$133,$R$69:$R$133,$B15) -> 2182 | L15: =SUMIFS(L$69:L$133,$R$69:$R$133,$B15) -> 0 | M15: =SUMIFS(M$69:M$133,$R$69:$R$133,$B15) -> 0 | N15: =SUMIFS(N$69:N$133,$R$69:$R$133,$B15) -> 22101454 | O15: =SUMIFS(O$69:O$133,$R$69:$R$133,$B15) -> 2067945777
B16: 투자비용 | D16: =SUMIFS(D$69:D$133,$R$69:$R$133,$B16) -> 2067945777 | E16: =SUMIFS(E$69:E$133,$R$69:$R$133,$B16) -> 0 | G16: =SUMIFS(G$69:G$133,$R$69:$R$133,$B16) -> 0 | H16: =SUMIFS(H$69:H$133,$R$69:$R$133,$B16) -> 0 | I16: =SUMIFS(I$69:I$133,$R$69:$R$133,$B16) -> 0 | J16: =SUMIFS(J$69:J$133,$R$69:$R$133,$B16) -> 0 | K16: =SUMIFS(K$69:K$133,$R$69:$R$133,$B16) -> 0 | L16: =SUMIFS(L$69:L$133,$R$69:$R$133,$B16) -> 0 | M16: =SUMIFS(M$69:M$133,$R$69:$R$133,$B16) -> 0 | N16: =SUMIFS(N$69:N$133,$R$69:$R$133,$B16) -> 0 | O16: =SUMIFS(O$69:O$133,$R$69:$R$133,$B16) -> 2067945777
B17: 투자손익 | D17: =D15-D16 -> 22101454 | E17: =E15-E16 -> 28253274 | G17: =G15-G16 -> 22098561 | H17: =H15-H16 -> 0 | I17: =I15-I16 -> 658 | J17: =J15-J16 -> 53 | K17: =K15-K16 -> 2182 | L17: =L15-L16 -> 0 | M17: =M15-M16 -> 0 | N17: =N15-N16 -> 22101454 | O17: =O15-O16 -> 0
B18: 재무 및 법인세 전 손익 | D18: =D12+D17 -> -763615661 | E18: =E12+E17 -> 1046616702 | G18: =G12+G17 -> -689894859 | H18: =H12+H17 -> 0 | I18: =I12+I17 -> 44207891 | J18: =J12+J17 -> -96926329 | K18: =K12+K17 -> 17291318 | L18: =L12+L17 -> -8686031 | M18: =M12+M17 -> 0 | N18: =N12+N17 -> -734008010 | O18: =O12+O17 -> -29607651
B20: Ⅲ. 재무 범주
B21: 재무수익 | D21: =SUMIFS(D$69:D$133,$R$69:$R$133,$B21) -> 0 | E21: =SUMIFS(E$69:E$133,$R$69:$R$133,$B21) -> 0 | G21: =SUMIFS(G$69:G$133,$R$69:$R$133,$B21) -> 0 | H21: =SUMIFS(H$69:H$133,$R$69:$R$133,$B21) -> 0 | I21: =SUMIFS(I$69:I$133,$R$69:$R$133,$B21) -> 0 | J21: =SUMIFS(J$69:J$133,$R$69:$R$133,$B21) -> 0 | K21: =SUMIFS(K$69:K$133,$R$69:$R$133,$B21) -> 0 | L21: =SUMIFS(L$69:L$133,$R$69:$R$133,$B21) -> 0 | M21: =SUMIFS(M$69:M$133,$R$69:$R$133,$B21) -> 0 | N21: =SUMIFS(N$69:N$133,$R$69:$R$133,$B21) -> 0 | O21: =SUMIFS(O$69:O$133,$R$69:$R$133,$B21) -> 0
B22: 재무비용 | D22: =SUMIFS(D$69:D$133,$R$69:$R$133,$B22) -> 98954951 | E22: =SUMIFS(E$69:E$133,$R$69:$R$133,$B22) -> 45786340 | G22: =SUMIFS(G$69:G$133,$R$69:$R$133,$B22) -> 98954951 | H22: =SUMIFS(H$69:H$133,$R$69:$R$133,$B22) -> 0 | I22: =SUMIFS(I$69:I$133,$R$69:$R$133,$B22) -> 0 | J22: =SUMIFS(J$69:J$133,$R$69:$R$133,$B22) -> 0 | K22: =SUMIFS(K$69:K$133,$R$69:$R$133,$B22) -> 0 | L22: =SUMIFS(L$69:L$133,$R$69:$R$133,$B22) -> 0 | M22: =SUMIFS(M$69:M$133,$R$69:$R$133,$B22) -> 0 | N22: =SUMIFS(N$69:N$133,$R$69:$R$133,$B22) -> 98954951 | O22: =SUMIFS(O$69:O$133,$R$69:$R$133,$B22) -> 0
B23: 재무손익 | D23: =D21-D22 -> -98954951 | E23: =E21-E22 -> -45786340 | G23: =G21-G22 -> -98954951 | H23: =H21-H22 -> 0 | I23: =I21-I22 -> 0 | J23: =J21-J22 -> 0 | K23: =K21-K22 -> 0 | L23: =L21-L22 -> 0 | M23: =M21-M22 -> 0 | N23: =N21-N22 -> -98954951 | O23: =O21-O22 -> 0
B25: 법인세비용차감전손익 | D25: =D18+D23 -> -862570612 | E25: =E18+E23 -> 1000830362 | G25: =G18+G23 -> -788849810 | H25: =H18+H23 -> 0 | I25: =I18+I23 -> 44207891 | J25: =J18+J23 -> -96926329 | K25: =K18+K23 -> 17291318 | L25: =L18+L23 -> -8686031 | M25: =M18+M23 -> 0 | N25: =N18+N23 -> -832962961 | O25: =O18+O23 -> -29607651
B26: 법인세비용 | D26: =SUMIFS(D$69:D$133,$R$69:$R$133,$B26) -> 4983889 | E26: =SUMIFS(E$69:E$133,$R$69:$R$133,$B26) -> 4894989 | G26: =SUMIFS(G$69:G$133,$R$69:$R$133,$B26) -> 0 | H26: =SUMIFS(H$69:H$133,$R$69:$R$133,$B26) -> 0 | I26: =SUMIFS(I$69:I$133,$R$69:$R$133,$B26) -> 0 | J26: =SUMIFS(J$69:J$133,$R$69:$R$133,$B26) -> 0 | K26: =SUMIFS(K$69:K$133,$R$69:$R$133,$B26) -> 0 | L26: =SUMIFS(L$69:L$133,$R$69:$R$133,$B26) -> 0 | M26: =SUMIFS(M$69:M$133,$R$69:$R$133,$B26) -> 0 | N26: =SUMIFS(N$69:N$133,$R$69:$R$133,$B26) -> 0 | O26: =SUMIFS(O$69:O$133,$R$69:$R$133,$B26) -> 4983889
B27: 당기순이익(손실) | D27: =D25-D26 -> -867554501 | E27: =E25-E26 -> 995935373 | G27: =G25-G26 -> -788849810 | H27: =H25-H26 -> 0 | I27: =I25-I26 -> 44207891 | J27: =J25-J26 -> -96926329 | K27: =K25-K26 -> 17291318 | L27: =L25-L26 -> -8686031 | M27: =M25-M26 -> 0 | N27: =N25-N26 -> -832962961 | O27: =O25-O26 -> -34591540
B28: 기타포괄손익(재분류 불가) | D28: =SUMIFS(D$69:D$133,$R$69:$R$133,$B28) -> 0 | E28: =SUMIFS(E$69:E$133,$R$69:$R$133,$B28) -> 0 | G28: =SUMIFS(G$69:G$133,$R$69:$R$133,$B28) -> 0 | H28: =SUMIFS(H$69:H$133,$R$69:$R$133,$B28) -> 0 | I28: =SUMIFS(I$69:I$133,$R$69:$R$133,$B28) -> 0 | J28: =SUMIFS(J$69:J$133,$R$69:$R$133,$B28) -> 0 | K28: =SUMIFS(K$69:K$133,$R$69:$R$133,$B28) -> 0 | L28: =SUMIFS(L$69:L$133,$R$69:$R$133,$B28) -> 0 | M28: =SUMIFS(M$69:M$133,$R$69:$R$133,$B28) -> 0 | N28: =SUMIFS(N$69:N$133,$R$69:$R$133,$B28) -> 0 | O28: =SUMIFS(O$69:O$133,$R$69:$R$133,$B28) -> 0
B29: 기타포괄손익(재분류 가능) | D29: =SUMIFS(D$69:D$133,$R$69:$R$133,$B29) -> 11298394 | E29: =SUMIFS(E$69:E$133,$R$69:$R$133,$B29) -> -26600734 | G29: =SUMIFS(G$69:G$133,$R$69:$R$133,$B29) -> 0 | H29: =SUMIFS(H$69:H$133,$R$69:$R$133,$B29) -> 0 | I29: =SUMIFS(I$69:I$133,$R$69:$R$133,$B29) -> 99968525 | J29: =SUMIFS(J$69:J$133,$R$69:$R$133,$B29) -> -77454021 | K29: =SUMIFS(K$69:K$133,$R$69:$R$133,$B29) -> -693420 | L29: =SUMIFS(L$69:L$133,$R$69:$R$133,$B29) -> 1741310 | M29: =SUMIFS(M$69:M$133,$R$69:$R$133,$B29) -> 0 | N29: =SUMIFS(N$69:N$133,$R$69:$R$133,$B29) -> 23562394 | O29: =SUMIFS(O$69:O$133,$R$69:$R$133,$B29) -> -12264000
B30: 기타포괄손익 | D30: =D28+D29 -> 11298394 | E30: =E28+E29 -> -26600734 | G30: =G28+G29 -> 0 | H30: =H28+H29 -> 0 | I30: =I28+I29 -> 99968525 | J30: =J28+J29 -> -77454021 | K30: =K28+K29 -> -693420 | L30: =L28+L29 -> 1741310 | M30: =M28+M29 -> 0 | N30: =N28+N29 -> 23562394 | O30: =O28+O29 -> -12264000
B31: 총포괄손익 | D31: =D27+D30 -> -856256107 | E31: =E27+E30 -> 969334639 | G31: =G27+G30 -> -788849810 | H31: =H27+H30 -> 0 | I31: =I27+I30 -> 144176416 | J31: =J27+J30 -> -174380350 | K31: =K27+K30 -> 16597898 | L31: =L27+L30 -> -6944721 | M31: =M27+M30 -> 0 | N31: =N27+N30 -> -809400567 | O31: =O27+O30 -> -46855540
B33: [검증] 기존 [연결PL] 대비 차이 (모두 0이어야 함)
B34: 당기순이익 - 연결PL | D34: =D27-연결PL!D101 -> 0 | E34: =E27-연결PL!E101 -> 0
B35: 총포괄손익 - 연결PL | D35: =D31-연결PL!D109 -> 0 | E35: =E31-연결PL!E109 -> 0
B36: 법인세비용차감전손익 - 연결PL | D36: =D25-연결PL!D99 -> 0 | E36: =E25-연결PL!E99 -> 0
B37: 기타포괄손익 - 연결PL | D37: =D30-연결PL!D104 -> 0 | E37: =E30-연결PL!E104 -> 0
B38: 당기순이익 - [PL]시트 연결열(Y113) | D38: =D27-PL!Y113 -> 0
B39: 단순합산+연결조정 = 연결 (당기순이익) | D39: =N27+O27-D27 -> 0
B40: 표시항목 미지정/오류 계정 수 | D40: =SUMPRODUCT(--ISNA(MATCH($R$69:$R$133,$B$140:$B$151,0))) -> 0
B41: 종합 검증 | D41: =IF(AND(SUMPRODUCT(ABS(D34:E37))=0,D38=0,D39=0,D40=0),"OK","확인필요") -> OK
B43: [조정표] 기존 영업이익 → IFRS 18 영업손익
B44: 기존 영업이익 (연결PL) | D44: =연결PL!D68 -> -791041478 | E44: =연결PL!E68 -> 1096205226
B45: (+) IFRS 18 영업 범주로 편입된 기존 영업외손익 (기타영업손익·외환손익 등) | D45: =SUMPRODUCT(($S$69:$S$133="영업")*($U$69:$U$133=0)*$T$69:$T$133*D$69:D$133) -> 5324363 | E45: =SUMPRODUCT(($S$69:$S$133="영업")*($U$69:$U$133=0)*$T$69:$T$133*E$69:E$133) -> -77841798
...

Sheet 연결CF
B1: 과목 | C1: =연결PL!D1 -> 46203 | D1: =C1-365 -> 45838 | L1: 과목 | M1: 45838
B2: Ⅰ.영업활동으로인한현금흐름 | C2: =C3+C36+C37+C38 -> 1202295393 | D2: =D3+D36+D37+D38 -> 1183882268 | L2: Ⅰ.영업활동으로인한현금흐름 | M2: =M3+M36+M37+M38 -> 1183882268 | N2: =M2-D2 -> 0
B3: 1.영업에서창출된현금 | C3: =C4+C5+C27 -> 1276280827 | D3: =D4+D5+D27 -> 1244383314 | L3: 1.영업에서창출된현금 | M3: =M4+M5+M27 -> 1244383314 | N3: =M3-D3 -> 0
B4: 가.당기순이익 | C4: =연결PL!D101 -> -867554501 | D4: =M4 -> 995935373 | L4: 가.당기순이익 | M4: 995935373 | N4: =M4-D4 -> 0
B5: 나.조정 | C5: =SUM(C6:C26) -> 917008474 | D5: =SUM(D6:D26) -> 1002829676 | E5: PL | F5: 차이 | L5: 나.조정 | M5: =SUM(M6:M26) -> 1002829676 | N5: =M5-D5 -> 0
B6: 대손상각비 | C6: =SUMIF(CF정산표!$F$179:$F$210,연결CF!B6,CF정산표!$H$179:$H$210) -> -83305712 | D6: =IFERROR(VLOOKUP(B6,$L$6:$M$65,2,0),) -> 56559960 | E6: =연결PL!D62 -> -83305712 | F6: =C6=E6 -> TRUE | L6: 대손상각비 | M6: 56559960
B7: 이자수익 | C7: =SUMIF(CF정산표!$F$179:$F$210,연결CF!B7,CF정산표!$H$179:$H$210) -> -22101454 | D7: =IFERROR(VLOOKUP(B7,$L$6:$M$65,2,0),) -> -28253274 | E7: =연결PL!D86 -> 22101454 | F7: =C7=-E7 -> TRUE | L7: 이자수익 | M7: -28253274
B8: 유형자산처분이익 | C8: =SUMIF(CF정산표!$F$179:$F$210,연결CF!B8,CF정산표!$H$179:$H$210) -> -1202135 | D8: =IFERROR(VLOOKUP(B8,$L$6:$M$65,2,0),) -> -1054000 | E8: =연결PL!D74 -> 1202135 | F8: =E8=-C8 -> TRUE | L8: 유형자산처분이익 | M8: -1054000
B9: 외화환산이익 | C9: =SUMIF(CF정산표!$F$179:$F$210,연결CF!B9,CF정산표!$H$179:$H$210) -> -37603839 | D9: =IFERROR(VLOOKUP(B9,$L$6:$M$65,2,0),) -> -3042 | E9: =연결PL!D89 -> 37603839 | F9: =C9--E9 -> 0 | L9: 외화환산이익 | M9: -3042
B10: 재고자산평가손실(환입) | C10: =SUMIF(CF정산표!$F$179:$F$210,연결CF!B10,CF정산표!$H$179:$H$210) -> 131193174 | D10: =IFERROR(VLOOKUP(B10,$L$6:$M$65,2,0),) -> 15216604 | L10: 재고자산평가손실(환입) | M10: 15216604
B11: 퇴직급여 | C11: =SUMIF(CF정산표!$F$179:$F$210,연결CF!B11,CF정산표!$H$179:$H$210) -> 188019390 | D11: =IFERROR(VLOOKUP(B11,$L$6:$M$65,2,0),) -> 177665682 | E11: ='20'!C21 -> 188019390 | F11: =E11=C11 -> TRUE | L11: 퇴직급여 | M11: 177665682
B12: 주식보상비 | C12: =SUMIF(CF정산표!$F$179:$F$210,연결CF!B12,CF정산표!$H$179:$H$210) -> 0 | D12: =IFERROR(VLOOKUP(B12,$L$6:$M$65,2,0),) -> 0 | E12: =연결PL!D39 -> 0 | F12: =C12=E12 -> TRUE | L12: 주식보상비 | M12: 0
B13: 이자비용 | C13: =SUMIF(CF정산표!$F$179:$F$210,연결CF!B13,CF정산표!$H$179:$H$210) -> 98954951 | D13: =IFERROR(VLOOKUP(B13,$L$6:$M$65,2,0),) -> 45786340 | E13: =연결PL!D91 -> 98954951 | F13: =C13=E13 -> TRUE | L13: 이자비용 | M13: 45786340
B14: 감가상각비 | C14: =SUMIF(CF정산표!$F$179:$F$210,연결CF!B14,CF정산표!$H$179:$H$210) -> 585661920 | D14: =IFERROR(VLOOKUP(B14,$L$6:$M$65,2,0),) -> 497372122 | E14: ='28'!D13 -> 607191027 | F14: =C14+C15-E14 -> 0 | L14: 감가상각비 | M14: 497372122
B15: 무형자산상각비 | C15: =SUMIF(CF정산표!$F$179:$F$210,연결CF!B15,CF정산표!$H$179:$H$210) -> 21529107 | D15: =IFERROR(VLOOKUP(B15,$L$6:$M$65,2,0),) -> 144426793 | E15: =-'13'!F27 -> 21529107 | F15: =C15+C16-E15 -> 0 | L15: 무형자산상각비 | M15: 144426793
B16: 영업권손상차손 | C16: =SUMIF(CF정산표!$F$179:$F$210,연결CF!B16,CF정산표!$H$179:$H$210) -> 0 | D16: =IFERROR(VLOOKUP(B16,$L$6:$M$65,2,0),) -> 0 | L16: 영업권손상차손 | M16: 0
B17: 유형자산처분손실 | C17: =SUMIF(CF정산표!$F$179:$F$210,연결CF!B17,CF정산표!$H$179:$H$210) -> 4825402 | D17: =IFERROR(VLOOKUP(B17,$L$6:$M$65,2,0),) -> 3098042 | E17: =연결PL!D81 -> 4825402 | F17: =C17-E17 -> 0 | L17: 유형자산처분손실 | M17: 3098042
B18: 외화환산손실 | C18: =SUMIF(CF정산표!$F$179:$F$210,연결CF!B18,CF정산표!$H$179:$H$210) -> 2 | D18: =IFERROR(VLOOKUP(B18,$L$6:$M$65,2,0),) -> 58201925 | E18: =연결PL!D95 -> 2 | F18: =C18-E18 -> 0 | L18: 외화환산손실 | M18: 58201925
B19: 법인세비용 | C19: =SUMIF(CF정산표!$F$179:$F$210,연결CF!B19,CF정산표!$H$179:$H$210) -> 4983889 | D19: =IFERROR(VLOOKUP(B19,$L$6:$M$65,2,0),) -> 4894989 | E19: =연결PL!D100 -> 4983889 | F19: =C19-E19 -> 0 | L19: 법인세비용 | M19: 4894989
B20: 복리후생비 | C20: =SUMIF(CF정산표!$F$179:$F$210,연결CF!B20,CF정산표!$H$179:$H$210) -> 37001898 | D20: =IFERROR(VLOOKUP(B20,$L$6:$M$65,2,0),) -> 34571148 | L20: 복리후생비 | M20: 34571148
B21: 상환전환우선주부채평가손실 | C21: =SUMIF(CF정산표!$F$179:$F$210,연결CF!B21,CF정산표!$H$179:$H$210) -> 0 | D21: =IFERROR(VLOOKUP(B21,$L$6:$M$65,2,0),) -> 0 | L21: 상환전환우선주부채평가손실 | M21: 0
B22: 당기손익공정가치측정금융자산평가손실 | C22: =SUMIF(CF정산표!$F$179:$F$210,연결CF!B22,CF정산표!$H$179:$H$210) -> 0 | D22: =IFERROR(VLOOKUP(B22,$L$6:$M$65,2,0),) -> 0 | E22: =연결PL!D92 -> 0 | F22: =C22=E22 -> TRUE | L22: 사채상환손실 | M22: 0
B23: 기타의 대손상각비(환입) | C23: =SUMIF(CF정산표!$F$179:$F$210,연결CF!B23,CF정산표!$H$179:$H$210) -> -3000000 | D23: =IFERROR(VLOOKUP(B23,$L$6:$M$65,2,0),) -> -3000000 | E23: =-연결PL!D73 -> -3000000 | F23: =C23=E23 -> TRUE | L23: 기타의 대손상각비(환입) | M23: -3000000
B24: 관계기업투자주식처분이익 | C24: =SUMIF(CF정산표!$F$179:$F$210,연결CF!B24,CF정산표!$H$179:$H$210) -> -2067945777 | D24: =IFERROR(VLOOKUP(B24,$L$6:$M$65,2,0),) -> 0 | L24: 관계기업투자주식처분손실 | M24: 0
B25: 지분법손실 | C25: =SUMIF(CF정산표!$F$179:$F$210,연결CF!B25,CF정산표!$H$179:$H$210) -> 2067945777 | D25: =IFERROR(VLOOKUP(B25,$L$6:$M$65,2,0),) -> 0 | E25: =연결PL!D98 -> 2067945777 | F25: =C25-E25 -> 0 | L25: 관계기업투자이익 | M25: 0
B26: 환불부채 | C26: =SUMIF(CF정산표!$F$179:$F$210,연결CF!B26,CF정산표!$H$179:$H$210) -> -7948119 | D26: =IFERROR(VLOOKUP(B26,$L$6:$M$65,2,0),) -> -2653613 | L26: 환불부채 | M26: -2653613
B27: 다.영업활동으로인한자산부채의변동 | C27: =SUM(C28:C35) -> 1226826854 | D27: =SUM(D28:D35) -> -754381735 | E27: =CF정산표!N170 -> 1226826854 | F27: =E27=C27 -> TRUE | L27: 다.영업활동으로인한자산부채의변동 | M27: =SUM(M28:M35) -> -754381735
B28: 매출채권및기타채권의 감소(증가) | C28: =SUMIF(CF정산표!$K$179:$K$199,연결CF!B28,CF정산표!$N$179:$N$199) -> 502587042 | D28: =IFERROR(VLOOKUP(B28,$L$6:$M$65,2,0),) -> -146111841 | L28: 매출채권및기타채권의 감소(증가) | M28: -146111841
B29: 기타유동자산의 감소(증가) | C29: =SUMIF(CF정산표!$K$179:$K$199,연결CF!B29,CF정산표!$N$179:$N$199) -> 433657614 | D29: =IFERROR(VLOOKUP(B29,$L$6:$M$65,2,0),) -> -140049917 | L29: 기타유동자산의 감소(증가) | M29: -140049917
B30: 재고자산의 감소(증가) | C30: =SUMIF(CF정산표!$K$179:$K$199,연결CF!B30,CF정산표!$N$179:$N$199) -> -326232101 | D30: =IFERROR(VLOOKUP(B30,$L$6:$M$65,2,0),) -> 77359122 | L30: 재고자산의 감소(증가) | M30: 77359122
B31: 매입채무및기타채무의 증가(감소) | C31: =SUMIF(CF정산표!$K$179:$K$199,연결CF!B31,CF정산표!$N$179:$N$199) -> 1866250998 | D31: =IFERROR(VLOOKUP(B31,$L$6:$M$65,2,0),) -> -456512459 | L31: 매입채무및기타채무의 증가(감소) | M31: -456512459
B32: 임차보증금유동 | C32: =SUMIF(CF정산표!$K$179:$K$199,연결CF!B32,CF정산표!$N$179:$N$199) -> 0 | D32: =IFERROR(VLOOKUP(B32,$L$6:$M$65,2,0),) -> 0 | L32: 임차보증금유동 | M32: 0
B33: 기타유동부채의 증가(감소) | C33: =SUMIF(CF정산표!$K$179:$K$199,연결CF!B33,CF정산표!$N$179:$N$199) -> -180207725 | D33: =IFERROR(VLOOKUP(B33,$L$6:$M$65,2,0),) -> -27252178 | L33: 기타유동부채의 증가(감소) | M33: -27252178
B34: 기타장기종업원급여의 증가(감소) | C34: =SUMIF(CF정산표!$K$179:$K$199,연결CF!B34,CF정산표!$N$179:$N$199) -> -4380000 | D34: =IFERROR(VLOOKUP(B34,$L$6:$M$65,2,0),) -> 0 | L34: 기타장기종업원급여의 증가(감소) | M34: 0
B35: 퇴직금의 지급 | C35: =SUMIF(CF정산표!$K$179:$K$199,연결CF!B35,CF정산표!$N$179:$N$199) -> -1064848974 | D35: =IFERROR(VLOOKUP(B35,$L$6:$M$65,2,0),) -> -61814462 | L35: 퇴직금의 지급 | M35: -61814462
B36: 2.이자의수취 | C36: =SUMIF(CF정산표!$K$179:$K$199,연결CF!B36,CF정산표!$N$179:$N$199) -> 14072249 | D36: =IFERROR(VLOOKUP(B36,$L$6:$M$65,2,0),) -> 21717532 | L36: 2.이자의수취 | M36: 21717532
B37: 3.이자의지급 | C37: =SUMIF(CF정산표!$K$179:$K$199,연결CF!B37,CF정산표!$N$179:$N$199) -> -91837405 | D37: =IFERROR(VLOOKUP(B37,$L$6:$M$65,2,0),) -> -84792594 | L37: 3.이자의지급 | M37: -84792594
B38: 4.법인세등환급액(부담액) | C38: =SUMIF(CF정산표!$K$179:$K$199,연결CF!B38,CF정산표!$N$179:$N$199) -> 3779722 | D38: =IFERROR(VLOOKUP(B38,$L$6:$M$65,2,0),) -> 2574016 | L38: 4.법인세등환급액(부담액) | M38: 2574016
B39: Ⅱ.투자활동으로인한현금흐름 | C39: =C40+C46 -> -8347846978 | D39: =D40+D46 -> -520360666 | L39: Ⅱ.투자활동으로인한현금흐름 | M39: =M40+M46 -> -520360666 | N39: =M39-D39 -> 0
B40: 1. 투자활동으로 인한 현금유입액 | C40: =SUM(C41:C45) -> 18208436 | D40: =SUM(D41:D45) -> 28087257 | L40: 1. 투자활동으로 인한 현금유입액 | M40: =SUM(M41:M45) -> 28087257
...

Sheet 연결CF_IFRS18
B1: 연결 현금흐름표 (IFRS 18 / IAS 7 개정 기준)
B2: ※ [연결CF] 시트 금액을 연동. IFRS 18(IAS 7 개정): ①간접법 출발점을 영업손익으로 변경 ②이자·배당 수취는 투자, 이자·배당 지급은 재무로 고정 ③영업손익에 포함되지 않는 손익(투자·재무·법인세)은 조정항목에서 제외
B3: 과목 | D3: =연결CF!C1 -> 46203 | E3: =연결CF!D1 -> 45838 | G3: 손익 범주 판정용 계정과목 (입력) | H3: IFRS 18 구분 | I3: 비고
B4: Ⅰ.영업활동으로인한현금흐름 | D4: =D5+D38 -> 1280060549 | E4: =E5+E38 -> 1246957330
B5: 1.영업에서창출된현금 | D5: =D6+D7+D29 -> 1276280827 | E5: =E6+E7+E29 -> 1244383314
B6: 가.영업손익 (IFRS 18) | D6: ='연결PL_IFRS18'!D12 -> -785717115 | E6: ='연결PL_IFRS18'!E12 -> 1018363428
B7: 나.조정 (영업손익에 포함된 비현금 항목) | D7: =SUM(D8:D28) -> 835171088 | E7: =SUM(E8:E28) -> 980401621
B8: =연결CF!B6 -> 대손상각비 | D8: =IF($H8="영업",연결CF!C6,0) -> -83305712 | E8: =IF($H8="영업",연결CF!D6,0) -> 56559960 | G8: 대손상각비 | H8: =IF(G8="","영업",IFERROR(INDEX('연결PL_IFRS18'!$S$69:$S$133,MATCH(G8,'연결PL_IFRS18'!$B$69:$B$133,0)),"오류")) -> 영업 | I8: =IF(H8="영업","",IF(H8="오류","계정과목명 확인 필요","영업손익 미포함 → 조정 제외"))
B9: =연결CF!B7 -> 이자수익 | D9: =IF($H9="영업",연결CF!C7,0) -> 0 | E9: =IF($H9="영업",연결CF!D7,0) -> 0 | G9: 이자수익 | H9: =IF(G9="","영업",IFERROR(INDEX('연결PL_IFRS18'!$S$69:$S$133,MATCH(G9,'연결PL_IFRS18'!$B$69:$B$133,0)),"오류")) -> 투자 | I9: =IF(H9="영업","",IF(H9="오류","계정과목명 확인 필요","영업손익 미포함 → 조정 제외")) -> 영업손익 미포함 → 조정 제외
B10: =연결CF!B8 -> 유형자산처분이익 | D10: =IF($H10="영업",연결CF!C8,0) -> -1202135 | E10: =IF($H10="영업",연결CF!D8,0) -> -1054000 | G10: 유형자산처분이익 | H10: =IF(G10="","영업",IFERROR(INDEX('연결PL_IFRS18'!$S$69:$S$133,MATCH(G10,'연결PL_IFRS18'!$B$69:$B$133,0)),"오류")) -> 영업 | I10: =IF(H10="영업","",IF(H10="오류","계정과목명 확인 필요","영업손익 미포함 → 조정 제외"))
B11: =연결CF!B9 -> 외화환산이익 | D11: =IF($H11="영업",연결CF!C9,0) -> -37603839 | E11: =IF($H11="영업",연결CF!D9,0) -> -3042 | G11: 외화환산이익 | H11: =IF(G11="","영업",IFERROR(INDEX('연결PL_IFRS18'!$S$69:$S$133,MATCH(G11,'연결PL_IFRS18'!$B$69:$B$133,0)),"오류")) -> 영업 | I11: =IF(H11="영업","",IF(H11="오류","계정과목명 확인 필요","영업손익 미포함 → 조정 제외"))
B12: =연결CF!B10 -> 재고자산평가손실(환입) | D12: =IF($H12="영업",연결CF!C10,0) -> 131193174 | E12: =IF($H12="영업",연결CF!D10,0) -> 15216604 | H12: =IF(G12="","영업",IFERROR(INDEX('연결PL_IFRS18'!$S$69:$S$133,MATCH(G12,'연결PL_IFRS18'!$B$69:$B$133,0)),"오류")) -> 영업 | I12: =IF(H12="영업","",IF(H12="오류","계정과목명 확인 필요","영업손익 미포함 → 조정 제외"))
B13: =연결CF!B11 -> 퇴직급여 | D13: =IF($H13="영업",연결CF!C11,0) -> 188019390 | E13: =IF($H13="영업",연결CF!D11,0) -> 177665682 | G13: 퇴직급여 | H13: =IF(G13="","영업",IFERROR(INDEX('연결PL_IFRS18'!$S$69:$S$133,MATCH(G13,'연결PL_IFRS18'!$B$69:$B$133,0)),"오류")) -> 영업 | I13: =IF(H13="영업","",IF(H13="오류","계정과목명 확인 필요","영업손익 미포함 → 조정 제외"))
B14: =연결CF!B12 -> 주식보상비 | D14: =IF($H14="영업",연결CF!C12,0) -> 0 | E14: =IF($H14="영업",연결CF!D12,0) -> 0 | G14: 주식보상비 | H14: =IF(G14="","영업",IFERROR(INDEX('연결PL_IFRS18'!$S$69:$S$133,MATCH(G14,'연결PL_IFRS18'!$B$69:$B$133,0)),"오류")) -> 영업 | I14: =IF(H14="영업","",IF(H14="오류","계정과목명 확인 필요","영업손익 미포함 → 조정 제외"))
B15: =연결CF!B13 -> 이자비용 | D15: =IF($H15="영업",연결CF!C13,0) -> 0 | E15: =IF($H15="영업",연결CF!D13,0) -> 0 | G15: 이자비용 | H15: =IF(G15="","영업",IFERROR(INDEX('연결PL_IFRS18'!$S$69:$S$133,MATCH(G15,'연결PL_IFRS18'!$B$69:$B$133,0)),"오류")) -> 재무 | I15: =IF(H15="영업","",IF(H15="오류","계정과목명 확인 필요","영업손익 미포함 → 조정 제외")) -> 영업손익 미포함 → 조정 제외
B16: =연결CF!B14 -> 감가상각비 | D16: =IF($H16="영업",연결CF!C14,0) -> 585661920 | E16: =IF($H16="영업",연결CF!D14,0) -> 497372122 | G16: 감가상각비 | H16: =IF(G16="","영업",IFERROR(INDEX('연결PL_IFRS18'!$S$69:$S$133,MATCH(G16,'연결PL_IFRS18'!$B$69:$B$133,0)),"오류")) -> 영업 | I16: =IF(H16="영업","",IF(H16="오류","계정과목명 확인 필요","영업손익 미포함 → 조정 제외"))
B17: =연결CF!B15 -> 무형자산상각비 | D17: =IF($H17="영업",연결CF!C15,0) -> 21529107 | E17: =IF($H17="영업",연결CF!D15,0) -> 144426793 | G17: 무형고정자산상각 | H17: =IF(G17="","영업",IFERROR(INDEX('연결PL_IFRS18'!$S$69:$S$133,MATCH(G17,'연결PL_IFRS18'!$B$69:$B$133,0)),"오류")) -> 영업 | I17: =IF(H17="영업","",IF(H17="오류","계정과목명 확인 필요","영업손익 미포함 → 조정 제외"))
B18: =연결CF!B16 -> 영업권손상차손 | D18: =IF($H18="영업",연결CF!C16,0) -> 0 | E18: =IF($H18="영업",연결CF!D16,0) -> 0 | H18: =IF(G18="","영업",IFERROR(INDEX('연결PL_IFRS18'!$S$69:$S$133,MATCH(G18,'연결PL_IFRS18'!$B$69:$B$133,0)),"오류")) -> 영업 | I18: =IF(H18="영업","",IF(H18="오류","계정과목명 확인 필요","영업손익 미포함 → 조정 제외"))
B19: =연결CF!B17 -> 유형자산처분손실 | D19: =IF($H19="영업",연결CF!C17,0) -> 4825402 | E19: =IF($H19="영업",연결CF!D17,0) -> 3098042 | G19: 유형자산처분손실 | H19: =IF(G19="","영업",IFERROR(INDEX('연결PL_IFRS18'!$S$69:$S$133,MATCH(G19,'연결PL_IFRS18'!$B$69:$B$133,0)),"오류")) -> 영업 | I19: =IF(H19="영업","",IF(H19="오류","계정과목명 확인 필요","영업손익 미포함 → 조정 제외"))
B20: =연결CF!B18 -> 외화환산손실 | D20: =IF($H20="영업",연결CF!C18,0) -> 2 | E20: =IF($H20="영업",연결CF!D18,0) -> 58201925 | G20: 외화환산손실 | H20: =IF(G20="","영업",IFERROR(INDEX('연결PL_IFRS18'!$S$69:$S$133,MATCH(G20,'연결PL_IFRS18'!$B$69:$B$133,0)),"오류")) -> 영업 | I20: =IF(H20="영업","",IF(H20="오류","계정과목명 확인 필요","영업손익 미포함 → 조정 제외"))
B21: =연결CF!B19 -> 법인세비용 | D21: =IF($H21="영업",연결CF!C19,0) -> 0 | E21: =IF($H21="영업",연결CF!D19,0) -> 0 | G21: 법인세비용 | H21: =IF(G21="","영업",IFERROR(INDEX('연결PL_IFRS18'!$S$69:$S$133,MATCH(G21,'연결PL_IFRS18'!$B$69:$B$133,0)),"오류")) -> 법인세 | I21: =IF(H21="영업","",IF(H21="오류","계정과목명 확인 필요","영업손익 미포함 → 조정 제외")) -> 영업손익 미포함 → 조정 제외
B22: =연결CF!B20 -> 복리후생비 | D22: =IF($H22="영업",연결CF!C20,0) -> 37001898 | E22: =IF($H22="영업",연결CF!D20,0) -> 34571148 | H22: =IF(G22="","영업",IFERROR(INDEX('연결PL_IFRS18'!$S$69:$S$133,MATCH(G22,'연결PL_IFRS18'!$B$69:$B$133,0)),"오류")) -> 영업 | I22: =IF(H22="영업","",IF(H22="오류","계정과목명 확인 필요","영업손익 미포함 → 조정 제외"))
B23: =연결CF!B21 -> 상환전환우선주부채평가손실 | D23: =IF($H23="영업",연결CF!C21,0) -> 0 | E23: =IF($H23="영업",연결CF!D21,0) -> 0 | H23: =IF(G23="","영업",IFERROR(INDEX('연결PL_IFRS18'!$S$69:$S$133,MATCH(G23,'연결PL_IFRS18'!$B$69:$B$133,0)),"오류")) -> 영업 | I23: =IF(H23="영업","",IF(H23="오류","계정과목명 확인 필요","영업손익 미포함 → 조정 제외"))
B24: =연결CF!B22 -> 당기손익공정가치측정금융자산평가손실 | D24: =IF($H24="영업",연결CF!C22,0) -> 0 | E24: =IF($H24="영업",연결CF!D22,0) -> 0 | G24: 당기손익-공정가치측정금융자산평가손실 | H24: =IF(G24="","영업",IFERROR(INDEX('연결PL_IFRS18'!$S$69:$S$133,MATCH(G24,'연결PL_IFRS18'!$B$69:$B$133,0)),"오류")) -> 투자 | I24: =IF(H24="영업","",IF(H24="오류","계정과목명 확인 필요","영업손익 미포함 → 조정 제외")) -> 영업손익 미포함 → 조정 제외
B25: =연결CF!B23 -> 기타의 대손상각비(환입) | D25: =IF($H25="영업",연결CF!C23,0) -> -3000000 | E25: =IF($H25="영업",연결CF!D23,0) -> -3000000 | G25: 기타의대손상각비환입 | H25: =IF(G25="","영업",IFERROR(INDEX('연결PL_IFRS18'!$S$69:$S$133,MATCH(G25,'연결PL_IFRS18'!$B$69:$B$133,0)),"오류")) -> 영업 | I25: =IF(H25="영업","",IF(H25="오류","계정과목명 확인 필요","영업손익 미포함 → 조정 제외"))
B26: =연결CF!B24 -> 관계기업투자주식처분이익 | D26: =IF($H26="영업",연결CF!C24,0) -> 0 | E26: =IF($H26="영업",연결CF!D24,0) -> 0 | G26: 관계기업투자주식처분이익 | H26: =IF(G26="","영업",IFERROR(INDEX('연결PL_IFRS18'!$S$69:$S$133,MATCH(G26,'연결PL_IFRS18'!$B$69:$B$133,0)),"오류")) -> 투자 | I26: =IF(H26="영업","",IF(H26="오류","계정과목명 확인 필요","영업손익 미포함 → 조정 제외")) -> 영업손익 미포함 → 조정 제외
B27: =연결CF!B25 -> 지분법손실 | D27: =IF($H27="영업",연결CF!C25,0) -> 0 | E27: =IF($H27="영업",연결CF!D25,0) -> 0 | G27: 관계기업투자손실 | H27: =IF(G27="","영업",IFERROR(INDEX('연결PL_IFRS18'!$S$69:$S$133,MATCH(G27,'연결PL_IFRS18'!$B$69:$B$133,0)),"오류")) -> 투자 | I27: =IF(H27="영업","",IF(H27="오류","계정과목명 확인 필요","영업손익 미포함 → 조정 제외")) -> 영업손익 미포함 → 조정 제외
B28: =연결CF!B26 -> 환불부채 | D28: =IF($H28="영업",연결CF!C26,0) -> -7948119 | E28: =IF($H28="영업",연결CF!D26,0) -> -2653613 | H28: =IF(G28="","영업",IFERROR(INDEX('연결PL_IFRS18'!$S$69:$S$133,MATCH(G28,'연결PL_IFRS18'!$B$69:$B$133,0)),"오류")) -> 영업 | I28: =IF(H28="영업","",IF(H28="오류","계정과목명 확인 필요","영업손익 미포함 → 조정 제외"))
B29: 다.영업활동으로인한자산부채의변동 | D29: =SUM(D30:D37) -> 1226826854 | E29: =SUM(E30:E37) -> -754381735
B30: =연결CF!B28 -> 매출채권및기타채권의 감소(증가) | D30: =연결CF!C28 -> 502587042 | E30: =연결CF!D28 -> -146111841
B31: =연결CF!B29 -> 기타유동자산의 감소(증가) | D31: =연결CF!C29 -> 433657614 | E31: =연결CF!D29 -> -140049917
B32: =연결CF!B30 -> 재고자산의 감소(증가) | D32: =연결CF!C30 -> -326232101 | E32: =연결CF!D30 -> 77359122
B33: =연결CF!B31 -> 매입채무및기타채무의 증가(감소) | D33: =연결CF!C31 -> 1866250998 | E33: =연결CF!D31 -> -456512459
B34: =연결CF!B32 -> 임차보증금유동 | D34: =연결CF!C32 -> 0 | E34: =연결CF!D32 -> 0
B35: =연결CF!B33 -> 기타유동부채의 증가(감소) | D35: =연결CF!C33 -> -180207725 | E35: =연결CF!D33 -> -27252178
B36: =연결CF!B34 -> 기타장기종업원급여의 증가(감소) | D36: =연결CF!C34 -> -4380000 | E36: =연결CF!D34 -> 0
B37: =연결CF!B35 -> 퇴직금의 지급 | D37: =연결CF!C35 -> -1064848974 | E37: =연결CF!D35 -> -61814462
B38: 2.법인세등환급액(부담액) | D38: =연결CF!C38 -> 3779722 | E38: =연결CF!D38 -> 2574016
B39: Ⅱ.투자활동으로인한현금흐름 | D39: =D40+D48 -> -8333774729 | E39: =E40+E48 -> -498643134
B40: 1.투자활동으로 인한 현금유입액 | D40: =SUM(D41:D47) -> 32280685 | E40: =SUM(E41:E47) -> 49804789
...

Sheet 연결CE
B2: 자본변동표
B3: 과목 | C3: 자본금 | D3: 자본잉여금 | E3: 기타자본항목 | F3: 이익잉여금(결손금) | G3: 비지배지분 | H3: 총계
B4: 2025.01.01(전기초) | C4: 3123279500 | D4: 12384121289 | E4: 429109150 | F4: -9977866938 | G4: 0 | H4: =SUM(C4:G4) -> 5958643001 | I4: 5958643001 | J4: =I4-H4 -> 0
B5: 총포괄손익:
B6: 당기순이익 | C6: 0 | D6: 0 | E6: 0 | F6: 989649425 | G6: 0 | H6: =SUM(C6:G6) -> 989649425
B7: 순확정급여부채의 재측정요소 | C7: 0 | D7: 0 | E7: 0 | F7: 40134025 | G7: 0 | H7: =SUM(C7:G7) -> 40134025
B8: 해외사업장환산외환차이 | C8: 0 | D8: 0 | E8: -17279474 | F8: 0 | G8: 0 | H8: =SUM(C8:G8) -> -17279474
B9: 자본에 직접 반영된 소유주와의 거래:
B10: 유상증자 | C10: 2511000000 | D10: 32474515340 | E10: 0 | F10: 0 | G10: 0 | H10: =SUM(C10:G10) -> 34985515340
B11: 주식매수선택권의 행사 | C11: 56912000 | D11: 298745669 | E11: -88626565 | H11: =SUM(C11:G11) -> 267031104
B12: 주식보상비용 | C12: 0 | D12: 0 | E12: 135571460 | F12: 0 | G12: 0 | H12: =SUM(C12:G12) -> 135571460
B13: 2025.12.31(전기말) | C13: =SUM(C4:C12) -> 5691191500 | D13: =SUM(D4:D12) -> 45157382298 | E13: =SUM(E4:E12) -> 458774571 | F13: =SUM(F4:F12) -> -8948083488 | G13: =SUM(G4:G12) -> 0 | H13: =SUM(H4:H12) -> 42359264881 | I13: 42359264881 | J13: =I13-H13 -> 0 | K13: =J13=J4 -> TRUE
B14: 2026.01.01(당기초) | C14: 5691191500 | D14: 45157382298 | E14: 458774571 | F14: -8948083488 | G14: 0 | H14: =SUM(C14:G14) -> 42359264881
B15: 총포괄손익:
B16: 당기순이익 | C16: 0 | D16: 0 | E16: 0 | F16: =연결PL!D101 -> -867554501 | G16: =연결PL!D103 -> 0 | H16: =SUM(C16:G16) -> -867554501
B17: 순확정급여부채의 재측정요소 | C17: 0 | D17: 0 | E17: 0 | F17: =연결PL!D106 -> 0 | G17: 0 | H17: =SUM(C17:G17) -> 0
B18: 해외사업장환산외환차이 | C18: 0 | D18: 0 | E18: =연결PL!D108 -> 11298394 | F18: 0 | G18: 0 | H18: =SUM(C18:G18) -> 11298394
B19: 자본에 직접 반영된 소유주와의 거래:
B20: 유상증자 | C20: 0 | D20: 0 | E20: 0 | F20: 0 | G20: 0 | H20: =SUM(C20:G20) -> 0
B21: 주식매수선택권의 행사 | C21: 0 | D21: 0 | E21: 0 | F21: 0 | G21: 0 | H21: =SUM(C21:G21) -> 0
B22: 연결범위변동 | C22: 0 | D22: 0 | E22: 0 | F22: 0 | G22: =RIC!I73 -> 117986065 | H22: =SUM(C22:G22) -> 117986065
B23: 2026.12.31(당기말) | C23: =SUM(C14:C22) -> 5691191500 | D23: =SUM(D14:D22) -> 45157382298 | E23: =SUM(E14:E22) -> 470072965 | F23: =SUM(F14:F22) -> -9815637989 | G23: =SUM(G14:G22) -> 117986065 | H23: =SUM(H14:H22) -> 41620994839 | I23: =연결BS!D115 -> 41620994839 | J23: =I23-H23 -> 0
C25: =C14-연결BS!E105 -> 0 | D25: =D14-연결BS!E106 -> 0 | E25: =E14-연결BS!E109 -> 0 | F25: =F14-연결BS!E112 -> 0 | H25: =H14-연결BS!E115 -> 0
C26: =C23-연결BS!D104 -> 0 | D26: =D23-연결BS!D106 -> 0 | E26: =E23-연결BS!D109 -> 0 | F26: =F23-연결BS!D112 -> 0 | G26: =G23-연결BS!D114 -> 0 | H26: =H23-연결BS!D115 -> 0

Sheet 공시PL
D2: 과목 | E2: 2026 | F2: 2026 | G2: 2025 | H2: 2025 | K2: 과 목 | L2: 2026
E3: 3개월 | F3: 누적 | G3: 3개월 | H3: 누적 | L3: 3개월 | M3: 누적
D4: 매출액 | E4: =F4-M4 -> 4518456853 | F4: =연결PL!D2 -> 8812244469 | G4: 4268206262 | H4: 9441165967 | K4: 매출액 | M4: 4293787616
D5: 매출원가 | E5: =F5-M5 -> 1797042032 | F5: =연결PL!D7 -> 3634217621 | G5: 1458903526 | H5: 3581100990 | K5: 매출원가 | M5: 1837175589
D6: 매출총이익 | E6: =E4-E5 -> 2721414821 | F6: =F4-F5 -> 5178026848 | G6: 2809302736 | H6: 5860064977 | K6: 매출총이익 | M6: 2456612027
D7: 판매비와관리비 | E7: =F7-M7 -> 3157559749 | F7: =연결PL!D35 -> 5969068326 | G7: 2405235596 | H7: 4763859751 | K7: 판매비와관리비 | M7: 2811508577
D8: 영업이익(손실) | E8: =E6-E7 -> -436144928 | F8: =F6-F7 -> -791041478 | G8: 404067140 | H8: 1096205226 | K8: 영업이익(손실) | M8: -354896550
D9: 기타수익 | E9: =F9-M9 -> 2107337429 | F9: =연결PL!D69 -> 2109602184 | G9: 1934393 | H9: 8256143 | K9: 기타수익 | M9: 2264755
D10: 기타비용 | E10: =F10-M10 -> 9222257 | F10: =연결PL!D77 -> 9488772 | G10: 6528994 | H10: 7087062 | K10: 기타비용 | M10: 266515
D11: 금융수익 | E11: =F11-M11 -> 70594021 | F11: =연결PL!D85 -> 169546726 | G11: 7723398 | H11: 48738081 | K11: 금융수익 | M11: 98952705
D12: 금융비용 | E12: =F12-M12 -> 214204709 | F12: =연결PL!D90 -> 273243495 | G12: 112078187 | H12: 145282026 | K12: 금융비용 | M12: 59038786
D13: 지분법손익 | E13: =F13-M13 -> -1282816342 | F13: =연결PL!D96 -> -2067945777 | G13: 0 | H13: 0 | K13: 지분법손익 | M13: -785129435
D14: 법인세비용차감전순이익(손실) | E14: =E8+E9-E10+E11-E12+E13 -> 235543214 | F14: =F8+F9-F10+F11-F12+F13 -> -862570612 | G14: 295117750 | H14: 1000830362 | K14: 법인세비용차감전순이익(손실) | M14: -1098113826
D15: 법인세비용 | E15: =F15-M15 -> -3009004 | F15: =연결PL!D100 -> 4983889 | G15: -3233729 | H15: 4894989 | K15: 법인세비용 | M15: 7992893
D16: 분기순이익(손실) | E16: =E14-E15 -> 238552218 | F16: =F14-F15 -> -867554501 | G16: 298351479 | H16: 995935373 | K16: 반기순이익(손실) | M16: -1106106719
D17: 지배기업의 소유주 귀속 분기순이익 | E17: =E16 -> 238552218 | F17: =F16 -> -867554501 | G17: 298351479 | H17: 995935373 | K17: 지배기업의 소유주 귀속 반기순이익 | M17: -1106106719
D18: 비지배지분 귀속 분기순이익 | E18: 0 | F18: 0 | G18: 0 | H18: 0 | K18: 비지배지분 귀속 반기순이익 | M18: 0
D19: 기타포괄손익 | E19: =E20+E22 -> 3267871 | F19: =F20+F22 -> 11298394 | G19: -17734655 | H19: -26600734 | K19: 기타포괄손익 | M19: 8030523
D20: 당기손익으로 재분류되지 않는 항목 | E20: =E21 -> 0 | F20: =F21 -> 0 | G20: 0 | H20: 0 | K20: 당기손익으로 재분류되지 않는 항목 | M20: 0
D21: 순확정급여부채의 재측정요소 | E21: =F21-M21 -> 0 | F21: =연결PL!D106 -> 0 | G21: 0 | H21: 0 | K21: 순확정급여부채의 재측정요소 | M21: 0
D22: 후속적으로당기손익으로 재분류되는항목 | E22: =E23 -> 3267871 | F22: =F23 -> 11298394 | G22: -17734655 | H22: -26600734 | K22: 후속적으로당기손익으로 재분류되는항목 | M22: 8030523
D23: 해외사업장환산외화차이 | E23: =F23-M23 -> 3267871 | F23: =연결PL!D108 -> 11298394 | G23: -17734655 | H23: -26600734 | K23: 해외사업장환산외화차이 | M23: 8030523
D24: 총포괄손익 | E24: =E16+E19 -> 241820089 | F24: =F16+F19 -> -856256107 | G24: 280616824 | H24: 969334639 | K24: 총포괄손익 | M24: -1098076196
D25: 지배기업의 소유주 귀속 총포괄손익 | E25: =E24 -> 241820089 | F25: =F24 -> -856256107 | G25: 280616824 | H25: 969334639 | K25: 지배기업의 소유주 귀속 총포괄손익 | M25: -1098076196
D26: 비지배지분 귀속 총포괄손익 | E26: 0 | F26: 0 | G26: 0 | H26: 0 | K26: 비지배지분 귀속 총포괄손익 | M26: 0
D27: 주당이익(손실) | K27: 주당이익(손실)
D28: 기본주당이익(손실) | E28: ='31'!C12 -> 21 | F28: ='31'!D12 -> -76 | G28: 47 | H28: 159 | K28: 기본주당이익(손실) | M28: -97
D29: 희석주당손익(손실) | E29: ='31'!C46 -> 21 | F29: ='31'!D46 -> -76 | G29: 47 | H29: 157 | K29: 희석주당손익(손실) | M29: -97
F30: =F24=연결PL!D109 -> TRUE

Sheet 공시PL_IFRS18
B1: 연결 손익계산서 (IFRS 18 기준)
B2: ※ [연결PL_IFRS18] 시트 연동 (범주 재분류는 해당 시트 매핑표에서 변경). 3개월 기간 컬럼은 1분기 계정별 자료가 없어 제외하고 누적 기준으로만 표시했습니다.
B4: 과 목 | C4: 주석 | D4: =연결PL!D1 -> 46203 | E4: =연결PL!E1 -> 45838
B5: Ⅰ. 영업 범주
B6: 매출액 | D6: ='연결PL_IFRS18'!D6 -> 8812244469 | E6: ='연결PL_IFRS18'!E6 -> 9441165967
B7: 매출원가 | D7: ='연결PL_IFRS18'!D7 -> 3634217621 | E7: ='연결PL_IFRS18'!E7 -> 3581100990
B8: 매출총이익 | D8: ='연결PL_IFRS18'!D8 -> 5178026848 | E8: ='연결PL_IFRS18'!E8 -> 5860064977
B9: 판매비와관리비 | D9: ='연결PL_IFRS18'!D9 -> 5969068326 | E9: ='연결PL_IFRS18'!E9 -> 4763859751
B10: 기타영업수익 | D10: ='연결PL_IFRS18'!D10 -> 189101679 | E10: ='연결PL_IFRS18'!E10 -> 28740950
B11: 기타영업비용 | D11: ='연결PL_IFRS18'!D11 -> 183777316 | E11: ='연결PL_IFRS18'!E11 -> 106582748
B12: 영업이익(손실) | D12: ='연결PL_IFRS18'!D12 -> -785717115 | E12: ='연결PL_IFRS18'!E12 -> 1018363428
B13: Ⅱ. 투자 범주
B14: 투자수익 | D14: ='연결PL_IFRS18'!D15 -> 2090047231 | E14: ='연결PL_IFRS18'!E15 -> 28253274
B15: 투자비용 | D15: ='연결PL_IFRS18'!D16 -> 2067945777 | E15: ='연결PL_IFRS18'!E16 -> 0
B16: 투자손익 | D16: ='연결PL_IFRS18'!D17 -> 22101454 | E16: ='연결PL_IFRS18'!E17 -> 28253274
B17: 재무 및 법인세 전 손익 | D17: ='연결PL_IFRS18'!D18 -> -763615661 | E17: ='연결PL_IFRS18'!E18 -> 1046616702
B18: Ⅲ. 재무 범주
B19: 재무수익 | D19: ='연결PL_IFRS18'!D21 -> 0 | E19: ='연결PL_IFRS18'!E21 -> 0
B20: 재무비용 | D20: ='연결PL_IFRS18'!D22 -> 98954951 | E20: ='연결PL_IFRS18'!E22 -> 45786340
B21: 재무손익 | D21: ='연결PL_IFRS18'!D23 -> -98954951 | E21: ='연결PL_IFRS18'!E23 -> -45786340
B22: 법인세비용차감전순이익(손실) | D22: ='연결PL_IFRS18'!D25 -> -862570612 | E22: ='연결PL_IFRS18'!E25 -> 1000830362
B23: 법인세비용 | D23: ='연결PL_IFRS18'!D26 -> 4983889 | E23: ='연결PL_IFRS18'!E26 -> 4894989
B24: 당기순이익(손실) | D24: ='연결PL_IFRS18'!D27 -> -867554501 | E24: ='연결PL_IFRS18'!E27 -> 995935373
B25: 1.지배기업소유주지분 | D25: =D24-D26 -> -867554501 | E25: =E24-E26 -> 995935373
B26: 2.비지배지분 | D26: =연결PL!D103 -> 0 | E26: =연결PL!E103 -> 0
B27: 기타포괄손익 | D27: ='연결PL_IFRS18'!D30 -> 11298394 | E27: ='연결PL_IFRS18'!E30 -> -26600734
B28: 당기손익으로 재분류되지 않는 항목 | D28: ='연결PL_IFRS18'!D28 -> 0 | E28: ='연결PL_IFRS18'!E28 -> 0
B29: 후속적으로 당기손익으로 재분류되는 항목 | D29: ='연결PL_IFRS18'!D29 -> 11298394 | E29: ='연결PL_IFRS18'!E29 -> -26600734
B30: 총포괄손익 | D30: =D24+D27 -> -856256107 | E30: =E24+E27 -> 969334639
B31: 1.지배기업소유주지분 | D31: =D30-D32 -> -856256107 | E31: =E30-E32 -> 969334639
B32: 2.비지배지분 | D32: =연결PL!D111 -> 0 | E32: =연결PL!E111 -> 0
B33: 주당이익
B34: 기본주당이익(손실) | D34: =연결PL!D113 -> -76 | E34: =연결PL!E113 -> 159
B35: 희석주당손익(손실) | D35: =연결PL!D114 -> -76 | E35: =연결PL!E114 -> 157
B37: [검증] 기존 손익계산서 대비 (0이어야 함)
B38: 당기순이익 - [연결PL] | D38: =D24-연결PL!D101 -> 0 | E38: =E24-연결PL!E101 -> 0
B39: 총포괄손익 - [연결PL] | D39: =D30-연결PL!D109 -> 0 | E39: =E30-연결PL!E109 -> 0
B40: 당기순이익 - [공시PL] | D40: =D24-공시PL!F16 -> 0
B41: 종합 검증 | D41: =IF(SUMPRODUCT(ABS(D38:E40))=0,"OK","확인필요") -> OK

Sheet 연결BS
B1: 계정과목 | C1: 주석 | D1: =A0!E7 -> 46203 | E1: 46022
B2: 자산
B3: 유동자산 | D3: =D4+D6+D7+D14+D25+D34+D31 -> 19569724244 | E3: 26088866610
B4: 현금및현금성자산 | D4: =D5 -> 11853592219 | E4: 19371699448
B5: 현금및현금성자산 | D5: =SUMIF(BS!$Y:$Y,연결BS!B5,BS!$X:$X) -> 11853592219 | E5: 19371699448
B6: 단기금융상품 | D6: =SUMIF(BS!$Y:$Y,연결BS!B6,BS!$X:$X) -> 1000000000 | E6: 0
B7: 매출채권및기타채권 | D7: =SUM(D8:D13) -> 1542306044 | E7: 1742211093
B8: 매출채권 | D8: =SUMIF(BS!$Y:$Y,연결BS!B8,BS!$X:$X) -> 1093289891 | E8: 1667334063
B9: 매출채권대손충당금 | D9: =SUMIF(BS!$Y:$Y,연결BS!B9,BS!$X:$X) -> -79701518 | E9: -163007230
B10: 미수수익 | D10: =SUMIF(BS!$Y:$Y,연결BS!B10,BS!$X:$X) -> 8344109 | E10: 0
B11: 미수수익대손충당금 | D11: =SUMIF(BS!$Y:$Y,연결BS!B11,BS!$X:$X) -> 0 | E11: 0
B12: 미수금 | D12: =SUMIF(BS!$Y:$Y,연결BS!B12,BS!$X:$X) -> 544512562 | E12: 265023260
B13: 미수금대손충당금 | D13: =SUMIF(BS!$Y:$Y,연결BS!B13,BS!$X:$X) -> -24139000 | E13: -27139000
B14: 재고자산 | D14: =SUM(D15:D24) -> 2306724877 | E14: 2120729597
B15: 상품 | D15: =SUMIF(BS!$Y:$Y,연결BS!B15,BS!$X:$X) -> 113083377 | E15: 111295016
B16: 상품평가충당금 | D16: =SUMIF(BS!$Y:$Y,연결BS!B16,BS!$X:$X) -> 0 | E16: -14089
B17: 제품 | D17: =SUMIF(BS!$Y:$Y,연결BS!B17,BS!$X:$X) -> 2573602294 | E17: 2367206763
B18: 제품평가충당금 | D18: =SUMIF(BS!$Y:$Y,연결BS!B18,BS!$X:$X) -> -827921741 | E18: -725171962
B19: 원재료 | D19: =SUMIF(BS!$Y:$Y,연결BS!B19,BS!$X:$X) -> 487254381 | E19: 354984836
B20: 원재료평가충당금 | D20: =SUMIF(BS!$Y:$Y,연결BS!B20,BS!$X:$X) -> -67100184 | E20: -34479470
B21: 부재료 | D21: =SUMIF(BS!$Y:$Y,연결BS!B21,BS!$X:$X) -> 48405072 | E21: 49267189
B22: 부재료평가충당금 | D22: =SUMIF(BS!$Y:$Y,연결BS!B22,BS!$X:$X) -> -20598322 | E22: -2358686
B23: 재공품 | D23: =SUMIF(BS!$Y:$Y,연결BS!B23,BS!$X:$X) -> 1451631047 | E23: 0
B24: 재공품평가충당금 | D24: =SUMIF(BS!$Y:$Y,연결BS!B24,BS!$X:$X) -> -1451631047 | E24: 0
B25: 기타유동자산 | D25: =SUM(D26:D30) -> 2793009371 | E25: 2780553225
B26: 선급금 | D26: =SUMIF(BS!$Y:$Y,연결BS!B26,BS!$X:$X) -> 1238992451 | E26: 2298824241
B27: 선급금대손충당금 | D27: =SUMIF(BS!$Y:$Y,연결BS!B27,BS!$X:$X) -> -564300000 | E27: 0
B28: 선급비용 | D28: =SUMIF(BS!$Y:$Y,연결BS!B28,BS!$X:$X) -> 1698698289 | E28: 474036344
B29: 환불자산 | D29: =SUMIF(BS!$Y:$Y,연결BS!B29,BS!$X:$X) -> 4272227 | E29: 7692640
B30: 부가세대급금 | D30: =SUMIF(BS!$Y:$Y,연결BS!B30,BS!$X:$X) -> 415346404 | E30: 0
B31: 기타유동금융자산 | D31: =SUM(D32:D33) -> 58432567 | E31: 56059511
B32: 임차보증금(유동) | D32: =SUMIF(BS!$Y:$Y,연결BS!B32,BS!$X:$X) -> 58432567 | E32: 54809510
B33: 주 . 임.종단기채권 | D33: =SUMIF(BS!$Y:$Y,연결BS!B33,BS!$X:$X) -> 0 | E33: 1250001
B34: 당기법인세자산 | D34: =SUMIF(BS!$Y:$Y,연결BS!B34,BS!$X:$X) -> 15659166 | E34: 17613736
B35: 비유동자산 | D35: =D36+D40+D43+D62+D73+D39+D71 -> 47987765603 | E35: 29206530706
B36: 기타비유동금융자산 | D36: =SUM(D37:D38) -> 715041595 | E36: 388220275
B37: 임차보증금 | D37: =SUMIF(BS!$Y:$Y,연결BS!B37,BS!$X:$X) -> 696916809 | E37: 378196105
B38: 기타보증금 | D38: =SUMIF(BS!$Y:$Y,연결BS!B38,BS!$X:$X) -> 18124786 | E38: 10024170
B39: 당기손익-공정가치금융자산 | D39: =SUMIF(BS!$Y:$Y,연결BS!B39,BS!$X:$X) -> 172664940 | E39: 172664940
B40: 종속기업및관계기업투자 | D40: =SUM(D41:D42) -> 0 | E40: 16999999500
...

Sheet CF정산표
B1: =+A0!E5 -> 주식회사 울트라브이와 그 종속기업 | F1: <주석 시트 수식 연동
B2: 현 금 흐 름 정 산 표 | AB2: =CF정산표!AC11+CF정산표!H11-CF정산표!K11 -> -13318794
B3: =+A0!E7 -> 46203
B4: 과 목 | G4: 영 업 활 동 으 로 인 한 현 금 흐 름 | P4: 투 자 활 동 으 로 인 한 현 금 흐 름 | V4: 재 무 활 동 으 로 인 한 현 금 흐 름 | AB4: 대 체 거 래
D5: 전 기 말 | E5: 당 기 말 | F5: 증감액 | G5: 현금의 유입이 없는 수익등 | J5: 현금의 유출이 없는 비용등 | M5: 영업활동으로인한 자산·부채의 변동 | P5: 차 변 (현 금 의 유 출) | S5: 대 변 (현 금 의 유 입) | V5: 차 변 (현 금 의 유 출) | Y5: 대 변 (현 금 의 유 입) | AB5: 차 변 | AE5: 대 변 | AH5: 차 이
D6: 금 액 | E6: 금 액 | G6: 내 역 | H6: 금 액 | J6: 내 역 | K6: 금 액 | M6: 내 역 | N6: 금 액 | P6: 내 역 | Q6: 금 액 | S6: 내 역 | T6: 금 액 | V6: 내 역 | W6: 금 액 | Y6: 내 역 | Z6: 금 액 | AB6: 내 역 | AC6: 금 액 | AE6: 내 역 | AF6: 금 액
D7: =연결BS!E3-D8 -> 0 | E7: =E8-연결BS!D3 -> 0
B8: Ⅰ. | C8: 유동자산 | D8: =+D10+D13+D18+D37+D52+D30 -> 26088866610 | E8: =+E10+E13+E18+E37+E52+E30 -> 19569724244
C10: =연결BS!B5 -> 현금및현금성자산 | D10: =SUM(D11) -> 19371699448 | E10: =SUM(E11) -> 11853592219
A11: =AH11 -> 0 | C11: =연결BS!B5 -> 현금및현금성자산 | D11: =연결BS!E5 -> 19371699448 | E11: =연결BS!D5 -> 11853592219 | F11: =E11-D11 -> -7518107229 | G11: 외화환산이익 | H11: 5 | J11: 외화환산손실 | K11: 0 | M11: =C11&"의 증가(감소)" -> 현금및현금성자산의 증가(감소) | N11: =D11-E11+H11-K11+Q11-T11+W11-Z11+SUM(AC11:AC12)-AF11 -> 7504788435 | P11: 연결범위변동 | Q11: =-AC12 -> -677182600 | AB11: 해외사업장환산차대 | AC11: =환율변동효과!D16+환율변동효과!D17+환율변동효과!D18 -> -13318799 | AH11: =D11-E11+H11-K11-N11+Q11-T11+W11-Z11+SUM(AC11:AC12)-AF11 -> 0
A12: =AH12 -> 0 | AB12: 연결범위변동(에이티지씨) | AC12: =BS!N8 -> 677182600
A13: =AH13 -> 0 | C13: 단기금융상품 | D13: =SUM(D14) -> 0 | E13: =SUM(E14:E14) -> 1000000000
A14: =AH14 -> 0 | C14: =연결BS!B6 -> 단기금융상품 | D14: =연결BS!E6 -> 0 | E14: =연결BS!D6 -> 1000000000 | F14: =E14-D14 -> 1000000000 | G14: 단기금융상품평가이익 | H14: 0 | J14: 단기금융상품평가손실 | P14: 단기금융상품의 취득 | Q14: 0 | S14: 단기금융상품 처분 | AB14: 연결범위변동(에이티지씨) | AC14: 1000000000 | AH14: =D14-E14+SUM(H14:I17)-SUM(K14:K17)-N14+Q14-T14+W14-Z14+AC14-AF14 -> 0
A15: =AH15 -> 0 | G15: 단기금융상품처분이익 | H15: 0 | J15: 단기금융상품처분손실 | K15: 0
G16: 이자수익 | H16: 0 | J16: 외화환산손실 | K16: 0
A18: =AH18 -> 0 | C18: =연결BS!B7 -> 매출채권및기타채권 | D18: =SUM(D19:D29) -> 1742211093 | E18: =SUM(E19:E29) -> 1542306044
A19: =AH19 -> 0 | C19: =연결BS!B8 -> 매출채권 | D19: =연결BS!E8 -> 1667334063 | E19: =연결BS!D8 -> 1093289891 | F19: =E19-D19 -> -574044172 | G19: 외화환산이익 | H19: 37603834 | J19: 외화환산손실 | K19: 0 | M19: =C19&"의 감소(증가)" -> 매출채권의 감소(증가) | N19: =SUM(D19:D20)-SUM(E19:E20)+SUM(H19:H20)-SUM(K19:K20)+Q19-T19+W19-Z19+SUM(AC19:AC20)-SUM(AF19:AF20) -> 502587042 | AB19: 해외사업장환산차대 | AC19: =환율변동효과!D20+환율변동효과!D21 -> -109060964 | AE19: 매출채권 제각 | AF19: =AC20 -> 0 | AH19: =SUM(D19:D20)-SUM(E19:E20)+SUM(H19:H20)-SUM(K19:K20)-N19+Q19-T19+W19-Z19+SUM(AC19:AC20)-SUM(AF19:AF20) -> 0
A20: =AH20 -> 0 | C20: =연결BS!B9 -> 매출채권대손충당금 | D20: =연결BS!E9 -> -163007230 | E20: =연결BS!D9 -> -79701518 | F20: =E20-D20 -> 83305712 | J20: 대손상각비 | K20: ='8'!D76 -> -83305712 | AB20: 매출채권 제각 | AC20: =-'8'!E76 -> 0
A21: =AH21 -> 0 | C21: =연결BS!B10 -> 미수수익 | D21: =연결BS!E10 -> 0 | E21: =연결BS!D10 -> 8344109 | F21: =E21-D21 -> 8344109 | G21: 이자수익 | H21: =PL!Y97-H83 -> 14072249 | M21: 미수수익의 감소(증가) | N21: 14072249 | AB21: 해외사업장환산차대 | AC21: =환율변동효과!D22 -> 0 | AH21: =SUM(D21:D21)-SUM(E21:E21)+SUM(H21:H21)-SUM(K21:K21)-N21+Q21-T21+W21-Z21+SUM(AC21:AC22)-SUM(AF21:AF21) -> 0
AB22: 연결범위변동(에이티지씨) | AC22: 8344109
A23: =AH23 -> 0 | C23: =연결BS!B11 -> 미수수익대손충당금 | D23: =연결BS!E11 -> 0 | E23: =연결BS!D11 -> 0 | F23: =E23-D23 -> 0 | AB23: 해외사업장환산차대 | AC23: =환율변동효과!D23 -> 0 | AH23: =SUM(D23:D23)-SUM(E23:E23)+SUM(H23:H23)-SUM(K23:K23)-N23+Q23-T23+W23-Z23+SUM(AC23:AC23)-SUM(AF23:AF23) -> 0
A24: =AH24 -> 0 | C24: =연결BS!B12 -> 미수금 | D24: =연결BS!E12 -> 265023260 | E24: =연결BS!D12 -> 544512562 | F24: =E24-D24 -> 279489302 | G24: 외화환산이익 | J24: 외화환산손실 | M24: =C24&"의 감소(증가)" -> 미수금의 감소(증가) | N24: 4005688 | AB24: 연결범위변동(에이티지씨) | AC24: 283494990 | AE24: 팜합병 | AF24: 0 | AH24: =SUM(D24:D25)-SUM(E24:E25)+SUM(H24:H25)-SUM(K24:K25)-N24+Q24-T24+W24-Z24+SUM(AC24:AC25)-SUM(AF24:AF25) -> 0
A25: =AH25 -> 0 | C25: =연결BS!B13 -> 미수금대손충당금 | D25: =연결BS!E13 -> -27139000 | E25: =연결BS!D13 -> -24139000 | F25: =E25-D25 -> 3000000 | G25: 이자수익 | J25: 기타의 대손상각비(환입) | K25: ='8'!D77 -> -3000000 | AB25: 리스 미수금 | AC25: =환율변동효과!D25 -> 0
G26: 외화환산이익
A30: =AH30 -> 0 | C30: =연결BS!B14 -> 재고자산 | D30: =연결BS!E14 -> 2120729597 | E30: =연결BS!D14 -> 2306724877 | M30: 재고자산의 감소(증가) | N30: =SUM(D30:D34)-SUM(E30:E34)+SUM(H30:H34)-SUM(K30:K34)+Q30-T30+W30-Z30+AC30-SUM(AF30:AF33) -> -326232101 | AB30: 해외사업장환산차대 | AC30: =SUM(환율변동효과!D33:D41) -> -9043647 | AH30: =D30-E30+SUM(H30:H34)-SUM(K30:K34)-SUM(N30:N34)+SUM(Q30:Q34)-SUM(T30:T34)+SUM(W30:W34)-SUM(Z30:Z34)+SUM(AC30:AC35)-SUM(AF30:AF35) -> 0
A31: =AH31 -> 0 | G31: 상품평가손실환입 | H31: 14089 | J31: 상품평가손실 | K31: 0 | AB31: 연결범위변동(에이티지씨) | AC31: 0
G32: 제품평가손실환입 | H32: 0 | J32: 제품평가손실 | K32: 102749779
G33: 원재료평가손실환입 | H33: 0 | J33: 원재료평가손실 | K33: 10217848
G34: 부재료평가손실환입 | H34: 0 | J34: 부재료평가손실 | K34: 18239636
A35: =AH35 -> 0
A37: =AH37 -> 0 | C37: =연결BS!B25 -> 기타유동자산 | D37: =SUM(D38:D51) -> 2836612736 | E37: =SUM(E38:E51) -> 2851441938
A38: =AH38 -> 0 | C38: =연결BS!B26 -> 선급금 | D38: =연결BS!E26 -> 2298824241 | E38: =연결BS!D26 -> 1238992451 | F38: =E38-D38 -> -1059831790 | M38: =C38&"의 감소(증가)" -> 선급금의 감소(증가) | N38: =D38-E38+H38-K38+Q38-T38+W38-Z38+SUM(AC38:AC40)-SUM(AF38:AF39) -> 1650893458 | AB38: 해외사업장환산차대 | AC38: =ROUND(환율변동효과!D26,)+3.72529029846191E-09 -> -238332 | AH38: =D38-E38+SUM(H38:I39)-SUM(K38:K39)-SUM(N38:O39)+SUM(Q38:Q39)-SUM(T38:T39)+SUM(W38:W39)-SUM(Z38:Z39)+SUM(AC38:AC40)-SUM(AF38:AF39) -> 0
AB39: 기계장치 반품 | AC39: 27000000
AB40: 연결범위변동(에이티지씨) | AC40: 564300000
C41: =연결BS!B27 -> 선급금대손충당금 | D41: =연결BS!E27 -> 0 | E41: =연결BS!D27 -> -564300000 | F41: =E41-D41 -> -564300000 | J41: 기타의 대손상각비(환입) | K41: 0 | AB41: 해외사업장환산차대 | AC41: =환율변동효과!D27 -> 0 | AH41: =D41-E41+H41-K41-N41+Q41-T41+W41-Z41+SUM(AC41:AC42)-SUM(AF41) -> 0
AB42: 연결범위변동(에이티지씨) | AC42: -564300000
A43: =AH43 -> 0 | C43: =연결BS!B33 -> 주 . 임.종단기채권 | D43: =연결BS!E33 -> 1250001 | E43: =연결BS!D33 -> 0 | F43: =E43-D43 -> -1250001 | P43: 주 . 임.종단기채권의 증가 | Q43: 0 | S43: 주 . 임.종단기채권의 감소 | T43: 1250001 | AB43: 해외사업장환산차대 | AC43: 0 | AH43: =D43-E43+H43-K43-N43+Q43-T43+W43-Z43+SUM(AC43:AC44)-AF43 -> 0
AB44: 연결범위변동(에이티지씨) | AC44: 0
A45: =AH45 -> 0 | C45: =연결BS!B28 -> 선급비용 | D45: =연결BS!E28 -> 474036344 | E45: =연결BS!D28 -> 1698698289 | F45: =E45-D45 -> 1224661945 | M45: =C45&"의 감소(증가)" -> 선급비용의 감소(증가) | N45: =D45-E45+H45-K45+Q45-T45+W45-Z45+AC45-SUM(AF45:AF46) -> -1224661945 | AB45: 해외사업장환산차대 | AC45: 0 | AH45: =D45-E45+H45-K45-N45+Q45-T45+W45-Z45+AC45-AF45 -> 0
A46: =AH46 -> 0 | C46: =연결BS!B29 -> 환불자산 | D46: =연결BS!E29 -> 7692640 | E46: =연결BS!D29 -> 4272227 | F46: =E46-D46 -> -3420413 | M46: =C46&"의 감소(증가)" -> 환불자산의 감소(증가) | N46: =SUM(D46:D47)-SUM(E46:E47)+SUM(H46:H47)-SUM(K46:K47)+Q46-T46+W46-Z46+SUM(AC46:AC47)-SUM(AF46:AF47) -> 3420413 | AB46: 현할차설정 | AH46: =SUM(D46:D47)-SUM(E46:E47)+SUM(H46:H47)-SUM(K46:K47)-N46+Q46-T46+W46-Z46+SUM(AC46:AC47)-SUM(AF46:AF47) -> 0
...

Sheet BS
A1: Level | B1: 계정과목명(Account) | G1: Code | H1: 울트라브이 | I1: 울트라브이팜 | J1: ULTRA V HONG KONG LIMITED | K1: DERMASTER HONG KONG LIMITED | L1: ULTRA V SHANGHAI LIMITED | M1: ULTRA V (SG) PTE.LTD (24년 설립) | N1: ATGC | O1: 단순합산 | P1: 투자자본상계 | R1: IFRS(투자자본상계) | S1: 내부거래상계 | U1: IFRS(내부거래상계) | V1: 연결조정 | X1: 연결IFRS | Y1: 공시용mapping
P2: 차변 | Q2: 대변 | S2: 차변 | T2: 대변 | V2: 차변 | W2: 대변
A4: 1 | B4: 자산 | H4: =H5+H39 -> 54543045905 | I4: =I5+I39 -> 0 | J4: =J5+J39 -> 2268065089 | K4: =K5+K39 -> 358233996 | L4: =L5+L39 -> 2287111 | M4: =M5+M39 -> 22492142 | N4: =N5+N39 -> 10738913487 | O4: =O5+O39 -> 67933037730 | R4: =R5+R39 -> 71425319191 | U4: =U5+U39 -> 69331585038 | X4: =X5+X39 -> 67557489847
A5: 2 | C5: 유동자산 | H5: =H6+H24+H36 -> 16937363250 | I5: =I6+I24+I36 -> 0 | J5: =J6+J24+J36 -> 2042118015 | K5: =K6+K24+K36 -> 66475063 | L5: =L6+L24+L36 -> 2287111 | M5: =M6+M24+M36 -> 22492142 | N5: =N6+N24+N36 -> 2658778533 | O5: =O6+O24+O36 -> 21729514114 | R5: =R6+R24+R36 -> 21729514114 | U5: =U6+U24+U36 -> 19637356152 | X5: =X6+X24+X36 -> 19569724244
A6: 3 | D6: 당좌자산 | H6: =SUM(H7:H23) -> 14734753629 | I6: =SUM(I7:I23) -> 0 | J6: =SUM(J7:J23) -> 1882310421 | K6: =SUM(K7:K23) -> 26031396 | L6: =SUM(L7:L23) -> 2287111 | M6: =SUM(M7:M23) -> 22492142 | N6: =SUM(N7:N23) -> 2658778533 | O6: =SUM(O7:O23) -> 19326653232 | R6: =SUM(R7:R23) -> 19326653232 | U6: =SUM(U7:U23) -> 17315340360 | X6: =SUM(X7:X23) -> 17204566800
A7: 4 | E7: 현금 | G7: 10100 | H7: =SUMIF(별도정산표!$G:$G,BS!G7,별도정산표!$E:$E) -> 0 | I7: =SUMIF(울트라팜_FS!$A:$A,BS!G7,울트라팜_FS!$D:$D) -> 0 | J7: =SUMIF(HK_BS!$A:$A,BS!G7,HK_BS!$K:$K) -> 807554 | K7: =SUMIF(DHK_BS!$A:$A,BS!G7,DHK_BS!$K:$K) -> 0 | L7: =SUMIF(상해_BS!$A:$A,BS!G7,상해_BS!$K:$K) -> 0 | M7: =SUMIF(SG_BS!$A:$A,BS!G7,SG_BS!$K:$K) -> 0 | N7: =SUMIF(ATGC_BS!$H:$H,BS!G7,ATGC_BS!$I:$I) -> 0 | O7: =SUM(H7:N7) -> 807554 | P7: =SUMIF(RIC!D:D,BS!G7,RIC!F:F) -> 0 | Q7: =SUMIF(RIC!G:G,BS!G7,RIC!I:I) -> 0 | R7: =O7+P7-Q7 -> 807554 | S7: =SUMIF(RIT!H:H,BS!G7,RIT!J:J) -> 0 | T7: =SUMIF(RIT!K:K,BS!G7,RIT!M:M) -> 0 | U7: =R7+S7-T7 -> 807554 | V7: =SUMIF(지분법및기타!$D:$D,BS!G7,지분법및기타!$F:$F) -> 0 | W7: =SUMIF(지분법및기타!$G:$G,BS!G7,지분법및기타!$I:$I) -> 0 | X7: =U7+V7-W7 -> 807554 | Y7: 현금및현금성자산 | AA7: =X7-O7 -> 0
A8: 4 | E8: 보통예금 | G8: 10300 | H8: =SUMIF(별도정산표!$G:$G,BS!G8,별도정산표!$E:$E) -> 10968165061 | I8: =SUMIF(울트라팜_FS!$A:$A,BS!G8,울트라팜_FS!$D:$D) -> 0 | J8: =SUMIF(HK_BS!$A:$A,BS!G8,HK_BS!$K:$K) -> 160024453 | K8: =SUMIF(DHK_BS!$A:$A,BS!G8,DHK_BS!$K:$K) -> 24830657 | L8: =SUMIF(상해_BS!$A:$A,BS!G8,상해_BS!$K:$K) -> 0 | M8: =SUMIF(SG_BS!$A:$A,BS!G8,SG_BS!$K:$K) -> 14563594 | N8: =SUMIF(ATGC_BS!$H:$H,BS!G8,ATGC_BS!$I:$I) -> 677182600 | O8: =SUM(H8:N8) -> 11844766365 | P8: =SUMIF(RIC!D:D,BS!G8,RIC!F:F) -> 0 | Q8: =SUMIF(RIC!G:G,BS!G8,RIC!I:I) -> 0 | R8: =O8+P8-Q8 -> 11844766365 | S8: =SUMIF(RIT!H:H,BS!G8,RIT!J:J) -> 0 | T8: =SUMIF(RIT!K:K,BS!G8,RIT!M:M) -> 0 | U8: =R8+S8-T8 -> 11844766365 | V8: =SUMIF(지분법및기타!$D:$D,BS!G8,지분법및기타!$F:$F) -> 0 | W8: =SUMIF(지분법및기타!$G:$G,BS!G8,지분법및기타!$I:$I) -> 0 | X8: =U8+V8-W8 -> 11844766365 | Y8: 현금및현금성자산 | AA8: =X8-O8 -> 0
A9: 4 | E9: 외화보통예금 | G9: 10400 | H9: =SUMIF(별도정산표!$G:$G,BS!G9,별도정산표!$E:$E) -> 0 | I9: =SUMIF(울트라팜_FS!$A:$A,BS!G9,울트라팜_FS!$D:$D) -> 0 | J9: =SUMIF(HK_BS!$A:$A,BS!G9,HK_BS!$K:$K) -> 89752 | K9: =SUMIF(DHK_BS!$A:$A,BS!G9,DHK_BS!$K:$K) -> 0 | L9: =SUMIF(상해_BS!$A:$A,BS!G9,상해_BS!$K:$K) -> 0 | M9: =SUMIF(SG_BS!$A:$A,BS!G9,SG_BS!$K:$K) -> 7928548 | N9: =SUMIF(ATGC_BS!$H:$H,BS!G9,ATGC_BS!$I:$I) -> 0 | O9: =SUM(H9:N9) -> 8018300 | P9: =SUMIF(RIC!D:D,BS!G9,RIC!F:F) -> 0 | Q9: =SUMIF(RIC!G:G,BS!G9,RIC!I:I) -> 0 | R9: =O9+P9-Q9 -> 8018300 | S9: =SUMIF(RIT!H:H,BS!G9,RIT!J:J) -> 0 | T9: =SUMIF(RIT!K:K,BS!G9,RIT!M:M) -> 0 | U9: =R9+S9-T9 -> 8018300 | V9: =SUMIF(지분법및기타!$D:$D,BS!G9,지분법및기타!$F:$F) -> 0 | W9: =SUMIF(지분법및기타!$G:$G,BS!G9,지분법및기타!$I:$I) -> 0 | X9: =U9+V9-W9 -> 8018300 | Y9: 현금및현금성자산 | AA9: =X9-O9 -> 0
A10: 4 | E10: 기타단기금융상품 | G10: 10600 | H10: =SUMIF(별도정산표!$G:$G,BS!G10,별도정산표!$E:$E) -> 0 | I10: =SUMIF(울트라팜_FS!$A:$A,BS!G10,울트라팜_FS!$D:$D) -> 0 | J10: =SUMIF(HK_BS!$A:$A,BS!G10,HK_BS!$K:$K) -> 0 | K10: =SUMIF(DHK_BS!$A:$A,BS!G10,DHK_BS!$K:$K) -> 0 | L10: =SUMIF(상해_BS!$A:$A,BS!G10,상해_BS!$K:$K) -> 0 | M10: =SUMIF(SG_BS!$A:$A,BS!G10,SG_BS!$K:$K) -> 0 | N10: =SUMIF(ATGC_BS!$H:$H,BS!G10,ATGC_BS!$I:$I) -> 1000000000 | O10: =SUM(H10:N10) -> 1000000000 | P10: =SUMIF(RIC!D:D,BS!G10,RIC!F:F) -> 0 | Q10: =SUMIF(RIC!G:G,BS!G10,RIC!I:I) -> 0 | R10: =O10+P10-Q10 -> 1000000000 | S10: =SUMIF(RIT!H:H,BS!G10,RIT!J:J) -> 0 | T10: =SUMIF(RIT!K:K,BS!G10,RIT!M:M) -> 0 | U10: =R10+S10-T10 -> 1000000000 | V10: =SUMIF(지분법및기타!$D:$D,BS!G10,지분법및기타!$F:$F) -> 0 | W10: =SUMIF(지분법및기타!$G:$G,BS!G10,지분법및기타!$I:$I) -> 0 | X10: =U10+V10-W10 -> 1000000000 | Y10: 단기금융상품
A11: 4 | E11: 외상매출금 | G11: 10800 | H11: =SUMIF(별도정산표!$G:$G,BS!G11,별도정산표!$E:$E) -> 1535770100 | I11: =SUMIF(울트라팜_FS!$A:$A,BS!G11,울트라팜_FS!$D:$D) -> 0 | J11: =SUMIF(HK_BS!$A:$A,BS!G11,HK_BS!$K:$K) -> 1710243241 | K11: =SUMIF(DHK_BS!$A:$A,BS!G11,DHK_BS!$K:$K) -> 0 | L11: =SUMIF(상해_BS!$A:$A,BS!G11,상해_BS!$K:$K) -> 0 | M11: =SUMIF(SG_BS!$A:$A,BS!G11,SG_BS!$K:$K) -> 0 | N11: =SUMIF(ATGC_BS!$H:$H,BS!G11,ATGC_BS!$I:$I) -> 0 | O11: =SUM(H11:N11) -> 3246013341 | P11: =SUMIF(RIC!D:D,BS!G11,RIC!F:F) -> 0 | Q11: =SUMIF(RIC!G:G,BS!G11,RIC!I:I) -> 0 | R11: =O11+P11-Q11 -> 3246013341 | S11: =SUMIF(RIT!H:H,BS!G11,RIT!J:J) -> 0 | T11: =SUMIF(RIT!K:K,BS!G11,RIT!M:M) -> 2036954016 | U11: =R11+S11-T11 -> 1209059325 | V11: =SUMIF(지분법및기타!$D:$D,BS!G11,지분법및기타!$F:$F) -> 42605437 | W11: =SUMIF(지분법및기타!$G:$G,BS!G11,지분법및기타!$I:$I) -> 158374871 | X11: =U11+V11-W11 -> 1093289891 | Y11: 매출채권 | AA11: =X11-O11 -> -2152723450 | AB11: 전액 내부거래 차이
A12: 4 | E12: 외상매출금_대손충당금 | G12: 10900 | H12: =SUMIF(별도정산표!$G:$G,BS!G12,별도정산표!$E:$E) -> -105342662 | I12: =SUMIF(울트라팜_FS!$A:$A,BS!G12,울트라팜_FS!$D:$D) -> 0 | J12: =SUMIF(HK_BS!$A:$A,BS!G12,HK_BS!$K:$K) -> 0 | K12: =SUMIF(DHK_BS!$A:$A,BS!G12,DHK_BS!$K:$K) -> 0 | L12: =SUMIF(상해_BS!$A:$A,BS!G12,상해_BS!$K:$K) -> 0 | M12: =SUMIF(SG_BS!$A:$A,BS!G12,SG_BS!$K:$K) -> 0 | N12: =SUMIF(ATGC_BS!$H:$H,BS!G12,ATGC_BS!$I:$I) -> 0 | O12: =SUM(H12:N12) -> -105342662 | P12: =SUMIF(RIC!D:D,BS!G12,RIC!F:F) -> 0 | Q12: =SUMIF(RIC!G:G,BS!G12,RIC!I:I) -> 0 | R12: =O12+P12-Q12 -> -105342662 | S12: =SUMIF(RIT!H:H,BS!G12,RIT!J:J) -> 25641144 | T12: =SUMIF(RIT!K:K,BS!G12,RIT!M:M) -> 0 | U12: =R12+S12-T12 -> -79701518 | V12: =SUMIF(지분법및기타!$D:$D,BS!G12,지분법및기타!$F:$F) -> 0 | W12: =SUMIF(지분법및기타!$G:$G,BS!G12,지분법및기타!$I:$I) -> 0 | X12: =U12+V12-W12 -> -79701518 | Y12: 매출채권대손충당금 | AA12: =X12-O12 -> 25641144 | AB12: 전액 내부거래 차이
A13: 4 | E13: 미수수익 | G13: 11600 | H13: =SUMIF(별도정산표!$G:$G,BS!G13,별도정산표!$E:$E) -> 0 | I13: =SUMIF(울트라팜_FS!$A:$A,BS!G13,울트라팜_FS!$D:$D) -> 0 | J13: =SUMIF(HK_BS!$A:$A,BS!G13,HK_BS!$K:$K) -> 0 | K13: =SUMIF(DHK_BS!$A:$A,BS!G13,DHK_BS!$K:$K) -> 0 | L13: =SUMIF(상해_BS!$A:$A,BS!G13,상해_BS!$K:$K) -> 0 | M13: =SUMIF(SG_BS!$A:$A,BS!G13,SG_BS!$K:$K) -> 0 | N13: =SUMIF(ATGC_BS!$H:$H,BS!G13,ATGC_BS!$I:$I) -> 8344109 | O13: =SUM(H13:N13) -> 8344109 | P13: =SUMIF(RIC!D:D,BS!G13,RIC!F:F) -> 0 | Q13: =SUMIF(RIC!G:G,BS!G13,RIC!I:I) -> 0 | R13: =O13+P13-Q13 -> 8344109 | S13: =SUMIF(RIT!H:H,BS!G13,RIT!J:J) -> 0 | T13: =SUMIF(RIT!K:K,BS!G13,RIT!M:M) -> 0 | U13: =R13+S13-T13 -> 8344109 | V13: =SUMIF(지분법및기타!$D:$D,BS!G13,지분법및기타!$F:$F) -> 0 | W13: =SUMIF(지분법및기타!$G:$G,BS!G13,지분법및기타!$I:$I) -> 0 | X13: =U13+V13-W13 -> 8344109 | Y13: 미수수익
E14: 미수수익_대손충당금 | G14: 11700 | H14: =SUMIF(별도정산표!$G:$G,BS!G14,별도정산표!$E:$E) -> 0 | I14: =SUMIF(울트라팜_FS!$A:$A,BS!G14,울트라팜_FS!$D:$D) -> 0 | J14: =SUMIF(HK_BS!$A:$A,BS!G14,HK_BS!$K:$K) -> 0 | K14: =SUMIF(DHK_BS!$A:$A,BS!G14,DHK_BS!$K:$K) -> 0 | L14: =SUMIF(상해_BS!$A:$A,BS!G14,상해_BS!$K:$K) -> 0 | M14: =SUMIF(SG_BS!$A:$A,BS!G14,SG_BS!$K:$K) -> 0 | N14: =SUMIF(ATGC_BS!$H:$H,BS!G14,ATGC_BS!$I:$I) -> 0 | O14: =SUM(H14:N14) -> 0 | P14: =SUMIF(RIC!D:D,BS!G14,RIC!F:F) -> 0 | Q14: =SUMIF(RIC!G:G,BS!G14,RIC!I:I) -> 0 | R14: =O14+P14-Q14 -> 0 | S14: =SUMIF(RIT!H:H,BS!G14,RIT!J:J) -> 0 | T14: =SUMIF(RIT!K:K,BS!G14,RIT!M:M) -> 0 | U14: =R14+S14-T14 -> 0 | V14: =SUMIF(지분법및기타!$D:$D,BS!G14,지분법및기타!$F:$F) -> 0 | W14: =SUMIF(지분법및기타!$G:$G,BS!G14,지분법및기타!$I:$I) -> 0 | X14: =U14+V14-W14 -> 0 | Y14: 미수수익대손충당금
