Workbook
Name RF: #REF!
Name RF: #REF!
Name 기초가격: #REF!
Name 기초가격: #REF!
Name 만기: #REF!
Name 만기: #REF!
Name 주가상승계수: #REF!
Name 주가상승계수: #REF!
Name 주가하락계수: #REF!
Name 주가하락계수: #REF!
Name 행사가격: #REF!
Name 행사가격: #REF!
Name 행사시작일: #REF!
Name 행사시작일: #REF!
Name 행사종료일: #REF!
Name 행사종료일: #REF!
Name 헷지확률: #REF!
Name 헷지확률: #REF!

Sheet 계정코드
B2: 유동자산 | C2: 10300 | D2: 현금
C3: 10300 | D3: 보통예금
C4: 10300 | D4: 외화보통예금
C5: 10600 | D5: 기타단기금융상품
C6: 10800 | D6: 외상매출금
C7: 10900 | D7: 외상매출금_대손충당금
C8: 11600 | D8: 미수수익
C9: 11700 | D9: 미수수익_대손충당금
C10: 12000 | D10: 미수금
C11: 12100 | D11: 미수금_대손충당금
C12: 12400 | D12: 유동성임차보증금
C13: 13100 | D13: 선급금
C14: 13200 | D14: 선급금_대손충당금
C15: 13300 | D15: 선급비용
C16: 13400 | D16: 주임종단기채권
C17: 13500 | D17: 부가세대급금
C18: 13600 | D18: 선납법인세
C19: 16000 | D19: 상품재고자산평가충당금
C20: 14600 | D20: 상품
C21: 14700 | D21: 제품
C22: 16100 | D22: 제품재고자산평가충당금
C23: 14900 | D23: 원재료
C24: 16200 | D24: 원재료재고자산평가충당금
... C27: 15700 | D27: 재공품
B28: 비유동자산 | C28: 17600 | D28: 종속기업투자주식
C29: 17700 | D29: 관계기업투자주식
C30: 17800 | D30: 투자유가증권
C31: 20600 | D31: 기계장치
C32: 20700 | D32: 감가상각누계액기계장치
C33: 20800 | D33: 차량운반구
C34: 20900 | D34: 감가상각누계액차량운반구
C35: 21000 | D35: 공구와기구
C36: 21100 | D36: 감가상각누계액공구와기구
C37: 21200 | D37: 비품
C38: 21300 | D38: 감가상각누계액비품
C39: 21400 | D39: 건설중인자산
C40: 21900 | D40: 인테리어
C41: 22000 | D41: 감가상각누계액인테리어
C42: 22100 | D42: 시설장치
C43: 22200 | D43: 감가상각누계액시설장치
...

Sheet Dart_BS
B3: 과목 | C3: 2026. 06 | D3: 2025. 12 | I3: 과 목 | J3: 주석 | K3: 제 14(당) 기 | L3: 제 13(전) 기
B4: 자산 | I4: 자산
B5: 유동자산 | C5: =SUM(C6:C12) -> 16937363250 | D5: =SUM(D6:D12) -> 25996495943 | G5: =K5=D5 -> TRUE | I5: 유동자산 | K5: 25996495943 | L5: 7305989405
B6: 현금및현금성자산 | C6: =정산표!H7 -> 10968165061 | D6: =정산표!M7 -> 19169211185 | G6: =K6=D6 -> TRUE | I6: 현금및현금성자산 | J6: 4,5,6,7 | K6: 19169211185 | L6: 1957354410
B7: 단기금융상품 | C7: =정산표!H9 -> 0 | D7: =정산표!M9 -> 0 | G7: =D8=K7 -> TRUE | I7: 매출채권및기타수취채권 | J7: 4,5,6,8,35 | K7: 2048442985 | L7: 2018156685
B8: 매출채권및기타채권 | C8: =정산표!H10 -> 1667306010 | D8: =정산표!M10 -> 2048442985 | G8: =D9=K8 -> TRUE | I8: 재고자산 | J8: 9 | K8: 2034274672 | L8: 2152367340
B9: 재고자산 | C9: =정산표!H17 -> 2202609621 | D9: =정산표!M17 -> 2034274672 | G9: =D10=K9 -> TRUE | I9: 기타유동자산 | J9: 10 | K9: 2735837690 | L9: 772410372
B10: 기타유동자산 | C10: =정산표!H27 -> 2097128278 | D10: =정산표!M27 -> 2735837690 | G10: =D11=K10 -> TRUE | I10: 기타유동금융자산 | J10: 4,5,6,8,11,35 | K10: 1250001 | L10: 394803338
B11: 기타유동금융자산 | C11: =정산표!H33 -> 0 | D11: =정산표!M33 -> 1250001 | G11: =D12=K11 -> TRUE | I11: 당기법인세자산 | J11: 22 | K11: 7479410 | L11: 10897260
B12: 당기법인세자산 | C12: =정산표!H36 -> 2154280 | D12: =정산표!M36 -> 7479410 | G12: =D13=K12 -> TRUE | I12: 비유동자산 | K12: 29197391461 | L12: 9570884416
B13: 비유동자산 | C13: =SUM(C14:C19) -> 37605682655 | D13: =SUM(D14:D19) -> 29197391461 | G13: =D14=K13 -> TRUE | I13: 기타비유동금융자산 | J13: 4,5,6,11 | K13: 388220275 | L13: 21783535
B14: 기타비유동금융자산 | C14: =정산표!H38 -> 386082376 | D14: =정산표!M38 -> 388220275 | G14: =D15=K14 -> TRUE | I14: 당기손익-공정가치측정금융자산 | J14: 4,6,12 | K14: 172664940 | L14: 189231441
B15: 당기손익-공정가치금융자산 | C15: =정산표!H42 -> 172664940 | D15: =정산표!M42 -> 172664940 | G15: =D16=K15 -> TRUE | I15: 종속기업및관계기업투자 | J15: 15,35 | K15: 17348225181 | L15: 666578175
B16: 종속기업투자및관계기업투자 | C16: =정산표!H43 -> 25348225181 | D16: =정산표!M43 -> 17348225181 | G16: =D17=K16 -> TRUE | I16: 유형자산 | J16: 13,20,23 | K16: 8682807344 | L16: 6085259645
B17: 유형자산 | C17: =정산표!H47 -> 9018883065 | D17: =정산표!M47 -> 8682807344 | G17: =D18=K17 -> TRUE | I17: 무형자산 | J17: 14 | K17: 50368750 | L17: 218757479
B18: 무형자산 | C18: =정산표!H66 -> 124722122 | D18: =정산표!M66 -> 50368750 | G18: =D19=K18 -> TRUE | I18: 이연법인세자산 | J18: 22 | K18: 2555104971 | L18: 2389274141
B19: 이연법인세자산 | C19: =정산표!H71 -> 2555104971 | D19: =정산표!M71 -> 2555104971 | G19: =D20=K19 -> TRUE | I19: 자산총계 | K19: 55193887404 | L19: 16876873821
B20: 자산총계 | C20: =C5+C13 -> 54543045905 | D20: =D5+D13 -> 55193887404 | G20: =D21=K20 -> TRUE | I20: 부채
B21: 부채 | G21: =D22=K21 -> TRUE | I21: 유동부채 | K21: 5794685216 | L21: 5458740013
B22: 유동부채 | C22: =SUM(C23:C27) -> 7026815912 | D22: =SUM(D23:D27) -> 5794685216 | G22: =D23=K22 -> TRUE | I22: 매입채무및기타지급채무 | J22: 4,5,6,16,35 | K22: 1584755867 | L22: 1698293625
B23: 매입채무및기타지급채무 | C23: =정산표!H75 -> 3144825470 | D23: =정산표!M75 -> 1584755867 | G23: =D24=K23 -> TRUE | I23: 단기차입금 | J23: 4,5,6,19,23,35 | K23: 1120000000 | L23: 1120000000
B24: 단기차입금 | C24: =정산표!H80 -> 1120000000 | D24: =정산표!M80 -> 1120000000 | G24: =D25=K24 -> TRUE | I24: 유동성장기차입금 | J24: 4,5,6,19,23,35 | K24: 83300000 | L24: 99960000
B25: 유동성장기차입금 | C25: =정산표!H81 -> 0 | D25: =정산표!M81 -> 83300000 | G25: =D26=K25 -> TRUE | I25: 유동성리스부채 | J25: 4,5,6,20 | K25: 545986082 | L25: 359470185
B26: 유동성리스부채 | C26: =정산표!H82 -> 537067117 | D26: =정산표!M82 -> 545986082 | G26: =D27=K26 -> TRUE | I26: 기타유동부채 | J26: 17,18,27 | K26: 2460643267 | L26: 2181016203
B27: 기타유동부채 | C27: =정산표!H83 -> 2224923325 | D27: =정산표!M83 -> 2460643267 | G27: =D28=K27 -> TRUE | I27: 비유동부채 | K27: 6909567083 | L27: 5312588524
B28: 비유동부채 | C28: =SUM(C29:C32) -> 5815444698 | D28: =SUM(D29:D32) -> 6909567083 | G28: =D29=K28 -> TRUE | I28: 장기차입금 | J28: 4,5,6,19,23,35 | K28: 4100000000 | L28: 3683300000
B29: 장기차입금 | C29: =정산표!H89 -> 4100000000 | D29: =정산표!M89 -> 4100000000 | G29: =D30=K29 -> TRUE | I29: 리스부채 | J29: 4,5,6,20 | K29: 1049272823 | L29: 103490106
B30: 리스부채 | C30: =정산표!H90 -> 799358124 | D30: =정산표!M90 -> 1049272823 | E30: =C30+C26 -> 1336425241 | F30: =D30+D26 -> 1595258905 | G30: =D31=K30 -> TRUE | I30: 확정급여부채 | J30: 21 | K30: 1587206234 | L30: 1355144834
B31: 확정급여부채 | C31: =정산표!H91 -> 710376650 | D31: =정산표!M91 -> 1587206234 | G31: =D32=K31 -> TRUE | I31: 기타비유동부채 | J31: 17 | K31: 173088026 | L31: 170653584
B32: 기타비유동부채 | C32: =정산표!H87 -> 205709924 | D32: =정산표!M87 -> 173088026 | G32: =D33=K32 -> TRUE | I32: 부채총계 | K32: 12704252299 | L32: 10771328537
B33: 부채총계 | C33: =C22+C28 -> 12842260610 | D33: =D22+D28 -> 12704252299 | G33: =D34=K33 -> TRUE | I33: 자본
B34: 자본 | G34: =D35=K34 -> TRUE | I34: 자본금 | J34: 1,24 | K34: 5691191500 | L34: 3123279500
B35: 자본금 | C35: =정산표!H97 -> 5691191500 | D35: =정산표!M97 -> 5691191500 | G35: =D36=K35 -> TRUE | I35: 자본잉여금 | J35: 24 | K35: 45157382298 | L35: 12384121289
B36: 자본잉여금 | C36: =정산표!H99 -> 45157382298 | D36: =정산표!M99 -> 45157382298 | G36: =D37=K36 -> TRUE | I36: 기타자본항목 | J36: 25 | K36: 424627793 | L36: 377682898
B37: 기타자본항목 | C37: =정산표!H101 -> 424627793 | D37: =정산표!M101 -> 424627793 | G37: =D38=K37 -> TRUE | I37: 결손금 | J37: 26 | K37: -8783566486 | L37: -9779538403
B38: 이익잉여금(결손금) | C38: =정산표!H103 -> -9572416296 | D38: =정산표!M103 -> -8783566486 | G38: =D39=K38 -> TRUE | I38: 자본총계 | K38: 42489635105 | L38: 6105545284
B39: 자본총계 | C39: =SUM(C35:C38) -> 41700785295 | D39: =SUM(D35:D38) -> 42489635105 | G39: =D40=K39 -> TRUE | I39: 부채와자본총계 | K39: 55193887404 | L39: 16876873821
B40: 부채와자본총계 | C40: =C39+C33 -> 54543045905 | D40: =D39+D33 -> 55193887404 | I40: 부채와자본총계 | K40: 16876873821 | L40: 9623140957
C41: =C40=C20 -> TRUE | D41: =D40=D20 -> TRUE
C42: =C40=BS!E102 -> TRUE | D42: =D40=BS!F102 -> TRUE

Sheet Dart_PL
B3: 과목 | C3: 46203 | E3: 45838 | K3: 제 15 기 1분기 | M3: 제 14 기 1분기 | P3: 과 목 | Q3: 주석 | R3: 제 14(당)기 반기 | T3: 제 13(전)기 반기
C4: 3개월 | D4: 누적 | E4: 3개월 | F4: 누적 | K4: 3개월 | L4: 누적 | M4: 3개월 | N4: 누적 | R4: 3개월 | S4: 누적 | T4: 3개월 | U4: 누적
B5: Ⅰ. 매출액 | C5: =D5-L5 -> 4246368702 | D5: =정산표!H113 -> 8288170687 | E5: =R5 -> 3962518140 | F5: =정산표!M113 -> 8817426997 | J5: 매출 | K5: 4041801985 | L5: 4041801985 | M5: 4854908857 | N5: 4854908857 | P5: Ⅰ. 매출액 | Q5: 27,35 | R5: 3962518140 | S5: 8817426997 | T5: 4797315163 | U5: 9148806988 | V5: =S5=F5 -> TRUE
B6: Ⅱ. 매출원가 | C6: =D6+L6 -> 1761754181 | D6: =정산표!H117 -> 3596633522 | E6: =R6 -> 1448493973 | F6: =정산표!M117 -> 3527195264 | J6: 매출원가 | K6: -1834879341 | L6: -1834879341 | M6: -2078701291 | N6: -2078701291 | P6: Ⅱ. 매출원가 | Q6: 29,35 | R6: 1448493973 | S6: 3527195264 | T6: 1804112452 | U6: 3381675952 | V6: =S6=F6 -> TRUE
B7: Ⅲ. 매출총이익 | C7: =C5-C6 -> 2484614521 | D7: =D5-D6 -> 4691537165 | E7: =E5-E6 -> 2514024167 | F7: =F5-F6 -> 5290231733 | J7: 매출총이익 | K7: 2206922644 | L7: 2206922644 | M7: 2776207566 | N7: 2776207566 | P7: Ⅲ. 매출총이익 | R7: 2514024167 | S7: 5290231733 | T7: 2993202711 | U7: 5767131036 | V7: =S7=F7 -> TRUE
B8: 판매비와 관리비 | C8: =D8+L8 -> 2852109483 | D8: =정산표!H137 -> 5378351282 | E8: =R8 -> 1959525763 | F8: =정산표!M137 -> 3878517000 | J8: 판매비와관리비 | K8: -2526241799 | L8: -2526241799 | M8: -1918991237 | N8: -1918991237 | P8: 판매비와관리비 | Q8: 14,28,29,35 | R8: 1959525763 | S8: 3878517000 | T8: 2227267329 | U8: 4520359356 | V8: =S8=F8 -> TRUE
B9: Ⅳ. 영업이익(손실) | C9: =C7-C8 -> -367494962 | D9: =D7-D8 -> -686814117 | E9: =E7-E8 -> 554498404 | F9: =F7-F8 -> 1411714733 | J9: 영업이익(손실) | K9: -319319155 | L9: -319319155 | M9: 857216329 | N9: 857216329 | P9: Ⅳ. 영업이익 | R9: 554498404 | S9: 1411714733 | T9: 765935382 | U9: 1246771680 | V9: =S9=F9 -> TRUE
B10: 기타수익 | C10: =D10-L10 -> 2134230 | D10: =정산표!H172 -> 4395999 | E10: =R10 -> 1815214 | F10: =정산표!M172 -> 7957022 | J10: 기타수익 | K10: 2261769 | L10: 2261769 | M10: 6141808 | N10: 6141808 | P10: 기타수익 | Q10: 31 | R10: 1815214 | S10: 7957022 | T10: 20385 | U10: 22068 | V10: =S10=F10 -> TRUE
B11: 기타비용 | C11: =D11+L11 -> 4822403 | D11: =정산표!H178 -> 4825612 | E11: =R11 -> 3118300 | F11: =정산표!M178 -> 3158006 | J11: 기타비용 | K11: -3209 | L11: -3209 | M11: -39706 | N11: -39706 | P11: 기타비용 | Q11: 31 | R11: 3118300 | S11: 3158006 | T11: 66507 | U11: 95269 | V11: =S11=F11 -> TRUE
B12: 금융수익 | C12: =D12-L12 -> 70638682 | D12: =정산표!H186 -> 169543833 | E12: =R12 -> 7705501 | F12: =정산표!M186 -> 48493067 | J12: 금융수익 | K12: 98905151 | L12: 98905151 | M12: 40787566 | N12: 40787566 | P12: 금융수익 | Q12: 6,32,35 | R12: 7705501 | S12: 48493067 | T12: 86901778 | U12: 207329481 | V12: =S12=F12 -> TRUE
B13: 금융비용 | C13: =D13+L13 -> 212855541 | D13: =정산표!H190 -> 271149913 | E13: =R13 -> 109909945 | F13: =정산표!M190 -> 141374675 | J13: 금융비용 | K13: -58294372 | L13: -58294372 | M13: -31464730 | N13: -31464730 | P13: 금융비용 | Q13: 6,32 | R13: 109909945 | S13: 141374675 | T13: 35425643 | U13: 80836283 | V13: =S13=F13 -> TRUE
B14: Ⅴ. 법인세비용차감전순이익(손실) | C14: =C9+C10-C11+C12-C13 -> -512399994 | D14: =D9+D10-D11+D12-D13 -> -788849810 | E14: =E9+E10-E11+E12-E13 -> 450990874 | F14: =F9+F10-F11+F12-F13 -> 1323632141 | J14: 법인세비용차감전순이익(손실) | K14: -276449816 | L14: -276449816 | M14: 872641267 | N14: 872641267 | P14: Ⅴ. 법인세비용차감전순이익 | R14: 450990874 | S14: 1323632141 | T14: 817365395 | U14: 1373191677 | V14: =S14=F14 -> TRUE
B15: 법인세비용 | C15: 0 | D15: =PL!E85 -> 0 | E15: =R15 -> 0 | F15: =정산표!M196 -> 0 | J15: 법인세비용(수익) | P15: 법인세비용(수익) | Q15: 22 | R15: 0 | S15: 0 | T15: - | U15: - | V15: =S15=F15 -> TRUE
B16: Ⅵ. 당기순이익(손실) | C16: =C14-C15 -> -512399994 | D16: =D14-D15 -> -788849810 | E16: =E14-E15 -> 450990874 | F16: =F14-F15 -> 1323632141 | J16: 당기순이익(손실) | K16: -276449816 | L16: -276449816 | M16: 872641267 | N16: 872641267 | P16: Ⅵ. 반기순이익 | R16: 450990874 | S16: 1323632141 | T16: 817365395 | U16: 1373191677 | V16: =S16=F16 -> TRUE
B17: Ⅶ. 기타포괄손익 | C17: =C19 -> 0 | D17: =D19 -> 0 | E17: =E19 -> 0 | F17: =F19 -> 0 | J17: 기타포괄손익 | P17: Ⅶ. 기타포괄손익 | R17: 0 | S17: 0 | T17: -53227701 | U17: -53227701 | V17: =S17=F17 -> TRUE
B18: 후속적으로 당기손익으로 재분류되지 않은 기타포괄손익 | D18: =D19 -> 0 | F18: =F19 -> 0 | J18: 후속적으로 당기손익으로 재분류되지 않은 기타포괄손익 | P18: 후속적으로 당기손익으로 재분류되지 않은 기타포괄손익 | V18: =S18=F18 -> TRUE
B19: 순확정급여부채 재측정요소 | C19: 0 | D19: =정산표!H199 -> 0 | E19: =R19 -> 0 | F19: =정산표!M199 -> 0 | J19: 순확정급여부채 재측정요소 | P19: 순확정급여부채의 재측정요소 | Q19: 21,26 | R19: 0 | S19: 0 | T19: -53227701 | U19: -53227701 | V19: =S19=F19 -> TRUE
B20: Ⅷ. 당기총포괄이익(손실) | C20: =C16+C17 -> -512399994 | D20: =D16+D17 -> -788849810 | E20: =E16+E17 -> 450990874 | F20: =F16+F17 -> 1323632141 | J20: 총포괄손익 | K20: -276449816 | L20: -276449816 | M20: 872641267 | N20: 872641267 | P20: Ⅷ. 총포괄이익 | R20: 450990874 | S20: 1323632141 | T20: 764137694 | U20: 1319963976 | V20: =S20=F20 -> TRUE
B21: Ⅸ. 당기주당손익 | J21: 주당이익 | P21: Ⅸ. 주당손익
B22: 주당당기순이익(손실) | C22: ='33'!E12 -> -45 | D22: ='33'!F12 -> -69 | E22: ='33'!G12 -> 72 | F22: ='33'!H12 -> 211 | J22: 기본주당이익(손실) (단위 : 원) | K22: -24 | L22: -24 | M22: 140 | N22: 140 | P22: 기본주당이익 | Q22: 33 | R22: 72 | S22: 211 | T22: 131 | U22: 221
B23: 희석당기순이익(손실) | C23: ='33'!E74 -> -45 | D23: ='33'!F74 -> -69.304451 | E23: ='33'!G74 -> 71 | F23: ='33'!H74 -> 209 | J23: 희석주당이익(손실) (단위 : 원) | K23: -24 | L23: -24 | M23: 138 | N23: 138 | P23: 희석주당이익 | Q23: 33 | R23: 71 | S23: 209 | T23: 130 | U23: 218
D25: =D20=정산표!H201 -> TRUE | F25: =F20=정산표!M201 -> TRUE

Sheet 정산표
E1: =E72-E106 -> 0 | F1: =SUM(F6:F201) -> 25009091519 | G1: =SUM(G6:G201)-G124-G131-G124-G131 -> 24999999500 | H1: =H72-H106 -> 0 | J1: =J72-J106 -> 0 | K1: =SUM(K6:K201) -> 0 | L1: =SUM(L6:L201)-L124-L131-L124-L131 -> 0 | M1: =M72-M106 -> 0
G2: =F1-G1 -> 9092019 | L2: =K1-L1 -> 0
E3: 46203 | J3: 46022
B4: Code | D4: 계정과목 | E4: 수정전 | F4: 차변 | G4: 대변 | H4: 수정후 | J4: 수정전 | K4: 차변 | L4: 대변 | M4: 수정후
D5: 자산
D6: 유동자산 | E6: =E7+E10+E17+E27+E36+E9+E33 -> 16937363250 | H6: =H7+H10+H17+H27+H36+H9+H33 -> 16937363250 | J6: =J7+J10+J17+J27+J36+J9+J33 -> 25996495943 | M6: =M7+M10+M17+M27+M36+M9+M33 -> 25996495943
D7: 현금및현금성자산 | E7: =E8 -> 10968165061 | H7: =H8 -> 10968165061 | J7: =J8 -> 19169211185 | M7: =M8 -> 19169211185
B8: 10300 | D8: 현금및현금성자산 | E8: =SUMIFS(제시BS!$H:$H,제시BS!$A:$A,정산표!$B8) -> 10968165061 | F8: =SUMIFS(별도_AJE_26.2Q!$G:$G,별도_AJE_26.2Q!$D:$D,정산표!$B8) -> 0 | G8: =SUMIFS(별도_AJE_26.2Q!$H:$H,별도_AJE_26.2Q!$D:$D,정산표!$B8) -> 0 | H8: =E8+F8-G8 -> 10968165061 | J8: 19169211185 | K8: =SUMIFS(별도_AJE_25!G:G,별도_AJE_25!$D:$D,정산표!$B8) -> 0 | L8: =SUMIFS(별도_AJE_25!H:H,별도_AJE_25!$D:$D,정산표!$B8) -> 0 | M8: =J8+K8-L8 -> 19169211185
B9: 10600 | D9: 단기금융상품 | E9: =SUMIFS(제시BS!$H:$H,제시BS!$A:$A,정산표!$B9) -> 0 | F9: =SUMIFS(별도_AJE_26.2Q!$G:$G,별도_AJE_26.2Q!$D:$D,정산표!$B9) -> 0 | G9: =SUMIFS(별도_AJE_26.2Q!$H:$H,별도_AJE_26.2Q!$D:$D,정산표!$B9) -> 0 | H9: =E9+F9-G9 -> 0 | J9: 0 | K9: =SUMIFS(별도_AJE_25!G:G,별도_AJE_25!$D:$D,정산표!$B9) -> 0 | L9: =SUMIFS(별도_AJE_25!H:H,별도_AJE_25!$D:$D,정산표!$B9) -> 0 | M9: =J9+K9-L9 -> 0
D10: 매출채권및기타채권 | E10: =SUM(E11:E16) -> 1667306010 | H10: =SUM(H11:H16) -> 1667306010 | J10: =SUM(J11:J16) -> 2048442985 | K10: =SUM(K11:K16) -> 0 | L10: =SUM(L11:L16) -> 0 | M10: =SUM(M11:M16) -> 2048442985
B11: 10800 | D11: 매출채권 | E11: =SUMIFS(제시BS!$H:$H,제시BS!$A:$A,정산표!$B11) -> 1535770100 | F11: =SUMIFS(별도_AJE_26.2Q!$G:$G,별도_AJE_26.2Q!$D:$D,정산표!$B11) -> 0 | G11: =SUMIFS(별도_AJE_26.2Q!$H:$H,별도_AJE_26.2Q!$D:$D,정산표!$B11) -> 0 | H11: =E11+F11-G11 -> 1535770100 | J11: 1998788804 | K11: =SUMIFS(별도_AJE_25!G:G,별도_AJE_25!$D:$D,정산표!$B11) -> 0 | L11: =SUMIFS(별도_AJE_25!H:H,별도_AJE_25!$D:$D,정산표!$B11) -> 0 | M11: =J11+K11-L11 -> 1998788804
B12: 10900 | D12: 매출채권대손충당금 | E12: =SUMIFS(제시BS!$H:$H,제시BS!$A:$A,정산표!$B12) -> -105342662 | F12: =SUMIFS(별도_AJE_26.2Q!$G:$G,별도_AJE_26.2Q!$D:$D,정산표!$B12) -> 0 | G12: =SUMIFS(별도_AJE_26.2Q!$H:$H,별도_AJE_26.2Q!$D:$D,정산표!$B12) -> 0 | H12: =E12+F12-G12 -> -105342662 | J12: -188230079 | K12: =SUMIFS(별도_AJE_25!G:G,별도_AJE_25!$D:$D,정산표!$B12) -> 0 | L12: =SUMIFS(별도_AJE_25!H:H,별도_AJE_25!$D:$D,정산표!$B12) -> 0 | M12: =J12+K12-L12 -> -188230079
B13: 11600 | D13: 미수수익 | E13: =SUMIFS(제시BS!$H:$H,제시BS!$A:$A,정산표!$B13) -> 0 | F13: =SUMIFS(별도_AJE_26.2Q!$G:$G,별도_AJE_26.2Q!$D:$D,정산표!$B13) -> 0 | G13: =SUMIFS(별도_AJE_26.2Q!$H:$H,별도_AJE_26.2Q!$D:$D,정산표!$B13) -> 0 | H13: =E13+F13-G13 -> 0 | J13: 0 | K13: =SUMIFS(별도_AJE_25!G:G,별도_AJE_25!$D:$D,정산표!$B13) -> 0 | L13: =SUMIFS(별도_AJE_25!H:H,별도_AJE_25!$D:$D,정산표!$B13) -> 0 | M13: =J13+K13-L13 -> 0
B14: 11700 | D14: 미수수익대손충당금 | E14: =SUMIFS(제시BS!$H:$H,제시BS!$A:$A,정산표!$B14) -> 0 | F14: =SUMIFS(별도_AJE_26.2Q!$G:$G,별도_AJE_26.2Q!$D:$D,정산표!$B14) -> 0 | G14: =SUMIFS(별도_AJE_26.2Q!$H:$H,별도_AJE_26.2Q!$D:$D,정산표!$B14) -> 0 | H14: =E14+F14-G14 -> 0 | J14: 0 | K14: =SUMIFS(별도_AJE_25!G:G,별도_AJE_25!$D:$D,정산표!$B14) -> 0 | L14: =SUMIFS(별도_AJE_25!H:H,별도_AJE_25!$D:$D,정산표!$B14) -> 0 | M14: =J14+K14-L14 -> 0
B15: 12000 | D15: 미수금 | E15: =SUMIFS(제시BS!$H:$H,제시BS!$A:$A,정산표!$B15) -> 261017572 | F15: =SUMIFS(별도_AJE_26.2Q!$G:$G,별도_AJE_26.2Q!$D:$D,정산표!$B15) -> 0 | G15: =SUMIFS(별도_AJE_26.2Q!$H:$H,별도_AJE_26.2Q!$D:$D,정산표!$B15) -> 0 | H15: =E15+F15-G15 -> 261017572 | J15: 265023260 | K15: =SUMIFS(별도_AJE_25!G:G,별도_AJE_25!$D:$D,정산표!$B15) -> 0 | L15: =SUMIFS(별도_AJE_25!H:H,별도_AJE_25!$D:$D,정산표!$B15) -> 0 | M15: =J15+K15-L15 -> 265023260
B16: 12100 | D16: 미수금대손충당금 | E16: =SUMIFS(제시BS!$H:$H,제시BS!$A:$A,정산표!$B16) -> -24139000 | F16: =SUMIFS(별도_AJE_26.2Q!$G:$G,별도_AJE_26.2Q!$D:$D,정산표!$B16) -> 0 | G16: =SUMIFS(별도_AJE_26.2Q!$H:$H,별도_AJE_26.2Q!$D:$D,정산표!$B16) -> 0 | H16: =E16+F16-G16 -> -24139000 | J16: -27139000 | K16: =SUMIFS(별도_AJE_25!G:G,별도_AJE_25!$D:$D,정산표!$B16) -> 0 | L16: =SUMIFS(별도_AJE_25!H:H,별도_AJE_25!$D:$D,정산표!$B16) -> 0 | M16: =J16+K16-L16 -> -27139000
D17: 재고자산 | E17: =SUM(E18:E26) -> 2202609621 | H17: =SUM(H18:H26) -> 2202609621 | J17: =SUM(J18:J26) -> 2034274672 | K17: =SUM(K18:K26) -> 0 | L17: =SUM(L18:L26) -> 0 | M17: =SUM(M18:M26) -> 2034274672
B18: 14600 | D18: 상품 | E18: =SUMIFS(제시BS!$H:$H,제시BS!$A:$A,정산표!$B18) -> 47852743 | F18: =SUMIFS(별도_AJE_26.2Q!$G:$G,별도_AJE_26.2Q!$D:$D,정산표!$B18) -> 0 | G18: =SUMIFS(별도_AJE_26.2Q!$H:$H,별도_AJE_26.2Q!$D:$D,정산표!$B18) -> 0 | H18: =E18+F18-G18 -> 47852743 | J18: 42227029 | K18: =SUMIFS(별도_AJE_25!G:G,별도_AJE_25!$D:$D,정산표!$B18) -> 0 | L18: =SUMIFS(별도_AJE_25!H:H,별도_AJE_25!$D:$D,정산표!$B18) -> 0 | M18: =J18+K18-L18 -> 42227029
B19: 16000 | D19: 상품평가충당금 | E19: =SUMIFS(제시BS!$H:$H,제시BS!$A:$A,정산표!$B19) -> 0 | F19: =SUMIFS(별도_AJE_26.2Q!$G:$G,별도_AJE_26.2Q!$D:$D,정산표!$B19) -> 0 | G19: =SUMIFS(별도_AJE_26.2Q!$H:$H,별도_AJE_26.2Q!$D:$D,정산표!$B19) -> 0 | H19: =E19+F19-G19 -> 0 | J19: -14089 | K19: =SUMIFS(별도_AJE_25!G:G,별도_AJE_25!$D:$D,정산표!$B19) -> 0 | L19: =SUMIFS(별도_AJE_25!H:H,별도_AJE_25!$D:$D,정산표!$B19) -> 0 | M19: =J19+K19-L19 -> -14089
B20: 14700 | D20: 제품 | E20: =SUMIFS(제시BS!$H:$H,제시BS!$A:$A,정산표!$B20) -> 2534717672 | F20: =SUMIFS(별도_AJE_26.2Q!$G:$G,별도_AJE_26.2Q!$D:$D,정산표!$B20) -> 0 | G20: =SUMIFS(별도_AJE_26.2Q!$H:$H,별도_AJE_26.2Q!$D:$D,정산표!$B20) -> 0 | H20: =E20+F20-G20 -> 2534717672 | J20: 2349819825 | K20: =SUMIFS(별도_AJE_25!G:G,별도_AJE_25!$D:$D,정산표!$B20) -> 0 | L20: =SUMIFS(별도_AJE_25!H:H,별도_AJE_25!$D:$D,정산표!$B20) -> 0 | M20: =J20+K20-L20 -> 2349819825
B21: 16100 | D21: 제품평가충당금 | E21: =SUMIFS(제시BS!$H:$H,제시BS!$A:$A,정산표!$B21) -> -827921741 | F21: =SUMIFS(별도_AJE_26.2Q!$G:$G,별도_AJE_26.2Q!$D:$D,정산표!$B21) -> 0 | G21: =SUMIFS(별도_AJE_26.2Q!$H:$H,별도_AJE_26.2Q!$D:$D,정산표!$B21) -> 0 | H21: =E21+F21-G21 -> -827921741 | J21: -725171962 | K21: =SUMIFS(별도_AJE_25!G:G,별도_AJE_25!$D:$D,정산표!$B21) -> 0 | L21: =SUMIFS(별도_AJE_25!H:H,별도_AJE_25!$D:$D,정산표!$B21) -> 0 | M21: =J21+K21-L21 -> -725171962
B22: 14900 | D22: 원재료 | E22: =SUMIFS(제시BS!$H:$H,제시BS!$A:$A,정산표!$B22) -> 464851515 | F22: =SUMIFS(별도_AJE_26.2Q!$G:$G,별도_AJE_26.2Q!$D:$D,정산표!$B22) -> 0 | G22: =SUMIFS(별도_AJE_26.2Q!$H:$H,별도_AJE_26.2Q!$D:$D,정산표!$B22) -> 0 | H22: =E22+F22-G22 -> 464851515 | J22: 354984836 | K22: =SUMIFS(별도_AJE_25!G:G,별도_AJE_25!$D:$D,정산표!$B22) -> 0 | L22: =SUMIFS(별도_AJE_25!H:H,별도_AJE_25!$D:$D,정산표!$B22) -> 0 | M22: =J22+K22-L22 -> 354984836
B23: 16200 | D23: 원재료평가충당금 | E23: =SUMIFS(제시BS!$H:$H,제시BS!$A:$A,정산표!$B23) -> -44697318 | F23: =SUMIFS(별도_AJE_26.2Q!$G:$G,별도_AJE_26.2Q!$D:$D,정산표!$B23) -> 0 | G23: =SUMIFS(별도_AJE_26.2Q!$H:$H,별도_AJE_26.2Q!$D:$D,정산표!$B23) -> 0 | H23: =E23+F23-G23 -> -44697318 | J23: -34479470 | K23: =SUMIFS(별도_AJE_25!G:G,별도_AJE_25!$D:$D,정산표!$B23) -> 0 | L23: =SUMIFS(별도_AJE_25!H:H,별도_AJE_25!$D:$D,정산표!$B23) -> 0 | M23: =J23+K23-L23 -> -34479470
B24: 15200 | D24: 부재료 | E24: =SUMIFS(제시BS!$H:$H,제시BS!$A:$A,정산표!$B24) -> 48405072 | F24: =SUMIFS(별도_AJE_26.2Q!$G:$G,별도_AJE_26.2Q!$D:$D,정산표!$B24) -> 0 | G24: =SUMIFS(별도_AJE_26.2Q!$H:$H,별도_AJE_26.2Q!$D:$D,정산표!$B24) -> 0 | H24: =E24+F24-G24 -> 48405072 | J24: 49267189 | K24: =SUMIFS(별도_AJE_25!G:G,별도_AJE_25!$D:$D,정산표!$B24) -> 0 | L24: =SUMIFS(별도_AJE_25!H:H,별도_AJE_25!$D:$D,정산표!$B24) -> 0 | M24: =J24+K24-L24 -> 49267189
B25: 15300 | D25: 부재료평가충당금 | E25: =SUMIFS(제시BS!$H:$H,제시BS!$A:$A,정산표!$B25) -> -20598322 | F25: =SUMIFS(별도_AJE_26.2Q!$G:$G,별도_AJE_26.2Q!$D:$D,정산표!$B25) -> 0 | G25: =SUMIFS(별도_AJE_26.2Q!$H:$H,별도_AJE_26.2Q!$D:$D,정산표!$B25) -> 0 | H25: =E25+F25-G25 -> -20598322 | J25: -2358686 | K25: =SUMIFS(별도_AJE_25!G:G,별도_AJE_25!$D:$D,정산표!$B25) -> 0 | L25: =SUMIFS(별도_AJE_25!H:H,별도_AJE_25!$D:$D,정산표!$B25) -> 0 | M25: =J25+K25-L25 -> -2358686
B26: 15700 | D26: 재공품 | E26: =SUMIFS(제시BS!$H:$H,제시BS!$A:$A,정산표!$B26) -> 0 | F26: =SUMIFS(별도_AJE_26.2Q!$G:$G,별도_AJE_26.2Q!$D:$D,정산표!$B26) -> 0 | G26: =SUMIFS(별도_AJE_26.2Q!$H:$H,별도_AJE_26.2Q!$D:$D,정산표!$B26) -> 0 | H26: =E26+F26-G26 -> 0 | J26: 0 | K26: =SUMIFS(별도_AJE_25!G:G,별도_AJE_25!$D:$D,정산표!$B26) -> 0 | L26: =SUMIFS(별도_AJE_25!H:H,별도_AJE_25!$D:$D,정산표!$B26) -> 0 | M26: =J26+K26-L26 -> 0
D27: 기타유동자산 | E27: =SUM(E28:E32) -> 2097128278 | H27: =SUM(H28:H32) -> 2097128278 | J27: =SUM(J28:J32) -> 2735837690 | M27: =SUM(M28:M32) -> 2735837690
B28: 13100 | D28: 선급금 | E28: =SUMIFS(제시BS!$H:$H,제시BS!$A:$A,정산표!$B28) -> 394157762 | F28: =SUMIFS(별도_AJE_26.2Q!$G:$G,별도_AJE_26.2Q!$D:$D,정산표!$B28) -> 0 | G28: =SUMIFS(별도_AJE_26.2Q!$H:$H,별도_AJE_26.2Q!$D:$D,정산표!$B28) -> 0 | H28: =E28+F28-G28 -> 394157762 | J28: 2254829529 | K28: =SUMIFS(별도_AJE_25!G:G,별도_AJE_25!$D:$D,정산표!$B28) -> 0 | L28: =SUMIFS(별도_AJE_25!H:H,별도_AJE_25!$D:$D,정산표!$B28) -> 0 | M28: =J28+K28-L28 -> 2254829529
B29: 13200 | D29: 선급금대손충당금 | E29: =SUMIFS(제시BS!$H:$H,제시BS!$A:$A,정산표!$B29) -> 0 | F29: =SUMIFS(별도_AJE_26.2Q!$G:$G,별도_AJE_26.2Q!$D:$D,정산표!$B29) -> 0 | G29: =SUMIFS(별도_AJE_26.2Q!$H:$H,별도_AJE_26.2Q!$D:$D,정산표!$B29) -> 0 | H29: =E29+F29-G29 -> 0 | J29: 0 | K29: =SUMIFS(별도_AJE_25!G:G,별도_AJE_25!$D:$D,정산표!$B29) -> 0 | L29: =SUMIFS(별도_AJE_25!H:H,별도_AJE_25!$D:$D,정산표!$B29) -> 0 | M29: =J29+K29-L29 -> 0
B30: 13300 | D30: 선급비용 | E30: =SUMIFS(제시BS!$H:$H,제시BS!$A:$A,정산표!$B30) -> 1698698289 | F30: =SUMIFS(별도_AJE_26.2Q!$G:$G,별도_AJE_26.2Q!$D:$D,정산표!$B30) -> 0 | G30: =SUMIFS(별도_AJE_26.2Q!$H:$H,별도_AJE_26.2Q!$D:$D,정산표!$B30) -> 0 | H30: =E30+F30-G30 -> 1698698289 | J30: 473315521 | K30: =SUMIFS(별도_AJE_25!G:G,별도_AJE_25!$D:$D,정산표!$B30) -> 0 | L30: =SUMIFS(별도_AJE_25!H:H,별도_AJE_25!$D:$D,정산표!$B30) -> 0 | M30: =J30+K30-L30 -> 473315521
B31: 14000 | D31: 환불자산 | E31: =SUMIFS(제시BS!$H:$H,제시BS!$A:$A,정산표!$B31) -> 4272227 | F31: =SUMIFS(별도_AJE_26.2Q!$G:$G,별도_AJE_26.2Q!$D:$D,정산표!$B31) -> 0 | G31: =SUMIFS(별도_AJE_26.2Q!$H:$H,별도_AJE_26.2Q!$D:$D,정산표!$B31) -> 0 | H31: =E31+F31-G31 -> 4272227 | J31: 7692640 | K31: =SUMIFS(별도_AJE_25!G:G,별도_AJE_25!$D:$D,정산표!$B31) -> 0 | L31: =SUMIFS(별도_AJE_25!H:H,별도_AJE_25!$D:$D,정산표!$B31) -> 0 | M31: =J31+K31-L31 -> 7692640
B32: 13500 | D32: 부가세대급금 | E32: =SUMIFS(제시BS!$H:$H,제시BS!$A:$A,정산표!$B32) -> 0 | F32: =SUMIFS(별도_AJE_26.2Q!$G:$G,별도_AJE_26.2Q!$D:$D,정산표!$B32) -> 0 | G32: =SUMIFS(별도_AJE_26.2Q!$H:$H,별도_AJE_26.2Q!$D:$D,정산표!$B32) -> 0 | H32: =E32+F32-G32 -> 0 | J32: 0 | K32: =SUMIFS(별도_AJE_25!G:G,별도_AJE_25!$D:$D,정산표!$B32) -> 0 | L32: =SUMIFS(별도_AJE_25!H:H,별도_AJE_25!$D:$D,정산표!$B32) -> 0 | M32: =J32+K32-L32 -> 0
D33: 기타유동금융자산 | E33: =SUM(E34:E35) -> 0 | H33: =SUM(H34:H35) -> 0 | J33: =SUM(J34:J35) -> 1250001 | M33: =SUM(M34:M35) -> 1250001
B34: 12400 | D34: 임차보증금(유동) | E34: =SUMIFS(제시BS!$H:$H,제시BS!$A:$A,정산표!$B34) -> 0 | F34: =SUMIFS(별도_AJE_26.2Q!$G:$G,별도_AJE_26.2Q!$D:$D,정산표!$B34) -> 0 | G34: =SUMIFS(별도_AJE_26.2Q!$H:$H,별도_AJE_26.2Q!$D:$D,정산표!$B34) -> 0 | H34: =E34+F34-G34 -> 0 | J34: 0 | K34: =SUMIFS(별도_AJE_25!G:G,별도_AJE_25!$D:$D,정산표!$B34) -> 0 | L34: =SUMIFS(별도_AJE_25!H:H,별도_AJE_25!$D:$D,정산표!$B34) -> 0 | M34: =J34+K34-L34 -> 0
B35: 13400 | D35: 주 . 임.종단기채권 | E35: =SUMIFS(제시BS!$H:$H,제시BS!$A:$A,정산표!$B35) -> 0 | F35: =SUMIFS(별도_AJE_26.2Q!$G:$G,별도_AJE_26.2Q!$D:$D,정산표!$B35) -> 0 | G35: =SUMIFS(별도_AJE_26.2Q!$H:$H,별도_AJE_26.2Q!$D:$D,정산표!$B35) -> 0 | H35: =E35+F35-G35 -> 0 | J35: 1250001 | K35: =SUMIFS(별도_AJE_25!G:G,별도_AJE_25!$D:$D,정산표!$B35) -> 0 | L35: =SUMIFS(별도_AJE_25!H:H,별도_AJE_25!$D:$D,정산표!$B35) -> 0 | M35: =J35+K35-L35 -> 1250001
B36: 13600 | D36: 당기법인세자산 | E36: =SUMIFS(제시BS!$H:$H,제시BS!$A:$A,정산표!$B36) -> 2154280 | F36: =SUMIFS(별도_AJE_26.2Q!$G:$G,별도_AJE_26.2Q!$D:$D,정산표!$B36) -> 0 | G36: =SUMIFS(별도_AJE_26.2Q!$H:$H,별도_AJE_26.2Q!$D:$D,정산표!$B36) -> 0 | H36: =E36+F36-G36 -> 2154280 | J36: 7479410 | K36: =SUMIFS(별도_AJE_25!G:G,별도_AJE_25!$D:$D,정산표!$B36) -> 0 | L36: =SUMIFS(별도_AJE_25!H:H,별도_AJE_25!$D:$D,정산표!$B36) -> 0 | M36: =J36+K36-L36 -> 7479410
D37: 비유동자산 | E37: =E38+E43+E47+E66+E42+E71 -> 37614774674 | H37: =H38+H43+H47+H66+H42+H71 -> 37605682655 | J37: =J38+J43+J47+J66+J42+J71 -> 29197391461 | M37: =M38+M43+M47+M66+M42+M71 -> 29197391461
D38: 기타비유동금융자산 | E38: =SUM(E39:E41) -> 386082376 | H38: =SUM(H39:H41) -> 386082376 | J38: =SUM(J39:J41) -> 388220275 | K38: =SUM(K39:K41) -> 0 | L38: =SUM(L39:L41) -> 0 | M38: =SUM(M39:M41) -> 388220275
B39: 18800 | D39: 임차보증금 | E39: =SUMIFS(제시BS!$H:$H,제시BS!$A:$A,정산표!$B39) -> 403800000 | F39: =SUMIFS(별도_AJE_26.2Q!$G:$G,별도_AJE_26.2Q!$D:$D,정산표!$B39) -> 0 | G39: =SUMIFS(별도_AJE_26.2Q!$H:$H,별도_AJE_26.2Q!$D:$D,정산표!$B39) -> 0 | H39: =E39+F39-G39 -> 403800000 | J39: 413778000 | K39: =SUMIFS(별도_AJE_25!G:G,별도_AJE_25!$D:$D,정산표!$B39) -> 0 | L39: =SUMIFS(별도_AJE_25!H:H,별도_AJE_25!$D:$D,정산표!$B39) -> 0 | M39: =J39+K39-L39 -> 413778000
B40: 18900 | D40: 임차보증금_현재가치할인차금 | E40: =SUMIFS(제시BS!$H:$H,제시BS!$A:$A,정산표!$B40) -> -27853494 | F40: =SUMIFS(별도_AJE_26.2Q!$G:$G,별도_AJE_26.2Q!$D:$D,정산표!$B40) -> 0 | G40: =SUMIFS(별도_AJE_26.2Q!$H:$H,별도_AJE_26.2Q!$D:$D,정산표!$B40) -> 0 | H40: =E40+F40-G40 -> -27853494 | J40: -35581895 | K40: =SUMIFS(별도_AJE_25!G:G,별도_AJE_25!$D:$D,정산표!$B40) -> 0 | L40: =SUMIFS(별도_AJE_25!H:H,별도_AJE_25!$D:$D,정산표!$B40) -> 0 | M40: =J40+K40-L40 -> -35581895
...

Sheet 정산표_IFRS18
B1: 정산표 (IFRS 18 손익계산서 기준) - 별도
B2: ※ 기존 [정산표] 시트의 금액을 그대로 연동하여 IFRS 18 범주(영업·투자·재무·법인세)로 재분류한 정산표입니다. 재분류는 하단 [부록 1]의 P열(노란색·파란글씨)에서 변경하면 자동 반영됩니다.
E3: ='정산표'!E3 -> 46203 | J3: ='정산표'!J3 -> 46022
B4: Code | D4: 계정과목 | E4: 수정전 | F4: 차변 | G4: 대변 | H4: 수정후 | J4: 수정전 | K4: 차변 | L4: 대변 | M4: 수정후
B5: Ⅰ. 영업 범주
D6: 매출액 | E6: =SUMIFS(E$63:E$121,$P$63:$P$121,$D6) -> 8288170687 | F6: =SUMIFS(F$63:F$121,$P$63:$P$121,$D6) -> 0 | G6: =SUMIFS(G$63:G$121,$P$63:$P$121,$D6) -> 0 | H6: =SUMIFS(H$63:H$121,$P$63:$P$121,$D6) -> 8288170687 | J6: =SUMIFS(J$63:J$121,$P$63:$P$121,$D6) -> 8817426997 | K6: =SUMIFS(K$63:K$121,$P$63:$P$121,$D6) -> 0 | L6: =SUMIFS(L$63:L$121,$P$63:$P$121,$D6) -> 0 | M6: =SUMIFS(M$63:M$121,$P$63:$P$121,$D6) -> 8817426997
D7: 매출원가 | E7: =SUMIFS(E$63:E$121,$P$63:$P$121,$D7) -> 3596633522 | F7: =SUMIFS(F$63:F$121,$P$63:$P$121,$D7) -> 0 | G7: =SUMIFS(G$63:G$121,$P$63:$P$121,$D7) -> 0 | H7: =SUMIFS(H$63:H$121,$P$63:$P$121,$D7) -> 3596633522 | J7: =SUMIFS(J$63:J$121,$P$63:$P$121,$D7) -> 3527195264 | K7: =SUMIFS(K$63:K$121,$P$63:$P$121,$D7) -> 0 | L7: =SUMIFS(L$63:L$121,$P$63:$P$121,$D7) -> 0 | M7: =SUMIFS(M$63:M$121,$P$63:$P$121,$D7) -> 3527195264
D8: 매출총이익 | E8: =E6-E7 -> 4691537165 | H8: =H6-H7 -> 4691537165 | J8: =J6-J7 -> 5290231733 | M8: =M6-M7 -> 5290231733
D9: 판매비와관리비 | E9: =SUMIFS(E$63:E$121,$P$63:$P$121,$D9) -> 5378351282 | F9: =SUMIFS(F$63:F$121,$P$63:$P$121,$D9) -> 0 | G9: =SUMIFS(G$63:G$121,$P$63:$P$121,$D9) -> 0 | H9: =SUMIFS(H$63:H$121,$P$63:$P$121,$D9) -> 5378351282 | J9: =SUMIFS(J$63:J$121,$P$63:$P$121,$D9) -> 3878517000 | K9: =SUMIFS(K$63:K$121,$P$63:$P$121,$D9) -> 0 | L9: =SUMIFS(L$63:L$121,$P$63:$P$121,$D9) -> 0 | M9: =SUMIFS(M$63:M$121,$P$63:$P$121,$D9) -> 3878517000
D10: 기타영업수익 | E10: =SUMIFS(E$63:E$121,$P$63:$P$121,$D10) -> 151841271 | F10: =SUMIFS(F$63:F$121,$P$63:$P$121,$D10) -> 0 | G10: =SUMIFS(G$63:G$121,$P$63:$P$121,$D10) -> 0 | H10: =SUMIFS(H$63:H$121,$P$63:$P$121,$D10) -> 151841271 | J10: =SUMIFS(J$63:J$121,$P$63:$P$121,$D10) -> 28441829 | K10: =SUMIFS(K$63:K$121,$P$63:$P$121,$D10) -> 0 | L10: =SUMIFS(L$63:L$121,$P$63:$P$121,$D10) -> 0 | M10: =SUMIFS(M$63:M$121,$P$63:$P$121,$D10) -> 28441829
D11: 기타영업비용 | E11: =SUMIFS(E$63:E$121,$P$63:$P$121,$D11) -> 177020574 | F11: =SUMIFS(F$63:F$121,$P$63:$P$121,$D11) -> 0 | G11: =SUMIFS(G$63:G$121,$P$63:$P$121,$D11) -> 0 | H11: =SUMIFS(H$63:H$121,$P$63:$P$121,$D11) -> 177020574 | J11: =SUMIFS(J$63:J$121,$P$63:$P$121,$D11) -> 101288328 | K11: =SUMIFS(K$63:K$121,$P$63:$P$121,$D11) -> 0 | L11: =SUMIFS(L$63:L$121,$P$63:$P$121,$D11) -> 0 | M11: =SUMIFS(M$63:M$121,$P$63:$P$121,$D11) -> 101288328
D12: 영업손익 | E12: =E8-E9+E10-E11 -> -711993420 | H12: =H8-H9+H10-H11 -> -711993420 | J12: =J8-J9+J10-J11 -> 1338868234 | M12: =M8-M9+M10-M11 -> 1338868234
B14: Ⅱ. 투자 범주
D15: 투자수익 | E15: =SUMIFS(E$63:E$121,$P$63:$P$121,$D15) -> 22098561 | F15: =SUMIFS(F$63:F$121,$P$63:$P$121,$D15) -> 0 | G15: =SUMIFS(G$63:G$121,$P$63:$P$121,$D15) -> 0 | H15: =SUMIFS(H$63:H$121,$P$63:$P$121,$D15) -> 22098561 | J15: =SUMIFS(J$63:J$121,$P$63:$P$121,$D15) -> 28008260 | K15: =SUMIFS(K$63:K$121,$P$63:$P$121,$D15) -> 0 | L15: =SUMIFS(L$63:L$121,$P$63:$P$121,$D15) -> 0 | M15: =SUMIFS(M$63:M$121,$P$63:$P$121,$D15) -> 28008260
D16: 투자비용 | E16: =SUMIFS(E$63:E$121,$P$63:$P$121,$D16) -> 0 | F16: =SUMIFS(F$63:F$121,$P$63:$P$121,$D16) -> 0 | G16: =SUMIFS(G$63:G$121,$P$63:$P$121,$D16) -> 0 | H16: =SUMIFS(H$63:H$121,$P$63:$P$121,$D16) -> 0 | J16: =SUMIFS(J$63:J$121,$P$63:$P$121,$D16) -> 0 | K16: =SUMIFS(K$63:K$121,$P$63:$P$121,$D16) -> 0 | L16: =SUMIFS(L$63:L$121,$P$63:$P$121,$D16) -> 0 | M16: =SUMIFS(M$63:M$121,$P$63:$P$121,$D16) -> 0
D17: 투자손익 | E17: =E15-E16 -> 22098561 | H17: =H15-H16 -> 22098561 | J17: =J15-J16 -> 28008260 | M17: =M15-M16 -> 28008260
D18: 재무 및 법인세 전 손익 | E18: =E12+E17 -> -689894859 | H18: =H12+H17 -> -689894859 | J18: =J12+J17 -> 1366876494 | M18: =M12+M17 -> 1366876494
B20: Ⅲ. 재무 범주
D21: 재무수익 | E21: =SUMIFS(E$63:E$121,$P$63:$P$121,$D21) -> 0 | F21: =SUMIFS(F$63:F$121,$P$63:$P$121,$D21) -> 0 | G21: =SUMIFS(G$63:G$121,$P$63:$P$121,$D21) -> 0 | H21: =SUMIFS(H$63:H$121,$P$63:$P$121,$D21) -> 0 | J21: =SUMIFS(J$63:J$121,$P$63:$P$121,$D21) -> 0 | K21: =SUMIFS(K$63:K$121,$P$63:$P$121,$D21) -> 0 | L21: =SUMIFS(L$63:L$121,$P$63:$P$121,$D21) -> 0 | M21: =SUMIFS(M$63:M$121,$P$63:$P$121,$D21) -> 0
D22: 재무비용 | E22: =SUMIFS(E$63:E$121,$P$63:$P$121,$D22) -> 89862932 | F22: =SUMIFS(F$63:F$121,$P$63:$P$121,$D22) -> 9092019 | G22: =SUMIFS(G$63:G$121,$P$63:$P$121,$D22) -> 0 | H22: =SUMIFS(H$63:H$121,$P$63:$P$121,$D22) -> 98954951 | J22: =SUMIFS(J$63:J$121,$P$63:$P$121,$D22) -> 43244353 | K22: =SUMIFS(K$63:K$121,$P$63:$P$121,$D22) -> 0 | L22: =SUMIFS(L$63:L$121,$P$63:$P$121,$D22) -> 0 | M22: =SUMIFS(M$63:M$121,$P$63:$P$121,$D22) -> 43244353
D23: 재무손익 | E23: =E21-E22 -> -89862932 | H23: =H21-H22 -> -98954951 | J23: =J21-J22 -> -43244353 | M23: =M21-M22 -> -43244353
D25: 법인세비용차감전손익 | E25: =E18+E23 -> -779757791 | H25: =H18+H23 -> -788849810 | J25: =J18+J23 -> 1323632141 | M25: =M18+M23 -> 1323632141
D26: 법인세비용 | E26: =SUMIFS(E$63:E$121,$P$63:$P$121,$D26) -> 0 | F26: =SUMIFS(F$63:F$121,$P$63:$P$121,$D26) -> 0 | G26: =SUMIFS(G$63:G$121,$P$63:$P$121,$D26) -> 0 | H26: =SUMIFS(H$63:H$121,$P$63:$P$121,$D26) -> 0 | J26: =SUMIFS(J$63:J$121,$P$63:$P$121,$D26) -> 0 | K26: =SUMIFS(K$63:K$121,$P$63:$P$121,$D26) -> 0 | L26: =SUMIFS(L$63:L$121,$P$63:$P$121,$D26) -> 0 | M26: =SUMIFS(M$63:M$121,$P$63:$P$121,$D26) -> 0
D27: 당기순이익(손실) | E27: =E25-E26 -> -779757791 | H27: =H25-H26 -> -788849810 | J27: =J25-J26 -> 1323632141 | M27: =M25-M26 -> 1323632141
D28: 기타포괄손익 | E28: =SUMIFS(E$63:E$121,$P$63:$P$121,$D28) -> 0 | F28: =SUMIFS(F$63:F$121,$P$63:$P$121,$D28) -> 0 | G28: =SUMIFS(G$63:G$121,$P$63:$P$121,$D28) -> 0 | H28: =SUMIFS(H$63:H$121,$P$63:$P$121,$D28) -> 0 | J28: =SUMIFS(J$63:J$121,$P$63:$P$121,$D28) -> 0 | K28: =SUMIFS(K$63:K$121,$P$63:$P$121,$D28) -> 0 | L28: =SUMIFS(L$63:L$121,$P$63:$P$121,$D28) -> 0 | M28: =SUMIFS(M$63:M$121,$P$63:$P$121,$D28) -> 0
D29: 총포괄손익 | E29: =E27+E28 -> -779757791 | H29: =H27+H28 -> -788849810 | J29: =J27+J28 -> 1323632141 | M29: =M27+M28 -> 1323632141
B31: [검증] 기존 정산표 대비 차이 (모두 0이어야 함)
D32: 당기순이익 - 정산표 | E32: =E27-'정산표'!E197 -> 0 | H32: =H27-'정산표'!H197 -> 0 | J32: =J27-'정산표'!J197 -> 0 | M32: =M27-'정산표'!M197 -> 0
D33: 총포괄손익 - 정산표 | E33: =E29-'정산표'!E201 -> 0 | H33: =H29-'정산표'!H201 -> 0 | J33: =J29-'정산표'!J201 -> 0 | M33: =M29-'정산표'!M201 -> 0
D34: 법인세비용차감전손익 - 정산표 | E34: =E25-'정산표'!E195 -> 0 | H34: =H25-'정산표'!H195 -> 0 | J34: =J25-'정산표'!J195 -> 0 | M34: =M25-'정산표'!M195 -> 0
D35: 표시항목 미지정/오류 계정 수 | E35: =SUMPRODUCT(--ISNA(MATCH($P$63:$P$121,$D$127:$D$137,0))) -> 0
D36: 종합 검증 | E36: =IF(AND(SUMPRODUCT(ABS(E32:M34))=0,E35=0),"OK","확인필요") -> OK
B38: [조정표] 기존 영업이익 → IFRS 18 영업손익
D39: 기존 영업이익 (정산표) | E39: ='정산표'!E171 -> -686814117 | H39: ='정산표'!H171 -> -686814117 | J39: ='정산표'!J171 -> 1411714733 | M39: ='정산표'!M171 -> 1411714733
D40: (+) IFRS 18 영업 범주로 편입된 기존 영업외손익 (기타영업손익·외환손익 등) | E40: =SUMPRODUCT(($Q$63:$Q$121="영업")*($S$63:$S$121=0)*$R$63:$R$121*E$63:E$121) -> -25179303 | H40: =SUMPRODUCT(($Q$63:$Q$121="영업")*($S$63:$S$121=0)*$R$63:$R$121*H$63:H$121) -> -25179303 | J40: =SUMPRODUCT(($Q$63:$Q$121="영업")*($S$63:$S$121=0)*$R$63:$R$121*J$63:J$121) -> -72846499 | M40: =SUMPRODUCT(($Q$63:$Q$121="영업")*($S$63:$S$121=0)*$R$63:$R$121*M$63:M$121) -> -72846499
D41: (-) 영업 범주에서 제외된 기존 영업손익 | E41: =SUMPRODUCT(($Q$63:$Q$121<>"영업")*($S$63:$S$121=1)*$R$63:$R$121*E$63:E$121)*-1 -> 0 | H41: =SUMPRODUCT(($Q$63:$Q$121<>"영업")*($S$63:$S$121=1)*$R$63:$R$121*H$63:H$121)*-1 -> 0 | J41: =SUMPRODUCT(($Q$63:$Q$121<>"영업")*($S$63:$S$121=1)*$R$63:$R$121*J$63:J$121)*-1 -> 0 | M41: =SUMPRODUCT(($Q$63:$Q$121<>"영업")*($S$63:$S$121=1)*$R$63:$R$121*M$63:M$121)*-1 -> 0
D42: IFRS 18 영업손익 | E42: =E39+E40+E41 -> -711993420 | H42: =H39+H40+H41 -> -711993420 | J42: =J39+J40+J41 -> 1338868234 | M42: =M39+M40+M41 -> 1338868234
D43: 검증: 상단 영업손익과의 차이 | E43: =E42-E12 -> 0 | H43: =H42-H12 -> 0 | J43: =J42-J12 -> 0 | M43: =M42-M12 -> 0
B45: [참고] 성격별 비용 공시 자료 (IFRS 18 주석 대응용 - 판관비+제조경비 발생액 기준, 재고자산 이연분 미반영)
D46: 감가상각비 (판관비 + 제조경비) | E46: ='정산표'!E149+'정산표'!E235 -> 514853870 | F46: ='정산표'!F149+'정산표'!F235 -> 0 | G46: ='정산표'!G149+'정산표'!G235 -> 0 | H46: ='정산표'!H149+'정산표'!H235 -> 514853870 | J46: ='정산표'!J149+'정산표'!J235 -> 333241562 | K46: ='정산표'!K149+'정산표'!K235 -> 0 | L46: ='정산표'!L149+'정산표'!L235 -> 0 | M46: ='정산표'!M149+'정산표'!M235 -> 333241562
...

Sheet 별도_AJE_26.2Q
B1: 기준일: | C1: 46203
B4: Ref. | C4: 순번 | D4: Code | E4: 계정과목 | G4: 수정금액 | I4: effect | J4: effect | K4: effect | L4: Discription
E5: 차변 | F5: 대변 | G5: 차변 | H5: 대변 | I5: NI | J5: R/E | K5: 포괄손익
B7: 주식매수선택권
D9: 37700 | E9: 처분전이익잉여금
D10: 34400 | F10: 주식매수선택권
D11: 37700 | E11: 처분전이익잉여금 | I11: 0
D12: 34400 | F12: 주식매수선택권
D16: 81000 | E16: 주식보상비용 | I16: =-G16 -> 0
D17: 34400 | F17: 주식매수선택권
B21: 연차수당 | D21: 37700 | E21: 처분전이익잉여금
D22: 26200 | F22: 미지급비용
D23: 37700 | E23: 처분전이익잉여금
D24: 37700 | E24: 처분전이익잉여금
D25: 26200 | F25: 미지급비용
D29: 80200 | E29: 직원급여(판관) | I29: =-G29 -> 0
D30: 50300 | E30: 직원급여(제조원가) | I30: =-G30 -> 0
D31: 82300 | E31: 직원급여(경상) | I31: =-G31 -> 0
D32: 26200 | F32: 미지급비용
B37: 계리평가 | D37: 37700 | E37: 처분전이익잉여금
B38: 기타장기종업원급여 | D38: 31600 | F38: 장기종업원급여부채
D39: 37700 | E39: 처분전이익잉여금
D42: 39700 | F42: 보험수리적손익 | K42: =H42 -> 0
D43: 99800 | E43: 법인세 | I43: =-G43 -> 0
D46: 31600 | F46: 장기종업원급여부채
D47: 37700 | E47: 미처분이익잉여금
D49: 31600 | E49: 장기종업원급여부채
D50: 80200 | F50: 급여 | I50: =H50 -> 0
B55: 외화선수취대가 환율보정 | D55: 37700 | E55: 처분전이익잉여금
D56: 37700 | E56: 처분전이익잉여금
D57: 37700 | F57: 처분전이익잉여금
B63: 리스수정 | D63: 37700 | E63: 처분전이익잉여금
D64: 37700 | E64: 처분전이익잉여금
D65: 37700 | E65: 처분전이익잉여금
D66: 37700 | E66: 처분전이익잉여금
D67: 37700 | F67: 처분전이익잉여금
D70: 22300 | E70: 사용권자산
D71: 22400 | E71: 사용권자산감가상각누계액
D72: 18810 | E72: 임차보증금_현재가치할인차금
D73: 28300 | F73: 유동성리스부채
...

Sheet BS
C1: 계정과목 | D1: 주석 | E1: 46203 | F1: 46022
C2: 자산
C3: 유동자산 | E3: =E4+E6+E7+E14+E24+E30+E33 -> 16937363250 | F3: =F4+F6+F7+F14+F24+F30+F33 -> 25996495943
C4: =정산표!D7 -> 현금및현금성자산 | E4: =E5 -> 10968165061 | F4: =F5 -> 19169211185 | J4: =F4-E4 -> 8201046124
B5: 10300 | C5: =정산표!D8 -> 현금및현금성자산 | E5: =VLOOKUP($B5,정산표!$B$7:$M$201,7,0) -> 10968165061 | F5: =VLOOKUP($B5,정산표!$B$7:$M$201,12,0) -> 19169211185 | J5: =F5-E5 -> 8201046124
B6: 10600 | C6: =정산표!D9 -> 단기금융상품 | E6: =VLOOKUP($B6,정산표!$B$7:$M$201,7,0) -> 0 | F6: =VLOOKUP($B6,정산표!$B$7:$M$201,12,0) -> 0 | J6: =F6-E6 -> 0
C7: =정산표!D10 -> 매출채권및기타채권 | E7: =SUM(E8:E13) -> 1667306010 | F7: =SUM(F8:F13) -> 2048442985 | J7: =F7-E7 -> 381136975
B8: 10800 | C8: =정산표!D11 -> 매출채권 | E8: =VLOOKUP($B8,정산표!$B$7:$M$201,7,0) -> 1535770100 | F8: =VLOOKUP($B8,정산표!$B$7:$M$201,12,0) -> 1998788804 | J8: =F8-E8 -> 463018704 | M8: 1735937300 | N8: =M8-E8 -> 200167200
B9: 10900 | C9: =정산표!D12 -> 매출채권대손충당금 | E9: =VLOOKUP($B9,정산표!$B$7:$M$201,7,0) -> -105342662 | F9: =VLOOKUP($B9,정산표!$B$7:$M$201,12,0) -> -188230079 | J9: =F9-E9 -> -82887417
B10: 11600 | C10: =정산표!D13 -> 미수수익 | E10: =VLOOKUP($B10,정산표!$B$7:$M$201,7,0) -> 0 | F10: =VLOOKUP($B10,정산표!$B$7:$M$201,12,0) -> 0 | J10: =F10-E10 -> 0
B11: 11700 | C11: =정산표!D14 -> 미수수익대손충당금 | E11: =VLOOKUP($B11,정산표!$B$7:$M$201,7,0) -> 0 | F11: =VLOOKUP($B11,정산표!$B$7:$M$201,12,0) -> 0
B12: 12000 | C12: =정산표!D15 -> 미수금 | E12: =VLOOKUP($B12,정산표!$B$7:$M$201,7,0) -> 261017572 | F12: =VLOOKUP($B12,정산표!$B$7:$M$201,12,0) -> 265023260 | J12: =F12-E12 -> 4005688
B13: 12100 | C13: =정산표!D16 -> 미수금대손충당금 | E13: =VLOOKUP($B13,정산표!$B$7:$M$201,7,0) -> -24139000 | F13: =VLOOKUP($B13,정산표!$B$7:$M$201,12,0) -> -27139000 | J13: =F13-E13 -> -3000000
C14: =정산표!D17 -> 재고자산 | E14: =SUM(E15:E23) -> 2202609621 | F14: =SUM(F15:F23) -> 2034274672 | J14: =F14-E14 -> -168334949
B15: 14600 | C15: =정산표!D18 -> 상품 | E15: =VLOOKUP($B15,정산표!$B$7:$M$201,7,0) -> 47852743 | F15: =VLOOKUP($B15,정산표!$B$7:$M$201,12,0) -> 42227029 | J15: =F15-E15 -> -5625714 | K15: =F15 -> 42227029
B16: 16000 | C16: =정산표!D19 -> 상품평가충당금 | E16: =VLOOKUP($B16,정산표!$B$7:$M$201,7,0) -> 0 | F16: =VLOOKUP($B16,정산표!$B$7:$M$201,12,0) -> -14089 | J16: =F16-E16 -> -14089 | K16: =F16 -> -14089
B17: 14700 | C17: =정산표!D20 -> 제품 | E17: =VLOOKUP($B17,정산표!$B$7:$M$201,7,0) -> 2534717672 | F17: =VLOOKUP($B17,정산표!$B$7:$M$201,12,0) -> 2349819825 | J17: =F17-E17 -> -184897847 | K17: =F17 -> 2349819825
B18: 16100 | C18: =정산표!D21 -> 제품평가충당금 | E18: =VLOOKUP($B18,정산표!$B$7:$M$201,7,0) -> -827921741 | F18: =VLOOKUP($B18,정산표!$B$7:$M$201,12,0) -> -725171962 | J18: =F18-E18 -> 102749779 | K18: =F18 -> -725171962
B19: 14900 | C19: =정산표!D22 -> 원재료 | E19: =VLOOKUP($B19,정산표!$B$7:$M$201,7,0) -> 464851515 | F19: =VLOOKUP($B19,정산표!$B$7:$M$201,12,0) -> 354984836 | J19: =F19-E19 -> -109866679 | K19: =F19 -> 354984836
B20: 16200 | C20: =정산표!D23 -> 원재료평가충당금 | E20: =VLOOKUP($B20,정산표!$B$7:$M$201,7,0) -> -44697318 | F20: =VLOOKUP($B20,정산표!$B$7:$M$201,12,0) -> -34479470 | J20: =F20-E20 -> 10217848 | K20: =F20 -> -34479470
B21: 15200 | C21: =정산표!D24 -> 부재료 | E21: =VLOOKUP($B21,정산표!$B$7:$M$201,7,0) -> 48405072 | F21: =VLOOKUP($B21,정산표!$B$7:$M$201,12,0) -> 49267189 | J21: =F21-E21 -> 862117 | K21: =F21 -> 49267189
B22: 15300 | C22: =정산표!D25 -> 부재료평가충당금 | E22: =VLOOKUP($B22,정산표!$B$7:$M$201,7,0) -> -20598322 | F22: =VLOOKUP($B22,정산표!$B$7:$M$201,12,0) -> -2358686 | J22: =F22-E22 -> 18239636 | K22: =F22 -> -2358686
B23: 15700 | C23: 재공품 | E23: =VLOOKUP($B23,정산표!$B$7:$M$201,7,0) -> 0 | F23: =VLOOKUP($B23,정산표!$B$7:$M$201,12,0) -> 0 | K23: =SUM(K15:K22) -> 2034274672
C24: =정산표!D27 -> 기타유동자산 | E24: =SUM(E25:E29) -> 2097128278 | F24: =SUM(F25:F29) -> 2735837690 | J24: =F24-E24 -> 638709412
B25: 13100 | C25: =정산표!D28 -> 선급금 | E25: =VLOOKUP($B25,정산표!$B$7:$M$201,7,0) -> 394157762 | F25: =VLOOKUP($B25,정산표!$B$7:$M$201,12,0) -> 2254829529 | J25: =F25-E25 -> 1860671767
B26: 13200 | C26: =정산표!D29 -> 선급금대손충당금 | E26: =VLOOKUP($B26,정산표!$B$7:$M$201,7,0) -> 0 | F26: =VLOOKUP($B26,정산표!$B$7:$M$201,12,0) -> 0 | J26: =F26-E26 -> 0
B27: 13300 | C27: =정산표!D30 -> 선급비용 | E27: =VLOOKUP($B27,정산표!$B$7:$M$201,7,0) -> 1698698289 | F27: =VLOOKUP($B27,정산표!$B$7:$M$201,12,0) -> 473315521 | J27: =F27-E27 -> -1225382768
B28: 14000 | C28: 환불자산 | E28: =VLOOKUP($B28,정산표!$B$7:$M$201,7,0) -> 4272227 | F28: =VLOOKUP($B28,정산표!$B$7:$M$201,12,0) -> 7692640
B29: 13500 | C29: =정산표!D32 -> 부가세대급금 | E29: =VLOOKUP($B29,정산표!$B$7:$M$201,7,0) -> 0 | F29: =VLOOKUP($B29,정산표!$B$7:$M$201,12,0) -> 0
C30: 기타유동금융자산 | E30: =SUM(E31:E32) -> 0 | F30: =SUM(F31:F32) -> 1250001
B31: 12400 | C31: 임차보증금(유동) | E31: =VLOOKUP($B31,정산표!$B$7:$M$201,7,0) -> 0 | F31: =VLOOKUP($B31,정산표!$B$7:$M$201,12,0) -> 0
B32: 13400 | C32: 주 . 임.종단기채권 | E32: =VLOOKUP($B32,정산표!$B$7:$M$201,7,0) -> 0 | F32: =VLOOKUP($B32,정산표!$B$7:$M$201,12,0) -> 1250001
B33: 13600 | C33: =정산표!D36 -> 당기법인세자산 | E33: =VLOOKUP($B33,정산표!$B$7:$M$201,7,0) -> 2154280 | F33: =VLOOKUP($B33,정산표!$B$7:$M$201,12,0) -> 7479410 | J33: =F33-E33 -> 5325130
C34: 비유동자산 | E34: =E35+E40+E43+E62+E67+E39 -> 37605682655 | F34: =F35+F40+F43+F62+F67+F39 -> 29197391461 | J34: =F34-E34 -> -8408291194
C35: =정산표!D38 -> 기타비유동금융자산 | E35: =SUM(E36:E38) -> 386082376 | F35: =SUM(F36:F38) -> 388220275 | J35: =F35-E35 -> 2137899
B36: 18800 | C36: =정산표!D39 -> 임차보증금 | E36: =VLOOKUP($B36,정산표!$B$7:$M$201,7,0) -> 403800000 | F36: =VLOOKUP($B36,정산표!$B$7:$M$201,12,0) -> 413778000 | J36: =F36-E36 -> 9978000
B37: 18900 | C37: =정산표!D40 -> 임차보증금_현재가치할인차금 | E37: =VLOOKUP($B37,정산표!$B$7:$M$201,7,0) -> -27853494 | F37: =VLOOKUP($B37,정산표!$B$7:$M$201,12,0) -> -35581895
B38: 19000 | C38: =정산표!D41 -> 기타보증금 | E38: =VLOOKUP($B38,정산표!$B$7:$M$201,7,0) -> 10135870 | F38: =VLOOKUP($B38,정산표!$B$7:$M$201,12,0) -> 10024170 | J38: =F38-E38 -> -111700
B39: 19500 | C39: =정산표!D42 -> 당기손익-공정가치금융자산 | E39: =VLOOKUP($B39,정산표!$B$7:$M$201,7,0) -> 172664940 | F39: =VLOOKUP($B39,정산표!$B$7:$M$201,12,0) -> 172664940
C40: =정산표!D43 -> 종속기업및관계기업투자 | E40: =SUM(E41:E42) -> 25348225181 | F40: =SUM(F41:F42) -> 17348225181 | J40: =F40-E40 -> -8000000000
...

Sheet PL
C1: =정산표!D4 -> 계정과목 | D1: 주석 | E1: =BS!E1 -> 46203 | F1: =E1-365 -> 45838 | H1: 당반기 | I1: 전반기
C2: 매출액 | E2: =SUM(E3:E5) -> 8288170687 | F2: =SUM(F3:F5) -> 8817426997
B3: 40100 | C3: =정산표!D114 -> 상품매출 | E3: =VLOOKUP($B3,정산표!$B$113:$M$201,7,0) -> 278070981 | F3: =VLOOKUP($B3,정산표!$B$113:$M$201,12,0) -> 72357415
B4: 40400 | C4: =정산표!D115 -> 제품매출 | E4: =VLOOKUP($B4,정산표!$B$113:$M$201,7,0) -> 7974892686 | F4: =VLOOKUP($B4,정산표!$B$113:$M$201,12,0) -> 8701040737
B5: 41300 | C5: =정산표!D116 -> 식음료매출 | E5: =VLOOKUP($B5,정산표!$B$113:$M$201,7,0) -> 35207020 | F5: =VLOOKUP($B5,정산표!$B$113:$M$201,12,0) -> 44028845
C6: 매출원가 | E6: =E7+E14+E21 -> 3596633522 | F6: =F7+F14+F21 -> 3527195264
B7: 45500 | C7: (1)제품매출원가 | E7: =E10+E11+E12-E13 -> 3389356072 | F7: =F10+F11+F12-F13 -> 3467738461
B8: 45500-1 | C8: 기초제품재고액 | E8: =BS!F17 -> 2349819825 | F8: =VLOOKUP($B8,정산표!$B$113:$M$201,12,0) -> 2459042471
B9: 45500-2 | C9: 당기제품제조원가 | E9: =VLOOKUP($B9,정산표!$B$113:$M$201,7,0) -> 3476800819 | F9: =VLOOKUP($B9,정산표!$B$113:$M$201,12,0) -> 3344382182 | L9: =PL!E27+PL!E28 -> 1302634521
C10: 계 | E10: =SUM(E8:E9) -> 5826620644 | F10: =SUM(F8:F9) -> 5803424653
B11: 45500-3 | C11: 타계정대체 | E11: =VLOOKUP($B11,정산표!$B$113:$M$201,7,0) -> -5296679 | F11: =VLOOKUP($B11,정산표!$B$113:$M$201,12,0) -> -6471662
B12: 45500-4 | C12: 재고자산평가 | E12: =VLOOKUP($B12,정산표!$B$113:$M$201,7,0) -> 102749779 | F12: =VLOOKUP($B12,정산표!$B$113:$M$201,12,0) -> 8624839
B13: 45500-5 | C13: 기말제품재고액 | E13: =BS!E17 -> 2534717672 | F13: =VLOOKUP($B13,정산표!$B$113:$M$201,12,0) -> 2337839369
B14: 45100 | C14: (2)상품매출원가 | E14: =E17+E18+E19-E20 -> 197040606 | F14: =F17+F18+F19-F20 -> 45654258
B15: 45100-1 | C15: 기초상품재고액 | E15: =BS!F15 -> 42227029 | F15: =VLOOKUP($B15,정산표!$B$113:$M$201,12,0) -> 32112993
B16: 45100-2 | C16: 당기상품매입액 | E16: =VLOOKUP($B16,정산표!$B$113:$M$201,7,0) -> 202680409 | F16: =VLOOKUP($B16,정산표!$B$113:$M$201,12,0) -> 87517683
C17: 계 | E17: =SUM(E15:E16) -> 244907438 | F17: =SUM(F15:F16) -> 119630676
B18: 45100-3 | C18: 상품타계정대체 | E18: =VLOOKUP($B18,정산표!$B$113:$M$201,7,0) -> 0 | F18: =VLOOKUP($B18,정산표!$B$113:$M$201,12,0) -> 0
B19: 45100-4 | C19: 재고자산평가 | E19: =VLOOKUP($B19,정산표!$B$113:$M$201,7,0) -> -14089 | F19: =VLOOKUP($B19,정산표!$B$113:$M$201,12,0) -> 0
B20: 45100-5 | C20: 기말상품재고액 | E20: =BS!E15 -> 47852743 | F20: =VLOOKUP($B20,정산표!$B$113:$M$201,12,0) -> 73976418
B21: 45700 | C21: (3)식음료매출원가 | E21: =E22+E23-E24 -> 10236844 | F21: =F22+F23-F24 -> 13802545
B22: 45700-1 | C22: 기초상품재고액 | E22: 0 | F22: =정산표!M133 -> 0
B23: 45700-2 | C23: 당기상품매입액 | E23: =정산표!E134 -> 10236844 | F23: =정산표!M134 -> 13802545
B24: 45700-3 | C24: 기말상품재고액 | E24: 0 | F24: =정산표!M135 -> 0
C25: 매출총이익 | E25: =E2-E6 -> 4691537165 | F25: =F2-F6 -> 5290231733
C26: 판매비와관리비 | E26: =SUM(E27:E59) -> 5378351282 | F26: =SUM(F27:F59) -> 3878517000
B27: 80200 | C27: =정산표!D138 -> 급여 | E27: =VLOOKUP($B27,정산표!$B$113:$M$201,7,0) -> 1192275225 | F27: =VLOOKUP($B27,정산표!$B$113:$M$201,12,0) -> 1310935710
B28: 80800 | C28: =정산표!D139 -> 퇴직급여 | E28: =VLOOKUP($B28,정산표!$B$113:$M$201,7,0) -> 110359296 | F28: =VLOOKUP($B28,정산표!$B$113:$M$201,12,0) -> 104651910
B29: 85200 | C29: 해고급여 | E29: =VLOOKUP($B29,정산표!$B$113:$M$201,7,0) -> 45930430 | F29: =VLOOKUP($B29,정산표!$B$113:$M$201,12,0) -> 0
B30: 81000 | C30: =정산표!D141 -> 주식보상비 | E30: =VLOOKUP($B30,정산표!$B$113:$M$201,7,0) -> 0 | F30: =VLOOKUP($B30,정산표!$B$113:$M$201,12,0) -> 0
B31: 81100 | C31: =정산표!D142 -> 복리후생비 | E31: =VLOOKUP($B31,정산표!$B$113:$M$201,7,0) -> 187719099 | F31: =VLOOKUP($B31,정산표!$B$113:$M$201,12,0) -> 186599937
B32: 81200 | C32: =정산표!D143 -> 여비교통비 | E32: =VLOOKUP($B32,정산표!$B$113:$M$201,7,0) -> 224812833 | F32: =VLOOKUP($B32,정산표!$B$113:$M$201,12,0) -> 285932715
B33: 81300 | C33: =정산표!D144 -> 접대비 | E33: =VLOOKUP($B33,정산표!$B$113:$M$201,7,0) -> 25692474 | F33: =VLOOKUP($B33,정산표!$B$113:$M$201,12,0) -> 78340966
B34: 81400 | C34: =정산표!D145 -> 통신비 | E34: =VLOOKUP($B34,정산표!$B$113:$M$201,7,0) -> 8042843 | F34: =VLOOKUP($B34,정산표!$B$113:$M$201,12,0) -> 7473322
B35: 81500 | C35: =정산표!D146 -> 수도광열비 | E35: =VLOOKUP($B35,정산표!$B$113:$M$201,7,0) -> 2933840 | F35: =VLOOKUP($B35,정산표!$B$113:$M$201,12,0) -> 2671110
B36: 81600 | C36: 전력비 | E36: =VLOOKUP($B36,정산표!$B$113:$M$201,7,0) -> 3879022 | F36: =VLOOKUP($B36,정산표!$B$113:$M$201,12,0) -> 3182290
B37: 81700 | C37: =정산표!D148 -> 세금과공과금 | E37: =VLOOKUP($B37,정산표!$B$113:$M$201,7,0) -> 8506220 | F37: =VLOOKUP($B37,정산표!$B$113:$M$201,12,0) -> 9688630
B38: 81800 | C38: =정산표!D149 -> 감가상각비 | E38: =VLOOKUP($B38,정산표!$B$113:$M$201,7,0) -> 119880341 | F38: =VLOOKUP($B38,정산표!$B$113:$M$201,12,0) -> 84937975
B39: 81900 | C39: =정산표!D150 -> 지급임차료 | E39: =VLOOKUP($B39,정산표!$B$113:$M$201,7,0) -> 508414 | F39: =VLOOKUP($B39,정산표!$B$113:$M$201,12,0) -> 30334814
B40: 82000 | C40: =정산표!D151 -> 수선비 | E40: =VLOOKUP($B40,정산표!$B$113:$M$201,7,0) -> 1111000 | F40: =VLOOKUP($B40,정산표!$B$113:$M$201,12,0) -> 93300
...

Sheet CE
B2: 자본변동표
B3: 과목 | C3: 자본금 | D3: 자본잉여금 | E3: 기타자본항목 | F3: 이익잉여금(결손금) | G3: 총계
B4: 2018.01.01(당기초) | C4: 2223895000 | D4: 3463257344 | E4: 46972105 | F4: -597980560 | G4: 5136143889
B5: 총포괄손익: | D5: 0
B6: 당기순이익 | C6: 0 | E6: 0 | F6: -4291126371 | G6: -4291126371
B7: 종업원급여재측정요소 | C7: 0 | D7: 0 | E7: 0 | F7: 20686363 | G7: 20686363
B8: 자본에직접반영된소유주와의거래
B9: 유상증자 | C9: 213000000 | D9: 2556000000 | E9: 0 | F9: 0 | G9: 2769000000
B10: 주식보상비용 | C10: 0 | D10: 0 | E10: 71446833 | F10: 0 | G10: 71446833
B11: 2018.12.31(전기말) | C11: =SUM(C4:C10) -> 2436895000 | D11: =SUM(D4:D10) -> 6019257344 | E11: =SUM(E4:E10) -> 118418938 | F11: =SUM(F4:F10) -> -4868420568 | G11: =SUM(G4:G10) -> 3706150714
B12: 2025.01.01(전기초) | C12: 3123279500 | D12: 12384121289 | E12: 377682898 | F12: -9779538403 | G12: =SUM(C12:F12) -> 6105545284
B13: 총포괄손익:
B14: 당기순이익 | C14: 0 | D14: 0 | E14: 0 | F14: =Dart_PL!F16 -> 1323632141 | G14: =SUM(C14:F14) -> 1323632141
B15: 종업원급여재측정요소 | C15: 0 | D15: 0 | E15: 0 | F15: =Dart_PL!F19 -> 0 | G15: =SUM(C15:F15) -> 0
B16: 자본에직접반영된소유주와의거래
B17: 유상증자 | C17: 0 | D17: 0 | E17: 0 | F17: 0 | G17: =SUM(C17:F17) -> 0
B18: 주식매수선택권의 행사 | C18: 19664500 | D18: 100443904 | E18: -27842570 | F18: 0 | G18: =SUM(C18:F18) -> 92265834
B19: 주식보상비용 | C19: 0 | D19: 0 | E19: =정산표!M141 -> 0 | F19: 0 | G19: =SUM(C19:F19) -> 0
B20: 2025.06.30(전반기말) | C20: =SUM(C12:C19) -> 3142944000 | D20: =SUM(D12:D19) -> 12484565193 | E20: =SUM(E12:E19) -> 349840328 | F20: =SUM(F12:F19) -> -8455906262 | G20: =SUM(G12:G19) -> 7521443259 | H20: 7521443259 | I20: =H20=G20 -> TRUE
B21: 2026.01.01(당기초) | C21: 5691191500 | D21: 45157382298 | E21: 424627793 | F21: -8783566486 | G21: =SUM(C21:F21) -> 42489635105
B22: 총포괄손익: | G22: =SUM(C22:F22) -> 0
B23: 당기순이익 | C23: 0 | D23: 0 | E23: 0 | F23: =정산표!H197 -> -788849810 | G23: =SUM(C23:F23) -> -788849810
B24: 종업원급여재측정요소 | C24: 0 | D24: 0 | E24: 0 | F24: =정산표!H199 -> 0 | G24: =SUM(C24:F24) -> 0
B25: 자본에직접반영된소유주와의거래 | G25: =SUM(C25:F25) -> 0
B26: 유상증자 | C26: 0 | D26: 0 | E26: 0 | F26: 0 | G26: =SUM(C26:F26) -> 0
B27: 주식매수선택권의 행사 | C27: 0 | D27: ='CF정산표(26.2Q)'!N103-'CF정산표(26.2Q)'!Q103 -> 0 | E27: ='CF정산표(26.2Q)'!P105 -> 0 | F27: 0 | G27: =SUM(C27:F27) -> 0
B28: 주식보상비용 | C28: 0 | D28: 0 | E28: =정산표!H141 -> 0 | F28: 0 | G28: =SUM(C28:F28) -> 0
B29: 2026.06.30(당기말) | C29: =SUM(C21:C28) -> 5691191500 | D29: =SUM(D21:D28) -> 45157382298 | E29: =SUM(E21:E28) -> 424627793 | F29: =SUM(F21:F28) -> -9572416296 | G29: =SUM(G21:G28) -> 41700785295 | H29: =Dart_BS!C39 -> 41700785295 | I29: =H29=G29 -> TRUE
B31: 전기대사 | C31: =C21=Dart_BS!D35 -> TRUE | D31: =D21=Dart_BS!D36 -> TRUE | E31: =E21=Dart_BS!D37 -> TRUE | F31: =F21=Dart_BS!D38 -> TRUE | G31: =G21=Dart_BS!D39 -> TRUE
B32: 당기대사 | C32: =C29=Dart_BS!C35 -> TRUE | D32: =D29=Dart_BS!C36 -> TRUE | E32: =E29=Dart_BS!C37 -> TRUE | F32: =F29=Dart_BS!C38 -> TRUE | G32: =G29=Dart_BS!C39 -> TRUE
C33: =C21-BS!F94 -> 0 | D33: =D21-BS!F95 -> 0 | E33: =E21-BS!F97 -> 0 | F33: =F21-BS!F99 -> 0 | G33: =G21-BS!F101 -> 0
C34: =C29-BS!E93 -> 0 | D34: =D29-BS!E95 -> 0 | E34: =E29-BS!E97 -> 0 | F34: =F29-BS!E99 -> 0 | G34: =G29-BS!E101 -> 0

Sheet CF
B1: 과목 | C1: 주석 | D1: =BS!E1 -> 46203 | E1: =PL!F1 -> 45838 | G1: 검증
B2: Ⅰ.영업활동으로인한현금흐름 | D2: =D3+D34+D35+D36 -> 1181452121 | E2: =E3+E34+E35+E36 -> 1255790252
B3: 1.영업에서창출된현금 | D3: =D4+D5+D26 -> 1255384365 | E3: =E4+E5+E26 -> 1319946478
B4: 가.당기순이익 | D4: =PL!E86 -> -788849810 | E4: =PL!F86 -> 1323632141
B5: 나.조정 | D5: =SUM(D6:D25) -> 850953963 | E5: =SUM(E6:E25) -> 857239522
B6: 대손상각비(환입) | D6: ='CF정산표(26.2Q)'!H15 -> -82887417 | E6: 56611534 | G6: =PL!E53=D6 -> TRUE | H6: =PL!F53=E6 -> TRUE
B7: 이자수익 | D7: =-'CF정산표(26.2Q)'!J16-'CF정산표(26.2Q)'!J42 -> -22098561 | E7: -28008260 | G7: =-PL!E76=D7 -> TRUE | H7: =-PL!F76=E7 -> TRUE
B8: 기타의대손상각비(환입) | D8: ='CF정산표(26.2Q)'!H32+'CF정산표(26.2Q)'!H19+'CF정산표(26.2Q)'!H17 -> -3000000 | E8: -3000000 | G8: =-PL!E62+PL!E68=D8 -> TRUE | H8: =-PL!F62+PL!F68=E8 -> TRUE
B9: 유형자산처분이익 | D9: =-('CF정산표(26.2Q)'!J54+'CF정산표(26.2Q)'!J65+'CF정산표(26.2Q)'!J63+'CF정산표(26.2Q)'!J53) -> -1202135 | E9: -1054000 | G9: =-PL!E64=D9 -> TRUE | H9: =-PL!F64=E9 -> TRUE
B10: 외화환산이익 | D10: =-'CF정산표(26.2Q)'!J11-'CF정산표(26.2Q)'!J14 -> -37603839 | E10: -3042 | G10: =-PL!E78=D10 -> TRUE | H10: =-PL!F78=E10 -> TRUE
B11: 재고자산평가손실(환입) | D11: ='CF정산표(26.2Q)'!H22+'CF정산표(26.2Q)'!H24+'CF정산표(26.2Q)'!H26-'CF정산표(26.2Q)'!J24-'CF정산표(26.2Q)'!J26-'CF정산표(26.2Q)'!J22+'CF정산표(26.2Q)'!H28-'CF정산표(26.2Q)'!J28 -> 131193174 | E11: 15216604 | G11: ='9'!E21=ROUND(D11/10^6,) -> TRUE
B12: 퇴직급여 | D12: ='CF정산표(26.2Q)'!H94 -> 188019390 | E12: 177665682 | G12: ='21'!E24=D12 -> TRUE
B13: 장기종업원급여 | D13: ='CF정산표(26.2Q)'!H90 -> 37001898 | E13: 34571148
B14: 주식보상비 | D14: ='CF정산표(26.2Q)'!H105 -> 0 | E14: 0 | G14: =PL!E30=D14 -> TRUE | H14: =PL!F30=E14 -> TRUE
B15: 이자비용 | D15: ='CF정산표(26.2Q)'!H76+'CF정산표(26.2Q)'!H92 -> 98954951 | E15: 43244353 | G15: =PL!E80=D15 -> TRUE | H15: =PL!F80=E15 -> TRUE
B16: 감가상각비 | D16: ='CF정산표(26.2Q)'!H51+'CF정산표(26.2Q)'!H53+'CF정산표(26.2Q)'!H57+'CF정산표(26.2Q)'!H59+'CF정산표(26.2Q)'!H62+'CF정산표(26.2Q)'!H64+'CF정산표(26.2Q)'!H66 -> 524170112 | E16: 359919576 | G16: =-'13'!J36=D16 -> TRUE
B17: 무형고정자산상각 | D17: ='CF정산표(26.2Q)'!H68+'CF정산표(26.2Q)'!H69+'CF정산표(26.2Q)'!H70+'CF정산표(26.2Q)'!H71 -> 21529107 | E17: 144426793 | G17: =-'14'!H22=D17 -> TRUE
B18: 유형자산처분손실 | D18: =SUMIFS('CF정산표(26.2Q)'!$H$8:$H$109,'CF정산표(26.2Q)'!$G$8:$G$109,"유형자산처분손실") -> 4825402 | E18: 3098042 | G18: =PL!E71=D18 -> TRUE | H18: =PL!F71=E18 -> TRUE
B19: 외화환산손실 | D19: ='CF정산표(26.2Q)'!H11+'CF정산표(26.2Q)'!H14 -> 0 | E19: 57204705 | G19: =PL!E83=D19 -> TRUE | H19: =PL!F83=E19 -> TRUE
B20: 당기손익-공정가치측정금융자산평가손실 | D20: ='CF정산표(26.2Q)'!H44 -> 0 | G20: =PL!E81=D20 -> TRUE
B21: 법인세비용(수익) | D21: ='CF정산표(26.2Q)'!H37 -> 0 | E21: 0 | G21: =PL!E85=D21 -> TRUE | H21: =PL!F85=E21 -> TRUE
B22: 종속기업투자주식손상환입 | D22: =-'CF정산표(26.2Q)'!J46 -> 0 | E22: 0
B23: 관계기업투자주식처분손실 | D23: ='CF정산표(26.2Q)'!H47 -> 0 | E23: 0 | G23: =PL!E70=D23 -> TRUE
B24: 종속기업투자주식손상차손 | D24: ='CF정산표(26.2Q)'!H46 -> 0 | E24: 0 | J24: =CF!E4+CF!E5+CF!E65 -> 2180867935
B25: 반품충당부채 설정(환입) | D25: ='CF정산표(26.2Q)'!H87 -> -7948119 | E25: -2653613
B26: 다.영업활동으로인한자산부채의변동 | D26: =SUM(D27:D33) -> 1193280212 | E26: =SUM(E27:E33) -> -860925185
B27: 매출채권및기타채권의 감소(증가) | D27: ='CF정산표(26.2Q)'!K14+'CF정산표(26.2Q)'!K18 -> 504628226 | E27: -285442157
B28: 기타유동자산의 감소(증가) | D28: ='CF정산표(26.2Q)'!K31+'CF정산표(26.2Q)'!K33+'CF정산표(26.2Q)'!K34 -> 665709412 | E28: -287650372
B29: 재고자산의 감소(증가) | D29: ='CF정산표(26.2Q)'!K21+'CF정산표(26.2Q)'!K23+'CF정산표(26.2Q)'!K25+'CF정산표(26.2Q)'!K29+'CF정산표(26.2Q)'!K27 -> -299528123 | E29: 73992229
B30: 매입채무및기타채무의 증가(감소) | D30: ='CF정산표(26.2Q)'!K78+'CF정산표(26.2Q)'!K79+'CF정산표(26.2Q)'!K80 -> 1534270814 | E30: -298721864
B31: 기타유동부채의 증가(감소) | D31: ='CF정산표(26.2Q)'!K86+'CF정산표(26.2Q)'!K81 -> -142571143 | E31: -1288559
B32: 기타장기종업원급여의 증가(감소) | D32: ='CF정산표(26.2Q)'!K90 -> -4380000 | E32: 0
B33: 퇴직금의 지급 | D33: ='CF정산표(26.2Q)'!K94 -> -1064848974 | E33: -61814462 | G33: ='21'!E13=D33 -> TRUE
B34: 2.이자의수취 | D34: ='CF정산표(26.2Q)'!K16 -> 14069356 | E34: 21472518
B35: 3.이자의지급 | D35: ='CF정산표(26.2Q)'!K76+'CF정산표(26.2Q)'!K92 -> -93326730 | E35: -92269564
B36: 4.법인세등환급액(부담액) | D36: ='CF정산표(26.2Q)'!K37 -> 5325130 | E36: 6640820
B37: Ⅱ.투자활동으로인한현금흐름 | D37: =D38+D45 -> -9023261400 | E37: =E38+E45 -> -534838334
B38: 1. 투자활동으로 인한 현금유입액 | D38: =SUM(D39:D44) -> 17756301 | E38: =SUM(E39:E44) -> 11233335
B39: 단기금융상품의 감소 | D39: ='CF정산표(26.2Q)'!L12 -> 0 | E39: 0
B40: 단기대여금의 감소 | D40: ='CF정산표(26.2Q)'!L36 -> 1250001 | E40: 3333335
...

Sheet CF참고(비교용)
D1: 코드 | E1: 10300 | F1: 10600 | G1: 10800 | H1: 10900 | I1: 11600 | J1: 11700 | K1: 12000 | L1: 12100 | M1: 14600 | N1: 16000 | O1: 14700 | P1: 16100 | Q1: 14900 | R1: 16200 | S1: 15200 | T1: 15300 | U1: 15700 | V1: 13100 | W1: 13200 | X1: 13300 | Y1: 13500 | Z1: 14000 | AA1: 12400 | AB1: 13400 | AC1: 13600 | AD1: 18800 | AE1: 18900 | AF1: 19000 | AG1: 19500 | AH1: 17600 | AI1: 17700 | AJ1: 20100 | AK1: 20200 | AL1: 20300 | AM1: 20600 | AN1: 20700 | AO1: 20800 | AP1: 20900 | AQ1: 21000 | AR1: 21100 | AS1: 21200 | AT1: 21300 | AU1: 21400 | AV1: 21900 | AW1: 22000 | AX1: 22100 | AY1: 22200 | AZ1: 22300 | BA1: 22400 | BB1: 23200 | BC1: 23300 | BD1: 23900 | BE1: 24000 | BF1: 19600 | BG1: 25100 | BH1: 25300 | BI1: 25400 | BJ1: 26200 | BK1: 26000 | BL1: 28200 | BM1: 28300 | BN1: 25900 | BO1: 28100 | BP1: 31600 | BQ1: 29300 | BR1: 31500 | BS1: 29500 | BT1: 29500-1 | BU1: 33100 | BV1: 34100 | BW1: 34400 | BX1: 37700
D2: 계정명 | E2: =VLOOKUP(E$1,BS!$B$4:$F$102,2,0) -> 현금및현금성자산 | F2: =VLOOKUP(F$1,BS!$B$4:$F$102,2,0) -> 단기금융상품 | G2: =VLOOKUP(G$1,BS!$B$4:$F$102,2,0) -> 매출채권 | H2: =VLOOKUP(H$1,BS!$B$4:$F$102,2,0) -> 매출채권대손충당금 | I2: =VLOOKUP(I$1,BS!$B$4:$F$102,2,0) -> 미수수익 | J2: =VLOOKUP(J$1,BS!$B$4:$F$102,2,0) -> 미수수익대손충당금 | K2: =VLOOKUP(K$1,BS!$B$4:$F$102,2,0) -> 미수금 | L2: =VLOOKUP(L$1,BS!$B$4:$F$102,2,0) -> 미수금대손충당금 | ... BX2: =VLOOKUP(BX$1,BS!$B$4:$F$102,2,0) -> 처분전이익잉여금 | CG2: 자산 | CH2: 부채 | CI2: 자본
D3: 45657 | E3: =VLOOKUP(E$1,BS!$B$4:$F$102,5,0) -> 19169211185 | F3: =VLOOKUP(F$1,BS!$B$4:$F$102,5,0) -> 0 | G3: =VLOOKUP(G$1,BS!$B$4:$F$102,5,0) -> 1998788804 | H3: =VLOOKUP(H$1,BS!$B$4:$F$102,5,0) -> -188230079 | I3: =VLOOKUP(I$1,BS!$B$4:$F$102,5,0) -> 0 | J3: =VLOOKUP(J$1,BS!$B$4:$F$102,5,0) -> 0 | K3: =VLOOKUP(K$1,BS!$B$4:$F$102,5,0) -> 265023260 | L3: =VLOOKUP(L$1,BS!$B$4:$F$102,5,0) -> -27139000 | ... BX3: =VLOOKUP(BX$1,BS!$B$4:$F$102,5,0) -> -8783566486 | CG3: =SUM(E3:BF3) -> 55193887404 | CH3: =SUM(BG3:BT3) -> 12704252299 | CI3: =SUM(BU3:BX3) -> 42489635105 | CJ3: =CG3=CH3+CI3 -> TRUE | CK3: =CG3=BS!F102 -> TRUE
D4: =C8 -> 46203 | E4: =VLOOKUP(E$1,BS!$B$4:$F$102,4,0) -> 10968165061 | F4: =VLOOKUP(F$1,BS!$B$4:$F$102,4,0) -> 0 | G4: =VLOOKUP(G$1,BS!$B$4:$F$102,4,0) -> 1535770100 | H4: =VLOOKUP(H$1,BS!$B$4:$F$102,4,0) -> -105342662 | I4: =VLOOKUP(I$1,BS!$B$4:$F$102,4,0) -> 0 | J4: =VLOOKUP(J$1,BS!$B$4:$F$102,4,0) -> 0 | K4: =VLOOKUP(K$1,BS!$B$4:$F$102,4,0) -> 261017572 | L4: =VLOOKUP(L$1,BS!$B$4:$F$102,4,0) -> -24139000 | ... BX4: =VLOOKUP(BX$1,BS!$B$4:$F$102,4,0) -> -9572416296 | CG4: =SUM(E4:BF4) -> 54543045905 | CH4: =SUM(BG4:BT4) -> 12842260610 | CI4: =SUM(BU4:BX4) -> 41700785295 | CJ4: =CG4=CH4+CI4 -> TRUE | CK4: =CG4=BS!E102 -> TRUE
D5: 증감 | E5: =E3-E4 -> 8201046124 | F5: =F3-F4 -> 0 | G5: =G3-G4 -> 463018704 | H5: =H3-H4 -> -82887417 | I5: =I3-I4 -> 0 | J5: =J3-J4 -> 0 | K5: =K3-K4 -> 4005688 | L5: =L3-L4 -> -3000000 | ... BF5: =BF3-BF4 -> 0 | BG5: =BG4-BG3 -> -246481096 | BH5: =BH4-BH3 -> -85369203 | BI5: =BI4-BI3 -> 85200680 | BJ5: =BJ4-BJ3 -> 1806719222 | BK5: =BK4-BK3 -> 0 | BL5: =BL4-BL3 -> -83300000 | BM5: =BM4-BM3 -> -8918965 | BN5: =BN4-BN3 -> -227771823 | ... BX5: =BX4-BX3 -> -788849810
D6: 계 | E6: =SUM(E8:E1048576) -> 0 | F6: =SUM(F8:F1048576) -> 0 | G6: =SUM(G8:G1048576) -> 463018704 | H6: =SUM(H8:H1048576) -> 52323396 | I6: =SUM(I8:I1048576) -> 0 | J6: =SUM(J8:J1048576) -> 0 | K6: =SUM(K8:K1048576) -> 4005688 | L6: =SUM(L8:L1048576) -> -3000000 | ... BX6: =SUM(BX8:BX1048576) -> -788849810 | BZ6: =SUM(BZ8:BZ125) -> 0 | CA6: =SUM(CA8:CA125) -> 0 | CB6: =SUM(CB8:CB125) -> 0
D7: 검증 | F7: =F6-F5 -> 0 | G7: =G6-G5 -> 0 | H7: =H6-H5 -> 135210813 | I7: =I6-I5 -> 0 | J7: =J6-J5 -> 0 | K7: =K6-K5 -> 0 | L7: =L6-L5 -> 0 | M7: =M6-M5 -> 0 | ... BX7: =BX6-BX5 -> 0 | BZ7: 법인세비용 | CA7: 이자수익 | CB7: 이자비용
B8: 과목 | C8: =CF!D1 -> 46203 | BY8: 0
B9: Ⅰ. 영업활동 현금흐름 | C9: =SUM(C10,C41:C44) -> 1952791785 | BY9: 0
B10: 1. 영업으로부터 창출된 현금흐름 | C10: =SUM(C11:C12,C33) -> 2078568308 | BY10: 0
B11: 가. 당기순이익(손실) | C11: =SUM(E11:BY11) -> -788849810 | BX11: =Dart_PL!D16 -> -788849810 | BY11: 0
B12: 나. 비현금 조정 | C12: =SUM(C13:C31) -> 909141401 | BY12: 0
A13: =CF!D6-C13 -> -139498951 | B13: 대손상각비(환입) | C13: =SUM(E13:CD13) -> 56611534 | H13: =1082586+55528948 -> 56611534 | BY13: 0
A14: =CF!D8-C14 -> 0 | B14: 기타의대손상각비(환입) | C14: =SUM(E14:CD14) -> -3000000 | L14: -3000000
A15: =CF!D7-C15 -> 0 | B15: 이자수익 | C15: =SUM(E15:CD15) -> -22098561 | AE15: -6535742 | BY15: 0 | CA15: =-정산표!H187-AE15 -> -15562819
A16: =CF!D9-C16 -> -148135 | B16: 유형자산처분이익 | C16: =SUM(E16:CD16) -> -1054000 | AO16: -799000 | AY16: -255000 | BY16: 0
A17: =CF!D10-C17 -> -37600797 | B17: 외화환산이익 | C17: =SUM(E17:CD17) -> -3042 | E17: -3042 | G17: 0 | BY17: 0
A18: =CF!D11-C18 -> 120400482 | B18: 재고자산평가손실(환입) | C18: =SUM(E18:CD18) -> 10792692 | P18: 8624839 | R18: =4694588-4423912 -> 270676 | T18: 1897177 | BY18: 0
A19: =CF!D12-C19 -> 10353708 | B19: 퇴직급여 | C19: =SUM(E19:CD19) -> 177665682 | BS19: 177665682 | BY19: 0
A20: =CF!D13-C20 -> 2430750 | B20: 장기종업원급여 | C20: =SUM(E20:CD20) -> 34571148 | BP20: 34571148 | BY20: 0
A21: =CF!D14-C21 -> 0 | B21: 주식보상비 | C21: =SUM(E21:CD21) -> 0 | BY21: 0
A22: =CF!D15-C22 -> 0 | B22: 이자비용 | C22: =SUM(E22:CD22) -> 98954951 | BR22: 9731787 | BY22: 0 | CB22: =정산표!H191-BR22 -> 89223164
A23: =CF!D16-C23 -> 164250536 | B23: 감가상각비 | C23: =SUM(E23:CD23) -> 359919576 | AL23: 14123855 | AN23: 85320738 | AR23: 5559008 | AT23: 9262066 | AW23: 9899922 | AY23: 39100835 | BA23: 196653152 | BY23: 0
A24: =CF!D17-C24 -> -122897686 | B24: 무형고정자산상각 | C24: =SUM(E24:CD24) -> 144426793 | BB24: 7256965 | BC24: 8609400 | BD24: 125626794 | BE24: 2933634 | BY24: 0
A25: =CF!D18-C25 -> 1727360 | B25: 유형자산처분손실 | C25: =SUM(E25:CD25) -> 3098042 | V25: 3000000 | BA25: 98042 | BY25: 0
A26: =CF!D19-C26 -> -57204705 | B26: 외화환산손실 | C26: =SUM(E26:CD26) -> 57204705 | E26: 6770 | G26: 57197935 | BY26: 0
A27: =CF!D21-C27 -> 0 | B27: 법인세비용 | C27: =SUM(E27:CD27) -> 0 | BY27: 0
A28: =CF!D22-C28 -> 0 | B28: 종속기업투자주식손상환입 | C28: =SUM(E28:CD28) -> 0 | BY28: 0
A29: =CF!D23-C29 -> 0 | B29: 관계기업투자주식처분손실 | C29: =SUM(E29:CD29) -> 0 | BY29: 0
A30: =CF!D24-C30 -> 0 | B30: 종속기업투자주식손상차손 | C30: =SUM(E30:CD30) -> 0 | BY30: 0
A31: =CF!D25-C31 -> 0 | B31: 환불부채 | C31: =SUM(E31:CD31) -> -7948119 | BO31: =BO5 -> -7948119 | BY31: 0
BY32: 0
B33: 다. 운전자본 조정 | C33: =SUM(C34:C40) -> 1958276717 | BY33: 0
